Workbook
Name A_elec: Inputs!$D$15
Name A_elec_m2: Inputs!$D$16
Name C_frac: Inputs!$D$31
Name CO2_ratio: 'CO2 dosing'!$D$24
Name CO2_sat: 'CO2 dosing'!$D$9
Name CO2_supply: 'CO2 dosing'!$D$23
Name DO_inhib: Inputs!$D$33
Name duty_cycle: 'CO2 dosing'!$D$35
Name eta_F: Inputs!$D$38
Name F_const: Inputs!$D$41
Name H_CO2_ref: Inputs!$D$43
Name H_CO2_T: Inputs!$D$44
Name H_O2_ref: Inputs!$D$45
Name H_O2_T: Inputs!$D$46
Name I_app: Inputs!$D$37
Name j: Inputs!$D$36
Name M_CO2: Inputs!$D$48
Name M_O2: Inputs!$D$49
Name mu: Inputs!$D$27
Name OD_target: Inputs!$D$28
Name p_CO2: Inputs!$D$20
Name p_H2: Inputs!$D$22
Name p_O2: Inputs!$D$21
Name P_tot: Inputs!$D$19
Name pulse_freq: 'CO2 dosing'!$D$32
Name Q_gas: Inputs!$D$23
Name Q_gas_Ls: Inputs!$D$24
Name R_gas: Inputs!$D$42
Name rCO2_min: 'CO2 dosing'!$D$18
Name rO2_cons: 'O2 balance'!$D$14
Name rO2_gen: 'O2 balance'!$D$8
Name rO2_net: 'O2 balance'!$D$17
Name strip_cap: 'O2 balance'!$D$29
Name strip_ratio: 'O2 balance'!$D$30
Name strip_req: 'O2 balance'!$D$22
Name T_C: Inputs!$D$13
Name t_drawdown: 'CO2 dosing'!$D$31
Name T_K: Inputs!$D$14
Name T_ref: Inputs!$D$47
Name t_sparge: 'CO2 dosing'!$D$34
Name t_to_inhib: 'O2 balance'!$D$21
Name V_head: Inputs!$D$12
Name V_optA: Inputs!$D$7
Name V_optB: Inputs!$D$8
Name V_sel: Inputs!$D$9
Name V_work: Inputs!$D$10
Name V_work_L: Inputs!$D$11
Name X_conc: Inputs!$D$30
Name X_per_OD: Inputs!$D$29
Name Y_O2: Inputs!$D$32
Name z_H2: Inputs!$D$50
Name z_O2: Inputs!$D$51

Sheet Inputs
A1: electroPioreactor Model — Inputs
A2: AMYBO aseptic electro-bioreactor — hydrogen-oxidising bacteria (C. necator) grown autotrophically on CO2 with electrolytic H2/O2. UK English, SI/metric. All output tabs trace to this sheet.
A4: Parameter | B4: Name | C4: Unit | D4: Value | E4: Source / Assumption
A6: REACTOR
A7: Working volume — option A | B7: V_optA | C7: mL | D7: 20 | E7: Design option (small cell)
A8: Working volume — option B | B8: V_optB | C8: mL | D8: 40 | E8: Design option (larger cell)
A9: Active volume selector (A or B) | B9: V_sel | C9: A/B | D9: A | E9: Choose which working volume the model uses
A10: Working volume (active) | B10: V_work | C10: mL | D10: =IF(D9="B",D8,D7) -> 20 | E10: Computed from selector
A11: Working volume (active) | B11: V_work_L | C11: L | D11: =D10/1000 -> 0.02 | E11: Unit conversion
A12: Headspace volume | B12: V_head | C12: mL | D12: 10 | E12: Assumed headspace above liquid
A13: Temperature | B13: T_C | C13: °C | D13: 30 | E13: C. necator optimum ~30°C (assumption)
A14: Temperature (absolute) | B14: T_K | C14: K | D14: =D13+273.15 -> 303.15 | E14: = °C + 273.15
A15: Electrode area (each electrode) | B15: A_elec | C15: cm² | D15: 10 | E15: Assumed electrode geometric area
A16: Electrode area (each electrode) | B16: A_elec_m2 | C16: m² | D16: =D15/10000 -> 0.001 | E16: Unit conversion
A18: GAS
A19: Total system pressure | B19: P_tot | C19: kPa | D19: 101.325 | E19: Atmospheric (standard)
A20: CO2 partial pressure (sparge gas) | B20: p_CO2 | C20: kPa | D20: 10 | E20: Assumed CO2 fraction in feed gas
A21: O2 partial pressure (sparge gas) | B21: p_O2 | C21: kPa | D21: 5 | E21: Assumed O2 in feed (kept low for hydrogenase)
A22: H2 partial pressure (sparge gas) | B22: p_H2 | C22: kPa | D22: 60 | E22: Assumed H2 fraction in feed gas
A23: Target sparge gas flow rate | B23: Q_gas | C23: mL/min | D23: 10 | E23: Target volumetric gas feed
A24: Target sparge gas flow rate | B24: Q_gas_Ls | C24: L/s | D24: =D23/1000/60 -> 0.00016666667 | E24: Unit conversion
A26: BIOLOGY
A27: Target specific growth rate | B27: mu | C27: 1/h | D27: 0.25 | E27: C. necator autotrophic µmax ~0.2–0.4 /h — LITERATURE PLACEHOLDER, verify
A28: Target optical density | B28: OD_target | C28: OD600 | D28: 10 | E28: Target cell density — PLACEHOLDER, verify
A29: Biomass per OD unit | B29: X_per_OD | C29: g DCW/L per OD | D29: 0.4 | E29: Typical ~0.3–0.5 gDCW/L/OD — PLACEHOLDER, verify
A30: Biomass concentration (target) | B30: X_conc | C30: g DCW/L | D30: =D28*D29 -> 4 | E30: = OD_target × X_per_OD
A31: Biomass C content (CO2 demand basis) | B31: C_frac | C31: g C / g DCW | D31: 0.48 | E31: Typical microbial ~0.48 — PLACEHOLDER, verify
A32: O2 yield per biomass (resp. demand) | B32: Y_O2 | C32: mol O2 / g DCW | D32: 0.04 | E32: Knallgas O2 demand ~0.03–0.05 mol/gDCW — PLACEHOLDER, verify
A33: Hydrogenase O2-inhibition threshold (dissolved) | B33: DO_inhib | C33: µM | D33: 50 | E33: [NiFe] hydrogenase O2-sensitivity — LITERATURE PLACEHOLDER, verify
A35: ELECTROLYSIS
A36: Applied current density | B36: j | C36: A/m² | D36: 100 | E36: Applied electrolysis current density — ASSUMPTION, verify
A37: Applied current | B37: I_app | C37: A | D37: =D36*D16 -> 0.1 | E37: = j × electrode area (m²)
A38: Faradaic efficiency (gas evolution) | B38: eta_F | C38: fraction | D38: 0.95 | E38: Assumed current-to-gas efficiency
A40: CONSTANTS (handbook)
A41: Faraday constant | B41: F_const | C41: C/mol | D41: 96485 | E41: CODATA 2018 (handbook)
A42: Ideal gas constant | B42: R_gas | C42: J/mol/K | D42: 8.314 | E42: CODATA (handbook)
A43: Henry's law solubility const, CO2 (Hcp, 298.15K) | B43: H_CO2_ref | C43: mol/m³/Pa | D43: 0.00033 | E43: Sander (2015) compilation, Hcp≈3.3e-4 mol/m³/Pa
A44: Henry temp. dependence, CO2 (−ΔsolH/R) | B44: H_CO2_T | C44: K | D44: 2400 | E44: Sander (2015), van 't Hoff coefficient for CO2
A45: Henry's law solubility const, O2 (Hcp, 298.15K) | B45: H_O2_ref | C45: mol/m³/Pa | D45: 1.3e-05 | E45: Sander (2015) compilation, Hcp≈1.3e-5 mol/m³/Pa
A46: Henry temp. dependence, O2 (−ΔsolH/R) | B46: H_O2_T | C46: K | D46: 1500 | E46: Sander (2015), van 't Hoff coefficient for O2
...

Sheet CO2 dosing
A1: CO2 Dosing — Henry's law solubility, carbon demand, pulsed sparge regime
A2: All values trace to Inputs. Black = formula. Goal: keep dissolved CO2 non-limiting at target growth rate.
A4: Step | B4: Quantity | C4: Unit | D4: Value | E4: Formula / working
A6: 1. CO2 SOLUBILITY (Henry's law)
A7: Henry const. CO2 at reactor T (van 't Hoff corrected) | B7: H_CO2_T | C7: mol/m³/Pa | D7: =H_CO2_ref*EXP(H_CO2_T*(1/T_K-1/T_ref)) -> 0.00028897092 | E7: Hcp(T)=Hcp_ref×exp[Δ(1/T−1/Tref)]
A8: CO2 partial pressure | B8: p_CO2_Pa | C8: Pa | D8: =p_CO2*1000 -> 10000 | E8: = p_CO2 (kPa) × 1000
A9: Saturated dissolved CO2 (equilibrium with feed) | B9: CO2_sat | C9: mol/m³ | D9: =D7*D8 -> 2.8897092 | E9: = H_CO2(T) × p_CO2 (Henry's law)
A10: Saturated dissolved CO2 | B10: CO2_sat_mM | C10: mmol/L | D10: =D9 -> 2.8897092 | E10: mol/m³ = mmol/L (identical)
A12: 2. CARBON DEMAND (from growth)
A13: Biomass in reactor (active volume) | B13: X_mass | C13: g DCW | D13: =X_conc*V_work_L -> 0.08 | E13: = X_conc × V_work_L
A14: Biomass production rate at µ (rX = µ·X) | B14: rX | C14: g DCW/h | D14: =mu*D13 -> 0.02 | E14: = µ × biomass mass
A15: Carbon assimilation rate | B15: rC | C15: g C/h | D15: =D14*C_frac -> 0.0096 | E15: = rX × C_frac
A16: CO2 molar demand rate | B16: rCO2_mol | C16: mol CO2/h | D16: =D15/12.011 -> 0.00079926734 | E16: = rC / atomic mass C (12.011); 1 mol C per mol CO2
A17: CO2 mass demand rate | B17: rCO2_mass | C17: mg CO2/h | D17: =D16*M_CO2*1000 -> 35.175756 | E17: = rCO2_mol × M_CO2 × 1000
A18: CO2 demand per minute (for pulse sizing) | B18: rCO2_min | C18: mmol/min | D18: =D16/60*1000 -> 0.013321122 | E18: = rCO2_mol / 60 × 1000
A20: 3. CO2 SUPPLY FROM SPARGE (continuous)
A21: Molar gas feed rate (ideal gas at reactor T,P) | B21: n_gas | C21: mol/min | D21: =(P_tot*1000*Q_gas/1000000/1000)/(R_gas*T_K)*60 -> 2.4121276e-05 | E21: PV=nRT; Q_gas mL/min→m³/s→mol/min
A22: CO2 mole fraction in feed | B22: y_CO2 | C22: fraction | D22: =p_CO2/P_tot -> 0.098692327 | E22: = p_CO2 / P_tot
A23: CO2 delivered by sparge (gas-phase throughput) | B23: CO2_supply | C23: mmol/min | D23: =D21*D22*1000 -> 0.0023805848 | E23: = n_gas × y_CO2 × 1000
A24: Supply : demand ratio (CO2) | B24: CO2_ratio | C24: × | D24: =D23/D18 -> 0.17870753 | E24: = CO2 supplied / CO2 demanded; >1 = non-limiting
A25: CO2 supply status | B25: CO2_status | C25: — | D25: =IF(D24>=1,"OK — non-limiting","LIMITING — raise flow or p_CO2") -> LIMITING — raise flow or p_CO2 | E25: Compares gas-phase CO2 throughput to assimilation demand
A27: 4. PULSED SPARGE REGIME
A28: Concept | E28: Each pulse re-saturates liquid to CO2_sat; cells draw it down; pulse again before it falls below the limiting fraction.
A29: Non-limiting floor (fraction of saturation, Monod-safe) | B29: CO2_floor_frac | C29: fraction | D29: 0.5 | E29: Assumed: keep dissolved CO2 above 50% of saturation
A30: Usable dissolved CO2 inventory per saturation cycle | B30: CO2_inv | C30: mmol | D30: =D9*(1-D29)*V_work_L -> 0.028897092 | E30: = CO2_sat × (1−floor) × V_work_L (mol/m³×L = mmol)
A31: Time to draw down inventory at demand rate | B31: t_drawdown | C31: min | D31: =D30/D18 -> 2.1692685 | E31: = usable inventory / CO2 demand per min = max interval between pulses
A32: Pulse frequency (max, to stay non-limiting) | B32: pulse_freq | C32: pulses/h | D32: =60/D31 -> 27.659093 | E32: = 60 / drawdown interval
A33: CO2 to replace per pulse | B33: CO2_pulse | C33: mmol | D33: =D30 -> 0.028897092 | E33: = inventory consumed = inventory restored
A34: Sparge on-time per pulse (at target flow & p_CO2) | B34: t_sparge | C34: s | D34: =D33/D23*60 -> 728.31915 | E34: = CO2 per pulse / CO2 supply rate (mmol/min) × 60
A35: Duty cycle (sparge on-time fraction) | B35: duty | C35: % | D35: =D34/(D31*60) -> 5.5957352 | E35: = sparge on-time / pulse interval; >100% ⇒ continuous sparge insufficient
A36: Pulsed regime feasibility | B36: pulse_status | C36: — | D36: =IF(D35>1,"INFEASIBLE — needs continuous sparge / higher p_CO2","FEASIBLE — pulse OK") -> INFEASIBLE — needs continuous sparge / higher p_CO2 | E36: If duty cycle exceeds 100%, pulsing cannot keep up

Sheet O2 balance
A1: O2 Balance — electrolytic generation vs consumption + stripping requirement
A2: Anodic O2 (Faraday's law) accumulates; cells consume some; the rest must be stripped to hold dissolved O2 below the hydrogenase inhibition threshold.
A4: Step | B4: Quantity | C4: Unit | D4: Value | E4: Formula / working
A6: 1. O2 GENERATION (electrolytic, Faraday's law)
A7: Applied current | B7: I_app | C7: A | D7: =I_app -> 0.1 | E7: From Inputs (= j × area)
A8: O2 generation rate (anode) | B8: rO2_gen | C8: mol O2/h | D8: =I_app*eta_F/(z_O2*F_const)*3600 -> 0.00088614811 | E8: = I×ηF/(z_O2×F)×3600 (mol/s→mol/h)
A9: O2 generation rate | B9: rO2_gen_mg | C9: mg O2/h | D9: =D8*M_O2*1000 -> 28.356739 | E9: = rO2_gen × M_O2 × 1000
A10: H2 generation rate (cathode, for reference) | B10: rH2_gen | C10: mol H2/h | D10: =I_app*eta_F/(z_H2*F_const)*3600 -> 0.0017722962 | E10: = I×ηF/(z_H2×F)×3600; H2:O2 = 2:1
A12: 2. O2 CONSUMPTION (respiration)
A13: Biomass production rate (rX = µ·X) | B13: rX_o2 | C13: g DCW/h | D13: =mu*X_conc*V_work_L -> 0.02 | E13: = µ × X_conc × V_work_L
A14: O2 consumption rate (respiration) | B14: rO2_cons | C14: mol O2/h | D14: =D13*Y_O2 -> 0.0008 | E14: = rX × Y_O2 (mol O2/gDCW)
A16: 3. NET O2 & STRIPPING REQUIREMENT
A17: Net O2 to remove (generation − consumption) | B17: rO2_net | C17: mol O2/h | D17: =D8-D14 -> 8.6148106e-05 | E17: = rO2_gen − rO2_cons; >0 ⇒ must strip
A18: Net O2 to remove | B18: rO2_net_mg | C18: mg O2/h | D18: =D17*M_O2*1000 -> 2.7567394 | E18: = rO2_net × M_O2 × 1000
A19: Inhibition threshold (dissolved O2) | B19: DO_inhib_uM | C19: µM | D19: =DO_inhib -> 50 | E19: From Inputs (hydrogenase O2-inhibition, PLACEHOLDER)
A20: Max allowed dissolved O2 inventory in liquid | B20: O2_inv_max | C20: µmol | D20: =DO_inhib*V_work_L -> 1 | E20: = DO_inhib (µM = µmol/L) × V_work_L
A21: Time to reach threshold if NOT stripped | B21: t_to_inhib | C21: min | D21: =IF(D17<=0,"never (net≤0)",D20/(D17*1000000)*60) -> 0.69647498 | E21: = max inventory / net O2 rate (µmol/h) × 60
A22: Required O2 strip rate (= net generation) | B22: strip_req | C22: mol O2/h | D22: =MAX(0,D17) -> 8.6148106e-05 | E22: Steady state: strip exactly the net O2 produced
A24: 4. SPARGE STRIPPING CAPACITY & REGIME FLAG
A25: Henry const. O2 at reactor T (van 't Hoff corrected) | B25: H_O2_T_cell | C25: mol/m³/Pa | D25: =H_O2_ref*EXP(H_O2_T*(1/T_K-1/T_ref)) -> 1.1964815e-05 | E25: Hcp(T)=Hcp_ref×exp[Δ(1/T−1/Tref)]
A26: Dissolved O2 at threshold | B26: DO_thr_molm3 | C26: mol/m³ | D26: =DO_inhib/1000 -> 0.05 | E26: = DO_inhib (µM) / 1000 → mmol/L = mol/m³
A27: Gas-phase O2 in equilib. with threshold liquid | B27: pO2_eq | C27: Pa | D27: =D26/D25 -> 4178.9197 | E27: = DO_threshold / H_O2(T) (Henry, inverted)
A28: Molar gas feed rate (sparge, ideal gas) | B28: n_gas_o2 | C28: mol/h | D28: =(P_tot*1000*Q_gas/1000000/1000)/(R_gas*T_K)*3600 -> 0.0014472765 | E28: PV=nRT; same basis as CO2 tab, per hour
A29: Max O2 strip capacity of sparge (gas can carry) | B29: strip_cap | C29: mol O2/h | D29: =D28*(D27/(P_tot*1000)) -> 5.9689637e-05 | E29: = gas molar flow × (pO2_eq / P_tot); O2 the exit gas can remove at threshold
A30: Stripping capacity : requirement ratio | B30: strip_ratio | C30: × | D30: =IF(D22=0,"n/a (no net O2)",D29/D22) -> 0.69287231 | E30: = strip capacity / strip requirement; ≥1 = can hold below threshold
A31: O2 REGIME | B31: O2_regime | C31: — | D31: =IF(D22=0,"OK — net O2 ≤0, no stripping needed",IF(D29>=D22,"OK — sparge strips enough","O2-INHIBITED — stripping insufficient")) -> O2-INHIBITED — stripping insufficient | E31: Flags when reactor goes O2-inhibited at current sparge rate

Sheet Sensitivity
A1: Sensitivity — response surfaces
A2: Each cell recomputes the model from its own axis values + Inputs constants, so the grids are live. Centre cell (yellow) ≈ current base case.
A4: TABLE 1 — CO2 supply : demand ratio (≥1 = non-limiting)
A5: Rows: gas flow (mL/min) ↓ Cols: growth rate µ (1/h) →
A6: Q_gas \ µ | B6: =mu*0.4 -> 0.1 | C6: =mu*0.7 -> 0.175 | D6: =mu*0.85 -> 0.2125 | E6: =mu -> 0.25 | F6: =mu*1.15 -> 0.2875 | G6: =mu*1.3 -> 0.325 | H6: =mu*1.6 -> 0.4
A7: =Q_gas*0.2 -> 2 | B7: =((P_tot*1000*$A7/1000000/1000)/(R_gas*T_K)*60*(p_CO2/P_tot)*1000)/(B$6*X_conc*V_work_L*C_frac/12.011/60*1000) -> 0.089353763 | C7: =((P_tot*1000*$A7/1000000/1000)/(R_gas*T_K)*60*(p_CO2/P_tot)*1000)/(C$6*X_conc*V_work_L*C_frac/12.011/60*1000) -> 0.051059293 | D7: =((P_tot*1000*$A7/1000000/1000)/(R_gas*T_K)*60*(p_CO2/P_tot)*1000)/(D$6*X_conc*V_work_L*C_frac/12.011/60*1000) -> 0.04204883 | E7: =((P_tot*1000*$A7/1000000/1000)/(R_gas*T_K)*60*(p_CO2/P_tot)*1000)/(E$6*X_conc*V_work_L*C_frac/12.011/60*1000) -> 0.035741505 | F7: =((P_tot*1000*$A7/1000000/1000)/(R_gas*T_K)*60*(p_CO2/P_tot)*1000)/(F$6*X_conc*V_work_L*C_frac/12.011/60*1000) -> 0.03107957 | G7: =((P_tot*1000*$A7/1000000/1000)/(R_gas*T_K)*60*(p_CO2/P_tot)*1000)/(G$6*X_conc*V_work_L*C_frac/12.011/60*1000) -> 0.027493466 | H7: =((P_tot*1000*$A7/1000000/1000)/(R_gas*T_K)*60*(p_CO2/P_tot)*1000)/(H$6*X_conc*V_work_L*C_frac/12.011/60*1000) -> 0.022338441
A8: =Q_gas*0.5 -> 5 | B8: =((P_tot*1000*$A8/1000000/1000)/(R_gas*T_K)*60*(p_CO2/P_tot)*1000)/(B$6*X_conc*V_work_L*C_frac/12.011/60*1000) -> 0.22338441 | C8: =((P_tot*1000*$A8/1000000/1000)/(R_gas*T_K)*60*(p_CO2/P_tot)*1000)/(C$6*X_conc*V_work_L*C_frac/12.011/60*1000) -> 0.12764823 | D8: =((P_tot*1000*$A8/1000000/1000)/(R_gas*T_K)*60*(p_CO2/P_tot)*1000)/(D$6*X_conc*V_work_L*C_frac/12.011/60*1000) -> 0.10512207 | E8: =((P_tot*1000*$A8/1000000/1000)/(R_gas*T_K)*60*(p_CO2/P_tot)*1000)/(E$6*X_conc*V_work_L*C_frac/12.011/60*1000) -> 0.089353763 | F8: =((P_tot*1000*$A8/1000000/1000)/(R_gas*T_K)*60*(p_CO2/P_tot)*1000)/(F$6*X_conc*V_work_L*C_frac/12.011/60*1000) -> 0.077698924 | G8: =((P_tot*1000*$A8/1000000/1000)/(R_gas*T_K)*60*(p_CO2/P_tot)*1000)/(G$6*X_conc*V_work_L*C_frac/12.011/60*1000) -> 0.068733664 | H8: =((P_tot*1000*$A8/1000000/1000)/(R_gas*T_K)*60*(p_CO2/P_tot)*1000)/(H$6*X_conc*V_work_L*C_frac/12.011/60*1000) -> 0.055846102
A9: =Q_gas*0.75 -> 7.5 | B9: =((P_tot*1000*$A9/1000000/1000)/(R_gas*T_K)*60*(p_CO2/P_tot)*1000)/(B$6*X_conc*V_work_L*C_frac/12.011/60*1000) -> 0.33507661 | C9: =((P_tot*1000*$A9/1000000/1000)/(R_gas*T_K)*60*(p_CO2/P_tot)*1000)/(C$6*X_conc*V_work_L*C_frac/12.011/60*1000) -> 0.19147235 | D9: =((P_tot*1000*$A9/1000000/1000)/(R_gas*T_K)*60*(p_CO2/P_tot)*1000)/(D$6*X_conc*V_work_L*C_frac/12.011/60*1000) -> 0.15768311 | E9: =((P_tot*1000*$A9/1000000/1000)/(R_gas*T_K)*60*(p_CO2/P_tot)*1000)/(E$6*X_conc*V_work_L*C_frac/12.011/60*1000) -> 0.13403064 | F9: =((P_tot*1000*$A9/1000000/1000)/(R_gas*T_K)*60*(p_CO2/P_tot)*1000)/(F$6*X_conc*V_work_L*C_frac/12.011/60*1000) -> 0.11654839 | G9: =((P_tot*1000*$A9/1000000/1000)/(R_gas*T_K)*60*(p_CO2/P_tot)*1000)/(G$6*X_conc*V_work_L*C_frac/12.011/60*1000) -> 0.1031005 | H9: =((P_tot*1000*$A9/1000000/1000)/(R_gas*T_K)*60*(p_CO2/P_tot)*1000)/(H$6*X_conc*V_work_L*C_frac/12.011/60*1000) -> 0.083769153
A10: =Q_gas -> 10 | B10: =((P_tot*1000*$A10/1000000/1000)/(R_gas*T_K)*60*(p_CO2/P_tot)*1000)/(B$6*X_conc*V_work_L*C_frac/12.011/60*1000) -> 0.44676881 | C10: =((P_tot*1000*$A10/1000000/1000)/(R_gas*T_K)*60*(p_CO2/P_tot)*1000)/(C$6*X_conc*V_work_L*C_frac/12.011/60*1000) -> 0.25529647 | D10: =((P_tot*1000*$A10/1000000/1000)/(R_gas*T_K)*60*(p_CO2/P_tot)*1000)/(D$6*X_conc*V_work_L*C_frac/12.011/60*1000) -> 0.21024415 | E10: =((P_tot*1000*$A10/1000000/1000)/(R_gas*T_K)*60*(p_CO2/P_tot)*1000)/(E$6*X_conc*V_work_L*C_frac/12.011/60*1000) -> 0.17870753 | F10: =((P_tot*1000*$A10/1000000/1000)/(R_gas*T_K)*60*(p_CO2/P_tot)*1000)/(F$6*X_conc*V_work_L*C_frac/12.011/60*1000) -> 0.15539785 | G10: =((P_tot*1000*$A10/1000000/1000)/(R_gas*T_K)*60*(p_CO2/P_tot)*1000)/(G$6*X_conc*V_work_L*C_frac/12.011/60*1000) -> 0.13746733 | H10: =((P_tot*1000*$A10/1000000/1000)/(R_gas*T_K)*60*(p_CO2/P_tot)*1000)/(H$6*X_conc*V_work_L*C_frac/12.011/60*1000) -> 0.1116922
A11: =Q_gas*1.5 -> 15 | B11: =((P_tot*1000*$A11/1000000/1000)/(R_gas*T_K)*60*(p_CO2/P_tot)*1000)/(B$6*X_conc*V_work_L*C_frac/12.011/60*1000) -> 0.67015322 | C11: =((P_tot*1000*$A11/1000000/1000)/(R_gas*T_K)*60*(p_CO2/P_tot)*1000)/(C$6*X_conc*V_work_L*C_frac/12.011/60*1000) -> 0.3829447 | D11: =((P_tot*1000*$A11/1000000/1000)/(R_gas*T_K)*60*(p_CO2/P_tot)*1000)/(D$6*X_conc*V_work_L*C_frac/12.011/60*1000) -> 0.31536622 | E11: =((P_tot*1000*$A11/1000000/1000)/(R_gas*T_K)*60*(p_CO2/P_tot)*1000)/(E$6*X_conc*V_work_L*C_frac/12.011/60*1000) -> 0.26806129 | F11: =((P_tot*1000*$A11/1000000/1000)/(R_gas*T_K)*60*(p_CO2/P_tot)*1000)/(F$6*X_conc*V_work_L*C_frac/12.011/60*1000) -> 0.23309677 | G11: =((P_tot*1000*$A11/1000000/1000)/(R_gas*T_K)*60*(p_CO2/P_tot)*1000)/(G$6*X_conc*V_work_L*C_frac/12.011/60*1000) -> 0.20620099 | H11: =((P_tot*1000*$A11/1000000/1000)/(R_gas*T_K)*60*(p_CO2/P_tot)*1000)/(H$6*X_conc*V_work_L*C_frac/12.011/60*1000) -> 0.16753831
A12: =Q_gas*2 -> 20 | B12: =((P_tot*1000*$A12/1000000/1000)/(R_gas*T_K)*60*(p_CO2/P_tot)*1000)/(B$6*X_conc*V_work_L*C_frac/12.011/60*1000) -> 0.89353763 | C12: =((P_tot*1000*$A12/1000000/1000)/(R_gas*T_K)*60*(p_CO2/P_tot)*1000)/(C$6*X_conc*V_work_L*C_frac/12.011/60*1000) -> 0.51059293 | D12: =((P_tot*1000*$A12/1000000/1000)/(R_gas*T_K)*60*(p_CO2/P_tot)*1000)/(D$6*X_conc*V_work_L*C_frac/12.011/60*1000) -> 0.4204883 | E12: =((P_tot*1000*$A12/1000000/1000)/(R_gas*T_K)*60*(p_CO2/P_tot)*1000)/(E$6*X_conc*V_work_L*C_frac/12.011/60*1000) -> 0.35741505 | F12: =((P_tot*1000*$A12/1000000/1000)/(R_gas*T_K)*60*(p_CO2/P_tot)*1000)/(F$6*X_conc*V_work_L*C_frac/12.011/60*1000) -> 0.3107957 | G12: =((P_tot*1000*$A12/1000000/1000)/(R_gas*T_K)*60*(p_CO2/P_tot)*1000)/(G$6*X_conc*V_work_L*C_frac/12.011/60*1000) -> 0.27493466 | H12: =((P_tot*1000*$A12/1000000/1000)/(R_gas*T_K)*60*(p_CO2/P_tot)*1000)/(H$6*X_conc*V_work_L*C_frac/12.011/60*1000) -> 0.22338441
A13: =Q_gas*3 -> 30 | B13: =((P_tot*1000*$A13/1000000/1000)/(R_gas*T_K)*60*(p_CO2/P_tot)*1000)/(B$6*X_conc*V_work_L*C_frac/12.011/60*1000) -> 1.3403064 | C13: =((P_tot*1000*$A13/1000000/1000)/(R_gas*T_K)*60*(p_CO2/P_tot)*1000)/(C$6*X_conc*V_work_L*C_frac/12.011/60*1000) -> 0.7658894 | D13: =((P_tot*1000*$A13/1000000/1000)/(R_gas*T_K)*60*(p_CO2/P_tot)*1000)/(D$6*X_conc*V_work_L*C_frac/12.011/60*1000) -> 0.63073244 | E13: =((P_tot*1000*$A13/1000000/1000)/(R_gas*T_K)*60*(p_CO2/P_tot)*1000)/(E$6*X_conc*V_work_L*C_frac/12.011/60*1000) -> 0.53612258 | F13: =((P_tot*1000*$A13/1000000/1000)/(R_gas*T_K)*60*(p_CO2/P_tot)*1000)/(F$6*X_conc*V_work_L*C_frac/12.011/60*1000) -> 0.46619355 | G13: =((P_tot*1000*$A13/1000000/1000)/(R_gas*T_K)*60*(p_CO2/P_tot)*1000)/(G$6*X_conc*V_work_L*C_frac/12.011/60*1000) -> 0.41240198 | H13: =((P_tot*1000*$A13/1000000/1000)/(R_gas*T_K)*60*(p_CO2/P_tot)*1000)/(H$6*X_conc*V_work_L*C_frac/12.011/60*1000) -> 0.33507661
A16: TABLE 2 — O2 stripping capacity : requirement ratio (<1 = O2-inhibited)
A17: Rows: gas flow (mL/min) ↓ Cols: current density j (A/m²) →
A18: Q_gas \ j | B18: =j*0.4 -> 40 | C18: =j*0.7 -> 70 | D18: =j*0.85 -> 85 | E18: =j -> 100 | F18: =j*1.15 -> 115 | G18: =j*1.3 -> 130 | H18: =j*1.6 -> 160
A19: =Q_gas*0.2 -> 2 | B19: =MIN(5,((P_tot*1000*$A19/1000000/1000)/(R_gas*T_K)*3600*(((DO_inhib/1000)/(H_O2_ref*EXP(H_O2_T*(1/T_K-1/T_ref))))/(P_tot*1000)))/MAX(0.000000000001,(B$18*A_elec_m2*eta_F/(z_O2*F_const)*3600)-(mu*X_conc*V_work_L*Y_O2))) -> 5 | C19: =MIN(5,((P_tot*1000*$A19/1000000/1000)/(R_gas*T_K)*3600*(((DO_inhib/1000)/(H_O2_ref*EXP(H_O2_T*(1/T_K-1/T_ref))))/(P_tot*1000)))/MAX(0.000000000001,(C$18*A_elec_m2*eta_F/(z_O2*F_const)*3600)-(mu*X_conc*V_work_L*Y_O2))) -> 5 | D19: =MIN(5,((P_tot*1000*$A19/1000000/1000)/(R_gas*T_K)*3600*(((DO_inhib/1000)/(H_O2_ref*EXP(H_O2_T*(1/T_K-1/T_ref))))/(P_tot*1000)))/MAX(0.000000000001,(D$18*A_elec_m2*eta_F/(z_O2*F_const)*3600)-(mu*X_conc*V_work_L*Y_O2))) -> 5 | E19: =MIN(5,((P_tot*1000*$A19/1000000/1000)/(R_gas*T_K)*3600*(((DO_inhib/1000)/(H_O2_ref*EXP(H_O2_T*(1/T_K-1/T_ref))))/(P_tot*1000)))/MAX(0.000000000001,(E$18*A_elec_m2*eta_F/(z_O2*F_const)*3600)-(mu*X_conc*V_work_L*Y_O2))) -> 0.13857446 | F19: =MIN(5,((P_tot*1000*$A19/1000000/1000)/(R_gas*T_K)*3600*(((DO_inhib/1000)/(H_O2_ref*EXP(H_O2_T*(1/T_K-1/T_ref))))/(P_tot*1000)))/MAX(0.000000000001,(F$18*A_elec_m2*eta_F/(z_O2*F_const)*3600)-(mu*X_conc*V_work_L*Y_O2))) -> 0.054493586 | G19: =MIN(5,((P_tot*1000*$A19/1000000/1000)/(R_gas*T_K)*3600*(((DO_inhib/1000)/(H_O2_ref*EXP(H_O2_T*(1/T_K-1/T_ref))))/(P_tot*1000)))/MAX(0.000000000001,(G$18*A_elec_m2*eta_F/(z_O2*F_const)*3600)-(mu*X_conc*V_work_L*Y_O2))) -> 0.033915286 | H19: =MIN(5,((P_tot*1000*$A19/1000000/1000)/(R_gas*T_K)*3600*(((DO_inhib/1000)/(H_O2_ref*EXP(H_O2_T*(1/T_K-1/T_ref))))/(P_tot*1000)))/MAX(0.000000000001,(H$18*A_elec_m2*eta_F/(z_O2*F_const)*3600)-(mu*X_conc*V_work_L*Y_O2))) -> 0.019322132
A20: =Q_gas*0.5 -> 5 | B20: =MIN(5,((P_tot*1000*$A20/1000000/1000)/(R_gas*T_K)*3600*(((DO_inhib/1000)/(H_O2_ref*EXP(H_O2_T*(1/T_K-1/T_ref))))/(P_tot*1000)))/MAX(0.000000000001,(B$18*A_elec_m2*eta_F/(z_O2*F_const)*3600)-(mu*X_conc*V_work_L*Y_O2))) -> 5 | C20: =MIN(5,((P_tot*1000*$A20/1000000/1000)/(R_gas*T_K)*3600*(((DO_inhib/1000)/(H_O2_ref*EXP(H_O2_T*(1/T_K-1/T_ref))))/(P_tot*1000)))/MAX(0.000000000001,(C$18*A_elec_m2*eta_F/(z_O2*F_const)*3600)-(mu*X_conc*V_work_L*Y_O2))) -> 5 | D20: =MIN(5,((P_tot*1000*$A20/1000000/1000)/(R_gas*T_K)*3600*(((DO_inhib/1000)/(H_O2_ref*EXP(H_O2_T*(1/T_K-1/T_ref))))/(P_tot*1000)))/MAX(0.000000000001,(D$18*A_elec_m2*eta_F/(z_O2*F_const)*3600)-(mu*X_conc*V_work_L*Y_O2))) -> 5 | E20: =MIN(5,((P_tot*1000*$A20/1000000/1000)/(R_gas*T_K)*3600*(((DO_inhib/1000)/(H_O2_ref*EXP(H_O2_T*(1/T_K-1/T_ref))))/(P_tot*1000)))/MAX(0.000000000001,(E$18*A_elec_m2*eta_F/(z_O2*F_const)*3600)-(mu*X_conc*V_work_L*Y_O2))) -> 0.34643615 | F20: =MIN(5,((P_tot*1000*$A20/1000000/1000)/(R_gas*T_K)*3600*(((DO_inhib/1000)/(H_O2_ref*EXP(H_O2_T*(1/T_K-1/T_ref))))/(P_tot*1000)))/MAX(0.000000000001,(F$18*A_elec_m2*eta_F/(z_O2*F_const)*3600)-(mu*X_conc*V_work_L*Y_O2))) -> 0.13623396 | G20: =MIN(5,((P_tot*1000*$A20/1000000/1000)/(R_gas*T_K)*3600*(((DO_inhib/1000)/(H_O2_ref*EXP(H_O2_T*(1/T_K-1/T_ref))))/(P_tot*1000)))/MAX(0.000000000001,(G$18*A_elec_m2*eta_F/(z_O2*F_const)*3600)-(mu*X_conc*V_work_L*Y_O2))) -> 0.084788214 | H20: =MIN(5,((P_tot*1000*$A20/1000000/1000)/(R_gas*T_K)*3600*(((DO_inhib/1000)/(H_O2_ref*EXP(H_O2_T*(1/T_K-1/T_ref))))/(P_tot*1000)))/MAX(0.000000000001,(H$18*A_elec_m2*eta_F/(z_O2*F_const)*3600)-(mu*X_conc*V_work_L*Y_O2))) -> 0.04830533
A21: =Q_gas*0.75 -> 7.5 | B21: =MIN(5,((P_tot*1000*$A21/1000000/1000)/(R_gas*T_K)*3600*(((DO_inhib/1000)/(H_O2_ref*EXP(H_O2_T*(1/T_K-1/T_ref))))/(P_tot*1000)))/MAX(0.000000000001,(B$18*A_elec_m2*eta_F/(z_O2*F_const)*3600)-(mu*X_conc*V_work_L*Y_O2))) -> 5 | C21: =MIN(5,((P_tot*1000*$A21/1000000/1000)/(R_gas*T_K)*3600*(((DO_inhib/1000)/(H_O2_ref*EXP(H_O2_T*(1/T_K-1/T_ref))))/(P_tot*1000)))/MAX(0.000000000001,(C$18*A_elec_m2*eta_F/(z_O2*F_const)*3600)-(mu*X_conc*V_work_L*Y_O2))) -> 5 | D21: =MIN(5,((P_tot*1000*$A21/1000000/1000)/(R_gas*T_K)*3600*(((DO_inhib/1000)/(H_O2_ref*EXP(H_O2_T*(1/T_K-1/T_ref))))/(P_tot*1000)))/MAX(0.000000000001,(D$18*A_elec_m2*eta_F/(z_O2*F_const)*3600)-(mu*X_conc*V_work_L*Y_O2))) -> 5 | E21: =MIN(5,((P_tot*1000*$A21/1000000/1000)/(R_gas*T_K)*3600*(((DO_inhib/1000)/(H_O2_ref*EXP(H_O2_T*(1/T_K-1/T_ref))))/(P_tot*1000)))/MAX(0.000000000001,(E$18*A_elec_m2*eta_F/(z_O2*F_const)*3600)-(mu*X_conc*V_work_L*Y_O2))) -> 0.51965423 | F21: =MIN(5,((P_tot*1000*$A21/1000000/1000)/(R_gas*T_K)*3600*(((DO_inhib/1000)/(H_O2_ref*EXP(H_O2_T*(1/T_K-1/T_ref))))/(P_tot*1000)))/MAX(0.000000000001,(F$18*A_elec_m2*eta_F/(z_O2*F_const)*3600)-(mu*X_conc*V_work_L*Y_O2))) -> 0.20435095 | G21: =MIN(5,((P_tot*1000*$A21/1000000/1000)/(R_gas*T_K)*3600*(((DO_inhib/1000)/(H_O2_ref*EXP(H_O2_T*(1/T_K-1/T_ref))))/(P_tot*1000)))/MAX(0.000000000001,(G$18*A_elec_m2*eta_F/(z_O2*F_const)*3600)-(mu*X_conc*V_work_L*Y_O2))) -> 0.12718232 | H21: =MIN(5,((P_tot*1000*$A21/1000000/1000)/(R_gas*T_K)*3600*(((DO_inhib/1000)/(H_O2_ref*EXP(H_O2_T*(1/T_K-1/T_ref))))/(P_tot*1000)))/MAX(0.000000000001,(H$18*A_elec_m2*eta_F/(z_O2*F_const)*3600)-(mu*X_conc*V_work_L*Y_O2))) -> 0.072457995
A22: =Q_gas -> 10 | B22: =MIN(5,((P_tot*1000*$A22/1000000/1000)/(R_gas*T_K)*3600*(((DO_inhib/1000)/(H_O2_ref*EXP(H_O2_T*(1/T_K-1/T_ref))))/(P_tot*1000)))/MAX(0.000000000001,(B$18*A_elec_m2*eta_F/(z_O2*F_const)*3600)-(mu*X_conc*V_work_L*Y_O2))) -> 5 | C22: =MIN(5,((P_tot*1000*$A22/1000000/1000)/(R_gas*T_K)*3600*(((DO_inhib/1000)/(H_O2_ref*EXP(H_O2_T*(1/T_K-1/T_ref))))/(P_tot*1000)))/MAX(0.000000000001,(C$18*A_elec_m2*eta_F/(z_O2*F_const)*3600)-(mu*X_conc*V_work_L*Y_O2))) -> 5 | D22: =MIN(5,((P_tot*1000*$A22/1000000/1000)/(R_gas*T_K)*3600*(((DO_inhib/1000)/(H_O2_ref*EXP(H_O2_T*(1/T_K-1/T_ref))))/(P_tot*1000)))/MAX(0.000000000001,(D$18*A_elec_m2*eta_F/(z_O2*F_const)*3600)-(mu*X_conc*V_work_L*Y_O2))) -> 5 | E22: =MIN(5,((P_tot*1000*$A22/1000000/1000)/(R_gas*T_K)*3600*(((DO_inhib/1000)/(H_O2_ref*EXP(H_O2_T*(1/T_K-1/T_ref))))/(P_tot*1000)))/MAX(0.000000000001,(E$18*A_elec_m2*eta_F/(z_O2*F_const)*3600)-(mu*X_conc*V_work_L*Y_O2))) -> 0.69287231 | F22: =MIN(5,((P_tot*1000*$A22/1000000/1000)/(R_gas*T_K)*3600*(((DO_inhib/1000)/(H_O2_ref*EXP(H_O2_T*(1/T_K-1/T_ref))))/(P_tot*1000)))/MAX(0.000000000001,(F$18*A_elec_m2*eta_F/(z_O2*F_const)*3600)-(mu*X_conc*V_work_L*Y_O2))) -> 0.27246793 | G22: =MIN(5,((P_tot*1000*$A22/1000000/1000)/(R_gas*T_K)*3600*(((DO_inhib/1000)/(H_O2_ref*EXP(H_O2_T*(1/T_K-1/T_ref))))/(P_tot*1000)))/MAX(0.000000000001,(G$18*A_elec_m2*eta_F/(z_O2*F_const)*3600)-(mu*X_conc*V_work_L*Y_O2))) -> 0.16957643 | H22: =MIN(5,((P_tot*1000*$A22/1000000/1000)/(R_gas*T_K)*3600*(((DO_inhib/1000)/(H_O2_ref*EXP(H_O2_T*(1/T_K-1/T_ref))))/(P_tot*1000)))/MAX(0.000000000001,(H$18*A_elec_m2*eta_F/(z_O2*F_const)*3600)-(mu*X_conc*V_work_L*Y_O2))) -> 0.096610659
A23: =Q_gas*1.5 -> 15 | B23: =MIN(5,((P_tot*1000*$A23/1000000/1000)/(R_gas*T_K)*3600*(((DO_inhib/1000)/(H_O2_ref*EXP(H_O2_T*(1/T_K-1/T_ref))))/(P_tot*1000)))/MAX(0.000000000001,(B$18*A_elec_m2*eta_F/(z_O2*F_const)*3600)-(mu*X_conc*V_work_L*Y_O2))) -> 5 | C23: =MIN(5,((P_tot*1000*$A23/1000000/1000)/(R_gas*T_K)*3600*(((DO_inhib/1000)/(H_O2_ref*EXP(H_O2_T*(1/T_K-1/T_ref))))/(P_tot*1000)))/MAX(0.000000000001,(C$18*A_elec_m2*eta_F/(z_O2*F_const)*3600)-(mu*X_conc*V_work_L*Y_O2))) -> 5 | D23: =MIN(5,((P_tot*1000*$A23/1000000/1000)/(R_gas*T_K)*3600*(((DO_inhib/1000)/(H_O2_ref*EXP(H_O2_T*(1/T_K-1/T_ref))))/(P_tot*1000)))/MAX(0.000000000001,(D$18*A_elec_m2*eta_F/(z_O2*F_const)*3600)-(mu*X_conc*V_work_L*Y_O2))) -> 5 | E23: =MIN(5,((P_tot*1000*$A23/1000000/1000)/(R_gas*T_K)*3600*(((DO_inhib/1000)/(H_O2_ref*EXP(H_O2_T*(1/T_K-1/T_ref))))/(P_tot*1000)))/MAX(0.000000000001,(E$18*A_elec_m2*eta_F/(z_O2*F_const)*3600)-(mu*X_conc*V_work_L*Y_O2))) -> 1.0393085 | F23: =MIN(5,((P_tot*1000*$A23/1000000/1000)/(R_gas*T_K)*3600*(((DO_inhib/1000)/(H_O2_ref*EXP(H_O2_T*(1/T_K-1/T_ref))))/(P_tot*1000)))/MAX(0.000000000001,(F$18*A_elec_m2*eta_F/(z_O2*F_const)*3600)-(mu*X_conc*V_work_L*Y_O2))) -> 0.40870189 | G23: =MIN(5,((P_tot*1000*$A23/1000000/1000)/(R_gas*T_K)*3600*(((DO_inhib/1000)/(H_O2_ref*EXP(H_O2_T*(1/T_K-1/T_ref))))/(P_tot*1000)))/MAX(0.000000000001,(G$18*A_elec_m2*eta_F/(z_O2*F_const)*3600)-(mu*X_conc*V_work_L*Y_O2))) -> 0.25436464 | H23: =MIN(5,((P_tot*1000*$A23/1000000/1000)/(R_gas*T_K)*3600*(((DO_inhib/1000)/(H_O2_ref*EXP(H_O2_T*(1/T_K-1/T_ref))))/(P_tot*1000)))/MAX(0.000000000001,(H$18*A_elec_m2*eta_F/(z_O2*F_const)*3600)-(mu*X_conc*V_work_L*Y_O2))) -> 0.14491599
A24: =Q_gas*2 -> 20 | B24: =MIN(5,((P_tot*1000*$A24/1000000/1000)/(R_gas*T_K)*3600*(((DO_inhib/1000)/(H_O2_ref*EXP(H_O2_T*(1/T_K-1/T_ref))))/(P_tot*1000)))/MAX(0.000000000001,(B$18*A_elec_m2*eta_F/(z_O2*F_const)*3600)-(mu*X_conc*V_work_L*Y_O2))) -> 5 | C24: =MIN(5,((P_tot*1000*$A24/1000000/1000)/(R_gas*T_K)*3600*(((DO_inhib/1000)/(H_O2_ref*EXP(H_O2_T*(1/T_K-1/T_ref))))/(P_tot*1000)))/MAX(0.000000000001,(C$18*A_elec_m2*eta_F/(z_O2*F_const)*3600)-(mu*X_conc*V_work_L*Y_O2))) -> 5 | D24: =MIN(5,((P_tot*1000*$A24/1000000/1000)/(R_gas*T_K)*3600*(((DO_inhib/1000)/(H_O2_ref*EXP(H_O2_T*(1/T_K-1/T_ref))))/(P_tot*1000)))/MAX(0.000000000001,(D$18*A_elec_m2*eta_F/(z_O2*F_const)*3600)-(mu*X_conc*V_work_L*Y_O2))) -> 5 | E24: =MIN(5,((P_tot*1000*$A24/1000000/1000)/(R_gas*T_K)*3600*(((DO_inhib/1000)/(H_O2_ref*EXP(H_O2_T*(1/T_K-1/T_ref))))/(P_tot*1000)))/MAX(0.000000000001,(E$18*A_elec_m2*eta_F/(z_O2*F_const)*3600)-(mu*X_conc*V_work_L*Y_O2))) -> 1.3857446 | F24: =MIN(5,((P_tot*1000*$A24/1000000/1000)/(R_gas*T_K)*3600*(((DO_inhib/1000)/(H_O2_ref*EXP(H_O2_T*(1/T_K-1/T_ref))))/(P_tot*1000)))/MAX(0.000000000001,(F$18*A_elec_m2*eta_F/(z_O2*F_const)*3600)-(mu*X_conc*V_work_L*Y_O2))) -> 0.54493586 | G24: =MIN(5,((P_tot*1000*$A24/1000000/1000)/(R_gas*T_K)*3600*(((DO_inhib/1000)/(H_O2_ref*EXP(H_O2_T*(1/T_K-1/T_ref))))/(P_tot*1000)))/MAX(0.000000000001,(G$18*A_elec_m2*eta_F/(z_O2*F_const)*3600)-(mu*X_conc*V_work_L*Y_O2))) -> 0.33915286 | H24: =MIN(5,((P_tot*1000*$A24/1000000/1000)/(R_gas*T_K)*3600*(((DO_inhib/1000)/(H_O2_ref*EXP(H_O2_T*(1/T_K-1/T_ref))))/(P_tot*1000)))/MAX(0.000000000001,(H$18*A_elec_m2*eta_F/(z_O2*F_const)*3600)-(mu*X_conc*V_work_L*Y_O2))) -> 0.19322132
A25: =Q_gas*3 -> 30 | B25: =MIN(5,((P_tot*1000*$A25/1000000/1000)/(R_gas*T_K)*3600*(((DO_inhib/1000)/(H_O2_ref*EXP(H_O2_T*(1/T_K-1/T_ref))))/(P_tot*1000)))/MAX(0.000000000001,(B$18*A_elec_m2*eta_F/(z_O2*F_const)*3600)-(mu*X_conc*V_work_L*Y_O2))) -> 5 | C25: =MIN(5,((P_tot*1000*$A25/1000000/1000)/(R_gas*T_K)*3600*(((DO_inhib/1000)/(H_O2_ref*EXP(H_O2_T*(1/T_K-1/T_ref))))/(P_tot*1000)))/MAX(0.000000000001,(C$18*A_elec_m2*eta_F/(z_O2*F_const)*3600)-(mu*X_conc*V_work_L*Y_O2))) -> 5 | D25: =MIN(5,((P_tot*1000*$A25/1000000/1000)/(R_gas*T_K)*3600*(((DO_inhib/1000)/(H_O2_ref*EXP(H_O2_T*(1/T_K-1/T_ref))))/(P_tot*1000)))/MAX(0.000000000001,(D$18*A_elec_m2*eta_F/(z_O2*F_const)*3600)-(mu*X_conc*V_work_L*Y_O2))) -> 5 | E25: =MIN(5,((P_tot*1000*$A25/1000000/1000)/(R_gas*T_K)*3600*(((DO_inhib/1000)/(H_O2_ref*EXP(H_O2_T*(1/T_K-1/T_ref))))/(P_tot*1000)))/MAX(0.000000000001,(E$18*A_elec_m2*eta_F/(z_O2*F_const)*3600)-(mu*X_conc*V_work_L*Y_O2))) -> 2.0786169 | F25: =MIN(5,((P_tot*1000*$A25/1000000/1000)/(R_gas*T_K)*3600*(((DO_inhib/1000)/(H_O2_ref*EXP(H_O2_T*(1/T_K-1/T_ref))))/(P_tot*1000)))/MAX(0.000000000001,(F$18*A_elec_m2*eta_F/(z_O2*F_const)*3600)-(mu*X_conc*V_work_L*Y_O2))) -> 0.81740379 | G25: =MIN(5,((P_tot*1000*$A25/1000000/1000)/(R_gas*T_K)*3600*(((DO_inhib/1000)/(H_O2_ref*EXP(H_O2_T*(1/T_K-1/T_ref))))/(P_tot*1000)))/MAX(0.000000000001,(G$18*A_elec_m2*eta_F/(z_O2*F_const)*3600)-(mu*X_conc*V_work_L*Y_O2))) -> 0.50872928 | H25: =MIN(5,((P_tot*1000*$A25/1000000/1000)/(R_gas*T_K)*3600*(((DO_inhib/1000)/(H_O2_ref*EXP(H_O2_T*(1/T_K-1/T_ref))))/(P_tot*1000)))/MAX(0.000000000001,(H$18*A_elec_m2*eta_F/(z_O2*F_const)*3600)-(mu*X_conc*V_work_L*Y_O2))) -> 0.28983198
A27: Note: Table 2 ratio capped at 5.00 for readability (when current density is low, net O2→0 and the ratio diverges). <1.00 (red) = O2-inhibited regime.

Sheet Na2CO3 electrolyte
A1: Na₂CO₃ Electrolyte Assessment — sodium carbonate vs current electrolyte
A2: Scores 1 (poor) – 5 (excellent), blue = editable judgement. Weighted total drives the go/no-go. Replace the ‘current electrolyte’ column header with your actual baseline.
A4: Criterion | B4: Weight | C4: Na₂CO₃ score | D4: Current score | E4: Na₂CO₃ wtd | F4: Current wtd | G4: Rationale / notes
A5: Ionic conductivity | B5: 0.2 | C5: 4 | D5: 4 | E5: =B5*C5 -> 0.8 | F5: =B5*D5 -> 0.8 | G5: Na₂CO₃ gives good ionic strength; conductivity rises with concentration. Verify vs current at working molarity.
A6: Cathode buffering / pH stability | B6: 0.25 | C6: 5 | D6: 3 | E6: =B6*C6 -> 1.25 | F6: =B6*D6 -> 0.75 | G6: Carbonate/bicarbonate is a natural buffer near pH 9–10; resists cathodic alkalinisation from H2 evolution. Strong advantage if cells tolerate that pH.
A7: Carbonate as carbon source | B7: 0.2 | C7: 4 | D7: 2 | E7: =B7*C7 -> 0.8 | F7: =B7*D7 -> 0.4 | G7: CO₃²⁻/HCO₃⁻ adds a dissolved inorganic carbon reservoir buffering CO₂ supply to cells — synergistic with autotrophy. Confirm C. necator uptake of HCO₃⁻.
A8: Electrode compatibility / corrosion | B8: 0.2 | C8: 3 | D8: 4 | E8: =B8*C8 -> 0.6 | F8: =B8*D8 -> 0.8 | G8: Alkaline carbonate is generally benign for Ni/stainless anodes but can scale with Ca²⁺; check electrode material and scaling risk.
A9: Safety / handling | B9: 0.15 | C9: 4 | D9: 3 | E9: =B9*C9 -> 0.6 | F9: =B9*D9 -> 0.45 | G9: Na₂CO₃ is mild alkali, low hazard, food-grade grades available — favourable for aseptic bioprocess vs caustic electrolytes.
A11: Weight total (must = 100%) | B11: =SUM(B5:B9) -> 1
A12: WEIGHTED TOTAL (out of 5) | E12: =SUM(E5:E9) -> 4.05 | F12: =SUM(F5:F9) -> 3.2
A14: Na₂CO₃ advantage (weighted points) | E14: =E12-F12 -> 0.85
A16: RECOMMENDATION
A17: =IF(ABS(B11-1)>0.001,"⚠ Fix weights — must sum to 100% before reading the verdict",IF(E12-F12>=0.5,"GO — adopt Na₂CO₃: clear weighted advantage. Pilot at working molarity and confirm cell tolerance to pH 9–10.",IF(E12-F12>0,"CONDITIONAL GO — Na₂CO₃ marginally ahead; trial side-by-side before committing.","NO-GO — retain current electrolyte; Na₂CO₃ does not outscore it on the weighted criteria."))) -> GO — adopt Na₂CO₃: clear weighted advantage. Pilot at working molarity and confirm cell tolerance to pH 9–10.
A18: Decision threshold: ≥0.50 weighted-point lead ⇒ GO; >0 ⇒ conditional; ≤0 ⇒ no-go. Adjust weights/scores to reflect AMYBO priorities.

Sheet Assumptions & sources
A1: Assumptions & Sources — reviewer checklist
A2: Every value a reviewer must check. RED status = unverified assumption or literature placeholder — confirm before relying on outputs. Blank Inputs cells (red) need a measured value; do not invent.
A4: Item | B4: Inputs cell | C4: Type | D4: Status | E4: Source / what's needed to verify
A5: CONSTANTS (verified handbook)
A6: Faraday constant | B6: Inputs!D41 | C6: Constant | D6: Verified | E6: CODATA 2018: 96485 C/mol
A7: Ideal gas constant | B7: Inputs!D42 | C7: Constant | D7: Verified | E7: CODATA: 8.314 J/mol/K
A8: Henry const. CO₂ (Hcp, 298K) + T-dependence | B8: Inputs!D43:D44 | C8: Constant | D8: Verified | E8: Sander, Atmos. Chem. Phys. 15 (2015): Hcp≈3.3e-4 mol/m³/Pa, −ΔsolH/R≈2400 K. Confirm exact value for your medium ionic strength (salting-out lowers solubility).
A9: Henry const. O₂ (Hcp, 298K) + T-dependence | B9: Inputs!D45:D46 | C9: Constant | D9: Verified | E9: Sander (2015): Hcp≈1.3e-5 mol/m³/Pa, −ΔsolH/R≈1500 K. Same salting-out caveat.
A10: Molar masses CO₂ / O₂; electron stoichiometry | B10: Inputs!D48:D51 | C10: Constant | D10: Verified | E10: Handbook: M_CO₂=44.01, M_O₂=32.00 g/mol; z=2 (H₂), z=4 (O₂) from water electrolysis half-reactions.
A12: ASSUMPTIONS / PLACEHOLDERS (must verify)
A13: Working volumes 20 / 40 mL; headspace 10 mL | B13: Inputs!D7,D8,D12 | C13: Design | D13: Assumption | E13: Confirm against actual reactor geometry.
A14: Temperature 30 °C | B14: Inputs!D13 | C14: Design | D14: Assumption | E14: C. necator optimum ~30 °C; confirm your setpoint.
A15: Electrode area 10 cm² | B15: Inputs!D15 | C15: Design | D15: Assumption | E15: Measure geometric (and ideally electrochemically active) area.
A16: Gas partial pressures CO₂/O₂/H₂ (10/5/60 kPa) | B16: Inputs!D20:D22 | C16: Design | D16: Assumption | E16: Set by gas-blending scheme; confirm feed composition.
A17: Target sparge flow 10 mL/min | B17: Inputs!D23 | C17: Design | D17: Assumption | E17: Operating target; the sensitivity tab shows model response across flow.
A18: Specific growth rate µ = 0.25 /h | B18: Inputs!D27 | C18: Biology | D18: PLACEHOLDER | E18: C. necator autotrophic µmax ~0.2–0.4 /h in literature; measure your strain/conditions.
A19: Target OD 10; biomass/OD 0.4 gDCW/L | B19: Inputs!D28:D29 | C19: Biology | D19: PLACEHOLDER | E19: Calibrate OD→DCW for your strain & spectrophotometer.
A20: Biomass C-fraction 0.48 gC/gDCW | B20: Inputs!D31 | C20: Biology | D20: PLACEHOLDER | E20: Typical microbial value; refine via elemental (CHN) analysis.
A21: O₂ demand 0.04 mol O₂/gDCW | B21: Inputs!D32 | C21: Biology | D21: PLACEHOLDER | E21: Knallgas respiratory O₂ yield; verify by off-gas / respirometry.
A22: Hydrogenase O₂-inhibition threshold 50 µM | B22: Inputs!D33 | C22: Biology | D22: PLACEHOLDER | E22: [NiFe] hydrogenase O₂-sensitivity is strain/enzyme specific; determine the tolerated dissolved-O₂ ceiling experimentally. DRIVES the O₂ regime flag.
A23: Current density 100 A/m²; Faradaic eff. 0.95 | B23: Inputs!D36,D38 | C23: Electrolysis | D23: Assumption | E23: Set by power supply / cell design; measure actual gas-evolution efficiency.
A24: CO₂ non-limiting floor 50% of saturation | B24: CO2 dosing!D29 | C24: Model | D24: Assumption | E24: Monod-safe floor; tighten if K_s for CO₂ is known.
A26: NOT YET SUPPLIED — leave blank, do not invent
A27: Current electrolyte identity & properties (baseline for Na₂CO₃ comparison) | B27: Na2CO3 tab col D | C27: Data gap | D27: NEEDED | E27: Supply the actual current electrolyte and its measured conductivity/pH so the comparison is real, not indicative.
A28: Volumetric gas-liquid mass-transfer coeff (kLa) for CO₂ and O₂ | B28: — | C28: Data gap | D28: NEEDED | E28: Model assumes sparge reaches gas-liquid equilibrium. Real stripping/dosing is kLa-limited; measure kLa to convert these equilibrium bounds into rates.
A29: CO₂ / HCO₃⁻ speciation & medium buffering | B29: — | C29: Data gap | D29: NEEDED | E29: At pH>6 much dissolved inorganic carbon is HCO₃⁻/CO₃²⁻, not CO₂(aq). Henry's law here gives CO₂(aq) only; add carbonate equilibria for total DIC available to cells.
A31: KEY MODEL RESULTS (live links)
A32: CO₂ supply : demand ratio | D32: ='CO2 dosing'!D24 -> 0.17870753 | E32: ='CO2 dosing'!D25 -> LIMITING — raise flow or p_CO2
A33: Pulsed sparge feasibility | E33: ='CO2 dosing'!D36 -> INFEASIBLE — needs continuous sparge / higher p_CO2
A34: Time to O₂ inhibition if unstripped (min) | D34: ='O2 balance'!D21 -> 0.69647498
A35: O₂ strip capacity : requirement | D35: ='O2 balance'!D30 -> 0.69287231 | E35: ='O2 balance'!D31 -> O2-INHIBITED — stripping insufficient
A36: Na₂CO₃ verdict | E36: ='Na2CO3 electrolyte'!A17 -> GO — adopt Na₂CO₃: clear weighted advantage. Pilot at working molarity and confirm cell tolerance to pH 9–10.
