Workbook
Name A_anode: Chemistry!$D$130
Name A_anode_wet: Electrochemistry!$D$46
Name A_cath_wet: Electrochemistry!$D$47
Name A_DH: Chemistry!$D$186
Name a_int: 'Mass Transfer'!$D$49
Name a_surf: 'Mass Transfer'!$D$71
Name A_x: Calibrations!$D$186
Name A_x: Geometry!$D$21
Name A_x: 'Mass Transfer'!$D$17
Name alk_NaHCO3_gL: Chemistry!$D$308
Name alk_needed: Chemistry!$D$306
Name alk_pH_target: Chemistry!$D$303
Name alk_pH_target_c: Chemistry!$D$304
Name alk_resid_t: Chemistry!$D$305
Name anode_dia: Electrochemistry!$D$42
Name anode_j_cont: Electrochemistry!$D$50
Name anode_j_max: Electrochemistry!$D$51
Name anode_material: Electrochemistry!$D$63
Name anode_shape: Electrochemistry!$D$41
Name b_anode: Electrochemistry!$D$107
Name b_cath: Electrochemistry!$D$109
Name beta_nonC: Chemistry!$D$295
Name bio_CO2: Biology!$D$12
Name bio_H2: Biology!$D$10
Name bio_O2: Biology!$D$11
Name bleach_flag: Chemistry!$D$109
Name bleach_rate: Chemistry!$D$107
Name bleach_t1ppm: Chemistry!$D$108
Name bp_const: Calibrations!$D$166
Name bubble_regime: 'Mass Transfer'!$D$64
Name buffer_caution_frac: Chemistry!$D$238
Name buffer_flag: Chemistry!$D$219
Name C_air_CO2: 'Mass Transfer'!$D$146
Name C_CO2_mf: 'Mass Transfer'!$D$382
Name C_cycle_peak: 'Mass Transfer'!$D$199
Name C_cycle_start: 'Mass Transfer'!$D$198
Name C_cycle_start_b: Biology!$D$97
Name C_eff: Chemistry!$D$145
Name C_eff_Cl2: Chemistry!$D$226
Name C_eff_hi: Chemistry!$D$157
Name C_eff_hi_Cl2: Chemistry!$D$260
Name C_eff_lo: Chemistry!$D$156
Name C_eff_lo_Cl2: Chemistry!$D$259
Name C_H2_sat: Biology!$D$41
Name C_sat_CO2: 'Mass Transfer'!$D$145
Name ca_rho_0: Calibrations!$D$181
Name ca_rho_k: Calibrations!$D$182
Name cal_Dint: Calibrations!$D$75
Name cal_DO_impair: Calibrations!$D$105
Name cal_DO_min: Calibrations!$D$103
Name cal_DO_opt: Calibrations!$D$104
Name cal_DO_toxic: Calibrations!$D$106
Name cal_etaF: Calibrations!$D$31
Name cal_etaF_OER: Calibrations!$D$32
Name cal_flow: Calibrations!$D$60
Name cal_gerrit_int: Calibrations!$D$17
Name cal_gerrit_slope: Calibrations!$D$16
Name cal_hs: Calibrations!$D$76
Name cal_hs_fill: Calibrations!$D$77
Name cal_j_ceiling: Calibrations!$D$137

Sheet Summary
A1: Parameter | B1: Name | C1: Unit | D1: Value | E1: Source | F1: Comment
A2: Reactor | B2: Reactor_sel | D2: ed04 | E2: select | F2: Active build. Choose from the values below. Dropdown.
A3: Electrode | B3: electrode_sel | D3: MMO tube | E3: select | F3: Anode material and sparger. Choose from the list (Electrochemistry A35:A38). Dropdown.
A4: HOB organism | B4: organism_sel | D4: Xanthobacter tagetidis | E4: select | F4: The HOB strain; sets the DO band the schedule targets.
A5: Media | B5: media_sel | D5: AMYBO03 | E5: select | F5: Growth medium.
A6: Electrolysis power | B6: led_intensity | C6: % | D6: 3 | E6: input | F6: LED channel D %, the AEP-Plugin 'electrolysis_power' setting (runtime-clamped 0–10 %); drives the electrolysis current via Gerrit's Law. The model needs 3–10 % (fit range ∩ plugin clamp), which the D6 validation enforces.
A7: Stirrer rate | B7: stir_rpm_set | C7: rpm | D7: 1000 | E7: input | F7: Stir rate; sets tip speed and surface O2 transfer.
A8: Temperature setpoint | B8: temp_C | C8: °C | D8: 30 | E8: input | F8: Temperature setpoint; sets Henry solubilities and rates.
A9: Media volume | B9: media_volume | C9: mL | E9: input/blank | F9: Liquid charged; leave blank to use the reactor's recommended max working volume.
A10: Ambient pressure | B10: P_atm_set | C10: Pa | E10: input/blank | F10: blank = default 101325 Pa
A11: Vent model | B11: vent_model_sel | C11: - | D11: Open vent | E11: select | F11: "Outflow only" = check valve or sealed cap that holds a vacuum (no air ever enters). "Open vent" = a plain needle or tube with no forced flow (air drawn back after each pulse; Q_backdraw, Mass Transfer D385, an estimate). "Air exchange" = measured bidirectional exchange at Q_vent (Mass Transfer D142). The MEP0.3 and AEP0.1.1 caps vent through 2 × 1/16" ID tubes to 0.2 µm PTFE filters, AEP0.2 through needles to the same filters, with no check valve: Open vent (owner, T5). Anything else → #N/A throughout.
A12: O₂ sizing phase | B12: O2_phase_sel | C12: - | D12: Growth | E12: select | F12: "Growth" sizes the headline schedule (rows 18–21) on the O₂ surplus after knallgas uptake; "Lag" on the whole net electrolytic O₂ plus H₂ (no uptake yet). Anything else → #N/A. Both phases are shown either way, and the start-up schedule (rows 31 and 33) is always the lag one. If the chosen phase’s DO target is unreachable (rows 65–66), the schedule falls back to the legacy O₂ flush guard (Mass Transfer D89).
A13: Added NaHCO₃ (on top of the recipe) | B13: NaHCO3_add_gL | C13: g/L | E13: input/blank | F13: NaHCO₃ added to the medium; blank = none. It feeds the charge balance, ionic strength, conductivity and CO₂ storage (Chemistry D44, D185, D180, D296), so pH, DO and the schedule respond. Row 80 then shows what is still needed. After a large addition (pH up by more than 0.1) re-enter the DIC reference pH, Chemistry D291 (D310 says when).
A14: N₂ dose (mean flow of timed pulses) | B14: N2_sweep_set | C14: mL/min | E14: input/blank | F14: Blank = none, the owner’s preference: fix the medium first (rows 80–81). If N₂ must be used it is pulsed apart from the CO₂ pulses (owner, T7); the balance takes its mean flow as an inert inflow with no O₂ or CO₂ (Mass Transfer D424–D425), exact for the mean-field fractions; the sawtooth of a separate N₂ flush is a model improvement (row 135).
A15: Solenoid command resolution | B15: pulse_res_set | C15: s | D15: 0.05 | E15: input | F15: Smallest step the AEP-Plugin solenoid timer is commanded in; the pulse is rounded to it (row 19). Same solenoid as ed04, whose logged pulses (0.2, 0.25, 0.4, 0.6 s) are all 0.05 s multiples (owner, T8).
A17: Results | B17: Name | C17: Unit | D17: Value | E17: Source | F17: Comment | G17: Override
A18: CO₂ sparge duration | B18: res_spg_dur | C18: s | D18: =IF('Mass Transfer'!has_cal=0,"calibrate this reactor first (CO₂ flow section of the Calibrations tab, or a CO2 flows row)",'Mass Transfer'!spg_dur_opt) -> 0.67407652 | E18: =HYPERLINK("#'Mass Transfer'!D90","→ Mass") -> → Mass | F18: How long to open the CO2 solenoid each dose.
A19: CO₂ sparge duration (as run) | B19: res_spg_dur_run | C19: s | D19: =IF(NOT(ISNUMBER(res_spg_dur)),res_spg_dur,'Mass Transfer'!spg_dur) -> 0.65 | F19: Pulse actually evaluated by every operating check below. Summary override wins, then Manual mode, otherwise the optimum rounded to the pulse resolution.
A20: ="CO₂ sparge interval ("&vent_model_sel&", sized on "&O2_phase_sel&")" -> CO₂ sparge interval (Open vent, sized on Growth) | B20: res_spg_int | C20: min | D20: =IF('Mass Transfer'!has_cal=0,"calibrate this reactor first (CO₂ flow section of the Calibrations tab, or a CO2 flows row)",'Mass Transfer'!spg_int_opt) -> 7.4219028 | E20: =HYPERLINK("#'Mass Transfer'!D91","→ Mass") -> → Mass | F20: Time between doses: the shortest of the carbon-limited, headspace-O₂-dilution and pH-ceiling intervals (rows 28–30), plus the H₂ flammability screen when the schedule is sized on Lag (row 12); row 22 says which binds. Sized for the vent model in row 11 and the pulse in row 19.
A21: CO₂ sparge interval (as run) | B21: res_spg_int_run | C21: min | D21: =IF(NOT(ISNUMBER(res_spg_int)),res_spg_int,'Mass Transfer'!spg_int) -> 7.19 | F21: Interval actually evaluated below, in decimal minutes. Default converts the commanded pulse to the ideal delivery duty and rounds down to 0.01 min; overrides and Manual mode are evaluated directly.
A22: Binding constraint on the interval | B22: res_binding | D22: ='Mass Transfer'!opt_binding -> O2-DILUTION (headspace O2 sets the interval) | E22: =HYPERLINK("#'Mass Transfer'!D94","→ Mass Transfer") -> → Mass Transfer | F22: Which upper bound sets row 20: carbon supply, headspace-O₂ dilution, the pH ceiling (rows 28–30) or, when sized on Lag, the H₂ flammability screen; an invalid selector or an unreachable target is named here instead.
A23: Cycle-average pH (activity scale, as a probe reads) | B23: res_pH | D23: =Chemistry!pH_meas -> 6.4877019 | E23: =HYPERLINK("#Chemistry!D220","→ Chemistry") -> → Chemistry | F23: pH at the cycle-average dissolved CO₂ of the schedule in use, on the activity scale a probe reads; the trough just after a pulse is lower. Colour: green inside the HOB band (Chemistry pH_band_lo–pH_band_hi), red outside pH_red_lo–pH_red_hi (Chemistry D299–D300), amber between; thresholds in rows 159–162.
A24: Cycle-mean DO (sawtooth, sizing phase) | B24: res_DO_ss | C24: mg/L | D24: ='Mass Transfer'!DO_ss -> 2.2745651 | E24: =HYPERLINK("#'Mass Transfer'!D108","→ Mass") -> → Mass | F24: Time-mean dissolved O₂ of the sawtooth model at the schedule in use, on the sizing phase; near the target by construction when O₂ dilution binds. Both phases, mean and peak: rows 59–62.
A25: Effective biocidal chlorine | B25: res_Cl2 | C25: mg/L | D25: =Chemistry!C_eff_Cl2 -> 0 | E25: =HYPERLINK("#Chemistry!D226","→ Chemistry") -> → Chemistry | F25: =IF(Chemistry!Cl_model_check<>"OK",Chemistry!Cl_model_check,"Effective chlorine on the as-Cl2 basis; zero for chloride-free medium. Lifetime and potency require measurement.") -> Effective chlorine on the as-Cl2 basis; zero for chloride-free medium. Lifetime and potency require measurement.
A27: SCHEDULE BOUNDS AND THE START-UP (LAG-PHASE) SCHEDULE
A28: Carbon-limited sparge interval | B28: res_spg_int_carbon | C28: min | D28: ='Mass Transfer'!spg_int_carbon -> 184.72314 | E28: =HYPERLINK("#'Mass Transfer'!D112","→ Mass") -> → Mass | F28: Interval set by CO₂ supply alone. The schedule uses it only when it is shorter than the O₂-dilution interval.
A29: DO-limited sparge interval | B29: res_spg_int_DO | C29: min | D29: ='Mass Transfer'!spg_int_DO -> 7.4219028 | E29: =HYPERLINK("#'Mass Transfer'!D185","→ Mass Transfer") -> → Mass Transfer | F29: Longest interval that still dilutes headspace O₂ enough to hold the DO target on the sizing phase (row 12). #N/A = the target is unreachable at this surface kLa.
A30: pH-ceiling interval (longest keeping pH at or under the band ceiling) | C30: min | D30: ='Mass Transfer'!spg_int_pH -> 212.48606 | E30: =HYPERLINK("#'Mass Transfer'!D432","→ Mass Transfer") -> → Mass Transfer | F30: Longest interval keeping pH at or under the band ceiling, for the pulse in use. Far above the other bounds, or "no pH bound", unless N₂ dilutes the headspace; then it stops pH overshooting the band once CO₂ no longer has to dilute O₂. Row 55 warns if a long interval lets the carbon pool run dry.
A31: Start-up (lag-phase) interval, same pulse | B31: res_spg_int_su | C31: min | D31: ='Mass Transfer'!spg_int_su_run -> 1.21 | E31: =HYPERLINK("#'Mass Transfer'!D547","→ Mass Transfer") -> → Mass Transfer | F31: Owner asked for both schedules (T4). Until uptake starts: the shortest of the lag O₂ bound (the legacy guard when the lag DO target is unreachable), the interval clearing the H₂ flammability screen (Biology D92), the lag pH ceiling and the carbon bound. Select Lag in row 12 to evaluate every output at exactly this schedule.
A32: As-run duty ÷ optimised duty | C32: × | D32: =IF(AND(ISNUMBER(res_spg_dur_run),ISNUMBER(res_spg_int_run),ISNUMBER('Mass Transfer'!duty_actual)),('Mass Transfer'!pulse_V0+'Mass Transfer'!Q_CO2_fit*res_spg_dur_run)/('Mass Transfer'!Q_CO2/60)/(60*res_spg_int_run)/'Mass Transfer'!duty_actual,"calibrate this reactor first (CO₂ flow section of the Calibrations tab, or a CO2 flows row)") -> 1.0006813 | E32: =HYPERLINK("#'Mass Transfer'!D93","→ Mass") -> → Mass | F32: Delivered CO₂ duty of the schedule as run (rows 19 and 21) against the sized duty; 1 = rounding the interval has not moved the CO₂ dose. The sizing already uses the commanded pulse (Mass Transfer D320), so a ratio near 1 also means the DO target holds.
A33: Start-up schedule: lag-phase DO and H₂ | B33: res_su_state | D33: =IF(ISNUMBER('Mass Transfer'!spg_int_su_run),"DO "&TEXT('Mass Transfer'!DO_avg_su_mgL,"0.0")&" mg/L mean, "&TEXT('Mass Transfer'!DO_peak_su_mgL,"0.0")&" peak; H₂ "&TEXT('Mass Transfer'!y_H2_end_su,"0%")&" before each pulse; set by "&'Mass Transfer'!su_binding,"no executable start-up schedule") -> DO 4.1 mg/L mean, 4.1 peak; H₂ 3% before each pulse; set by the legacy O₂ flush guard (lag DO target unreachable) | E33: =HYPERLINK("#'Mass Transfer'!D556","→ Mass Transfer") -> → Mass Transfer | F33: The lag sawtooth evaluated at the start-up interval (rows 61–62 show the lag phase at the headline schedule instead).
A34: Checks | D34: Value | E34: Source | F34: Comment
A35: Vial geometry consistent? | B35: chk_geom | D35: =Geometry!geom_check -> VIAL GEOMETRY INCONSISTENT - measure the true headspace (protocols/vial-geometry.md) | E35: =HYPERLINK("#Geometry!D90","→ Geometry") -> → Geometry | F35: Red until the vial headspace is measured (vial-geometry.md); while red, the pulse above is provisional (~4x uncertain). Once a headspace and its working fill are included on the Calibrations tab it reads OK, because the measured headspace replaces the cylinder approximation.
A36: Reactor calibrated? | B36: chk_cal | D36: ='Mass Transfer'!cal_warning -> calibrated: ed04 (flow from CO2 flows) | E36: =HYPERLINK("#'Mass Transfer'!D120","→ Mass") -> → Mass | F36: Red = no CO₂-flow calibration for this reactor (neither an included run in the Calibrations tab CO₂ flow section nor a CO2 flows row); results read 'calibrate first' (flow-calibration.md). Green names the source in use.
A37: O₂ within the organism band (mean vs optimum, peak vs impairment)? | B37: chk_DO_opt | D37: ='Mass Transfer'!DO_peak_band -> organism band unknown – peak 2.5 mg/L is under the inhibition ceiling | E37: =HYPERLINK("#'Mass Transfer'!D374","→ Mass Transfer") -> → Mass Transfer | F37: Rule (owner decision, option a): the cycle-MEAN dissolved O₂ is tested against the organism optimum — the schedule is sized on the mean, and the optimum is a time-averaged quantity — and the sawtooth PEAK (just before a pulse, sizing phase) against the impairment threshold. With the band unmeasured, the peak is tested against the inhibition ceiling. Not a tautology: the peak is not what the schedule is sized on.
A38: O₂ above organism minimum? | B38: chk_DO_min | D38: ='Mass Transfer'!DO_ss_vs_min -> minimum DO unknown - measure | E38: =HYPERLINK("#'Mass Transfer'!D110","→ Mass") -> → Mass | F38: Minimum DO is a data gap for most organisms (dissolved-oxygen.md).
A39: Can the interval relax to the carbon-limited one? | B39: chk_relax | D39: ='Mass Transfer'!sched_regime -> Do NOT relax: at the carbon-limited interval (185 min) the cycle-mean DO would be ≈13 mg/L, above the 10.1 mg/L inhibition ceiling (peaks higher) | E39: =HYPERLINK("#'Mass Transfer'!D113","→ Mass") -> → Mass | F39: Green only if CO₂ dosed for carbon alone would still hold dissolved O₂ at the target; otherwise it states the DO the longer interval would give.
A40: H₂ headspace flammable? | B40: chk_H2 | D40: =Biology!H2_safety -> POTENTIAL FLAMMABILITY (lag screen): H₂ 9% mean, 15% before each pulse; O₂ 5% mean, 8% before each pulse – until uptake starts, sparge every ≤2.3 min or sweep ≥1.0 mL/min N₂; vent to a hood; no ignition sources | E40: =HYPERLINK("#Biology!D44","→ Biology") -> → Biology | F40: Nominal lag-phase hazard screen, not safety certification. Predictions depend on unmeasured vent/transfer behaviour; validate mixture-specific limits, sampling and gas clearance before operation.
A41: Bubble model valid? | B41: chk_bubble | D41: ='Mass Transfer'!bubble_regime -> Dynamic | E41: =HYPERLINK("#'Mass Transfer'!D64","→ Mass") -> → Mass | F41: 'Sinter OOR' = sinter pore size out of the validated bubble range; sparge mass-transfer is approximate (expected for the porosity-0 disc).
A42: CO₂ supply meets demand? | B42: chk_CO2_supply | D42: =IFERROR("×"&TEXT('Mass Transfer'!CO2_sd_ratio,"0.0")&IF('Mass Transfer'!CO2_sd_ratio>=1," OK"," SHORTFALL (CO2 < demand)")&" delivered; ×"&TEXT('Mass Transfer'!CO2_uptake_ratio,"0.0")&" absorbed per pulse (row 77)","calibrate this reactor first") -> ×49.8 OK delivered; ×2.5 absorbed per pulse (row 77) | E42: =HYPERLINK("#'Mass Transfer'!D126","→ Mass") -> → Mass | F42: Ratio of CO₂ delivered to carbon demand (should be ≥ 1), with the absorbed ratio beside it (row 77): delivered counts gas the pulse expels unabsorbed, absorbed does not.
...

Sheet Geometry
A1: GEOMETRY
A2: Parameter | B2: Name | C2: Unit | D2: Value | E2: Source / assumption
A4: IMPORTS (from other tabs)
A5: (import) Reactor selection | B5: reactor_sel | C5: - | D5: =Summary!Reactor_sel -> ed04 | E5: =HYPERLINK("#Summary!D2","→ Summary") -> → Summary
A6: (import) Media volume (set) | B6: media_volume | C6: mL | D6: =Summary!media_volume -> 0 | E6: =HYPERLINK("#Summary!D9","→ Summary") -> → Summary
A18: Vial outer diameter | B18: vial_OD | C18: mm | D18: =VLOOKUP(rx_ver,tbl_rxtype,MATCH("vial OD (mm)",tbl_rxtype_hdr,0),FALSE) -> 27.48 | E18: Selected by rx_ver; invalid version returns an error.
A19: Vial wall thickness | B19: vial_wall | C19: mm | D19: 1.1 | E19: Borosilicate vial; Pioreactor publish neither wall nor internal diameter, so wall estimated ~1.1 mm (typical for this glass-vial class).
A20: Vial internal diameter | B20: vial_ID | C20: mm | D20: =vial_OD-2*vial_wall -> 25.28 | E20: OD minus two wall thicknesses.
A21: Internal cross-sectional area | B21: A_x | C21: mm² | D21: =PI()/4*vial_ID^2 -> 501.931 | E21: Uniform-cylinder body approximation (neck excluded - see headspace).
A22: Internal usable depth | B22: D_int | C22: mm | D22: =VLOOKUP(rx_ver,tbl_rxtype,MATCH("usable depth (mm)",tbl_rxtype_hdr,0),FALSE) -> 55 | E22: Physical cap-to-base depth from the reactor-type table, selected by rx_ver. The Calibrations volume-equivalent depth (D75) is not a physical length and does not replace it.
A23: Recommended max working volume (datum) | B23: V_max | C23: mL | D23: =VLOOKUP(rx_ver,tbl_rxtype,MATCH("max working (mL)",tbl_rxtype_hdr,0),FALSE) -> 16 | E23: Selected by rx_ver.
A24: Total internal vial volume | B24: V_vial_total | C24: mL | D24: =IF(ISNUMBER(cal_Vtot),cal_Vtot,VLOOKUP(rx_ver,tbl_rxtype,MATCH("total vial (mL)",tbl_rxtype_hdr,0),FALSE)) -> 20 | E24: Selected by rx_ver.
A25: Bare liquid level (datum height) | B25: h_datum | C25: mm | D25: =V_max*1000/A_x -> 31.876891 | E25: Height the bare max volume reaches with no inserts.
A26: Electrode rod diameter | B26: rod_d | C26: mm | D26: 6 | E26: 6 mm rod electrodes.
A27: Number of electrodes | B27: rod_n | C27: - | D27: 2 | E27: Anode + cathode.
A28: Electrode tip clearance above base | B28: elec_clear | C28: mm | D28: 22 | E28: Held constant across builds (OD clear zone). 22 mm ↔ 33 mm insertion in AEP0.1.1. Input.
A29: Electrode insertion depth (derived) | B29: elec_ins | C29: mm | D29: =D_int-elec_clear -> 33 | E29: Cap underside -> tip. Increases for the taller AEP0.2 to keep clearance constant.
A30: Sparge tube OD | B30: spg_OD | C30: mm | D30: 3.175 | E30: 1/8" OD Flexelene 135C.
A31: Sparge tube ID | B31: spg_ID | C31: mm | D31: 1.5875 | E31: 1/16" ID.
A32: Sparge release height (= anode tip) | B32: spg_tip_h | C32: mm | D32: =elec_clear -> 22 | E32: CO₂ released near anode tip.
A33: Efflux tube OD | B33: eff_OD | C33: mm | D33: 3.175 | E33: 1/8" OD Flexelene 135C.
A34: Efflux tube ID | B34: eff_ID | C34: mm | D34: 1.5875 | E34: 1/16" ID.
A35: Electrode submerged length (@datum) | B35: elec_sub_L | C35: mm | D35: =MAX(0,h_datum-elec_clear) -> 9.8768913 | E35: For displacement bookkeeping.
A36: Electrode displaced volume | B36: elec_disp | C36: mL | D36: =rod_n*(PI()/4*rod_d^2)*elec_sub_L/1000 -> 0.55852505 | E36: Submerged rod volume.
A37: Sparge tube displaced volume | B37: spg_disp | C37: mL | D37: =(PI()/4*spg_OD^2)*MAX(0,h_datum-spg_tip_h)/1000 -> 0.078198355 | E37: Submerged sparge-tube volume.
A38: Efflux tube submerged length | B38: eff_sub_L | C38: mm | D38: =(eff_OD+eff_ID)/2 -> 2.38125 | E38: 45 deg cut; level held at top of the ID opening, so wall is wetted from tip up to (OD+ID)/2.
A39: Efflux tube displaced volume | B39: eff_disp | C39: mL | D39: =(PI()/4*(eff_OD^2-eff_ID^2))*eff_sub_L/1000 -> 0.014139811 | E39: Annular wall only (bore is open to withdrawal). 45 deg approximation.
A40: Total displaced volume | B40: disp_tot | C40: mL | D40: =elec_disp+spg_disp+eff_disp -> 0.65086321 | E40: Sum of submerged inserts.
A41: LIQUID VOLUME TO CHARGE | B41: V_charge | C41: mL | D41: =IF(media_volume>0,media_volume,ROUND(V_max-disp_tot,0)) -> 15 | E41: Integer mL to charge so the level matches the bare datum despite inserts.
A42: Resulting liquid level | B42: h_actual | C42: mm | D42: =(V_charge+disp_tot)*1000/A_x -> 31.181304 | E42: Level achieved by the integer charge (displacement taken at datum; sub-mm error).
A43: Sparge depth / bubble path length | B43: sparge_depth | C43: mm | D43: =MAX(0,h_actual-spg_tip_h) -> 9.1813041 | E43: Release point to surface.
A44: Gas-liquid interfacial area | B44: interface_A | C44: mm² | D44: =A_x-(rod_n*(PI()/4*rod_d^2)+(PI()/4*spg_OD^2)+(PI()/4*eff_OD^2)) -> 429.54773 | E44: Free surface = cross-section minus inserts piercing it.
A45: Extra headspace tube OD | B45: xtube_OD | C45: mm | D45: =eff_OD -> 3.175 | E45: 3 further 1/8" tubes (gas-out, etc.) through the cap.
A46: Number of extra headspace tubes | B46: xtube_n | C46: - | D46: 3 | E46: Protrude through the cap into headspace. 1x media in, 2x gas out
A47: Extra tube protrusion | B47: xtube_pro | C47: mm | D47: 5 | E47: Each protrudes ~5 mm below cap (45 deg cut). Input.
A48: Total in-vial insert volume | B48: V_inserts | C48: mL | D48: =(rod_n*(PI()/4*rod_d^2)*elec_ins+(PI()/4*spg_OD^2)*spg_len+(PI()/4*(eff_OD^2-eff_ID^2))*(D_int-h_actual)+xtube_n*(PI()/4*xtube_OD^2)*xtube_pro)/1000 -> 2.3875715 | E48: In-vial inserts: electrodes & sparge solid; efflux annular (open bore); extra tubes solid.
A49: Headspace gas volume | B49: headspace_V | C49: mL | D49: =IF(AND(ISNUMBER(cal_hs),ISNUMBER(cal_hs_fill)),cal_hs-(V_charge-cal_hs_fill),V_vial_total-V_charge-V_inserts) -> 2.6124285 | E49: Measured when the Calibrations vial-geometry runs exist for this reactor type (headspace at the measured working fill, shifted by any difference between that fill and V_charge); otherwise total vial volume − liquid charged − inserts.
A50: Sparge tube in-vial length | B50: spg_len | C50: mm | D50: =D_int-spg_tip_h -> 33 | E50: Cap underside to release point; tracks spg_tip_h.
A51: Reactor type (resolved from reactor) | B51: rx_ver | D51: =VLOOKUP(reactor_sel,tbl_reactor,MATCH("Type",tbl_reactor_hdr,0),FALSE) -> MEP0.3 | E51: Looked up from the reactor table (tbl_reactor, rows 58–80) by the Summary reactor (D2).
A52: Stir-bar length (from reactor type) | B52: stir_bar_L | D52: =VLOOKUP(rx_ver,tbl_rxtype,MATCH("stir bar L (mm)",tbl_rxtype_hdr,0),FALSE) -> 12 | E52: Looked up from the reactor-type table (tbl_rxtype, rows 83–87) by the resolved type (D51).
...

Sheet Electrochemistry
A1: ELECTROCHEMISTRY
A2: Parameter | B2: Name | C2: Unit | D2: Value | E2: Source / assumption
A4: IMPORTS (from other tabs)
A5: (import) Temperature (absolute) | B5: T_K | C5: K | D5: =Biology!T_K -> 303.15 | E5: =HYPERLINK("#Biology!D18","→ Biology") -> → Biology
A6: (import) Surface pressure | B6: P_atm | C6: Pa | D6: =Biology!P_atm -> 101325 | E6: =HYPERLINK("#Biology!D19","→ Biology") -> → Biology
A7: (import) Ideal gas constant | B7: R_gas | C7: J/mol/K | D7: ='Mass Transfer'!R_gas -> 8.3144626 | E7: =HYPERLINK("#'Mass Transfer'!D101","→ Mass Transfer") -> → Mass Transfer
A8: (import) Electrode selection | B8: electrode_sel | D8: =Summary!electrode_sel -> MMO tube | E8: =HYPERLINK("#Summary!D3","→ Summary") -> → Summary
A10: LED intensity setpoint (Pioreactor LED_D) | B10: intensity | C10: % | D10: =Summary!led_intensity -> 3 | E10: Electrode drive via LED_D channel. Input.
A11: Gerrit's Law - slope | B11: gerrit_slope | C11: mA/% | D11: =IF(ISNUMBER(cal_gerrit_slope),cal_gerrit_slope,gerrit_slope_default) -> 1.03 | E11: Gerrit's Law fit (slope) - from LED-current calibration; see protocol gerrit-current.md
A12: Gerrit's Law - intercept | B12: gerrit_int | C12: mA | D12: =IF(ISNUMBER(cal_gerrit_int),cal_gerrit_int,gerrit_int_default) -> 2.6 | E12: Gerrit's Law fit (intercept); calibration-derived constant
A13: Gerrit's Law - min valid intensity | B13: gerrit_min | C13: % | D13: 3 | E13: Fit validated from 3%.
A14: Gerrit's Law - max valid intensity | B14: gerrit_max | C14: % | D14: 25 | E14: Fit validated to 25%; above this constant-current may fail as cell V nears the 5 V rail.
A15: Faraday constant | B15: F_const | C15: C/mol | D15: 96485.332 | E15: NIST CODATA (exact, SI 2019).
A16: Electrons per H₂ | B16: z_e_H2 | C16: - | D16: 2 | E16: 2H⁺ + 2e⁻ -> H₂.
A17: Electrons per O₂ | B17: z_e_O2 | C17: - | D17: 4 | E17: 2H₂O -> O₂ + 4H⁺ + 4e⁻.
A18: Faradaic efficiency – H₂ at cathode (HER share) | B18: etaF | C18: - | D18: =IF(ISNUMBER(cal_etaF),cal_etaF,etaF_calc) -> 0.96404431 | E18: Cathodic H₂ faradaic efficiency: a measured value from the Calibrations tab if there is one, otherwise CALCULATED (D88, etaF_calc) from the cathodic O₂ reduction competing for the current. Neutral-pH HER on stainless peaks near 97% before that competition is counted, so the calculated value remains an upper bound.
A19: Electrolysis current (Gerrit's Law) | B19: I_app | C19: A | D19: =IF(AND(intensity>=gerrit_min,intensity<=MIN(gerrit_max,power_max)),(gerrit_slope*intensity+gerrit_int)/1000,NA()) -> 0.00569 | E19: Empirical current fit only over the intersection of its validated range and the plugin runtime limit. Off and below-range commands return #N/A rather than inventing current from the fit intercept. Above-limit requests also return #N/A; the plugin clamps them.
A20: Gerrit's Law validity flag | B20: I_valid | C20: - | D20: =IF(AND(intensity>=gerrit_min,intensity<=MIN(gerrit_max,power_max)),"OK","OUT – no schedule: power outside validated fit/runtime range") -> OK | E20: Model domain: gerrit_min through MIN(gerrit_max,power_max), currently 3–10%. Lower-power/start-up behaviour needs measurement; no extrapolated schedule is issued.
A21: H₂ generation rate | B21: rH2_gen | C21: mol/h | D21: =I_app*etaF/(z_e_H2*F_const)*3600 -> 0.00010233412 | E21: Faraday: I x etaF /(z F).
A22: O₂ generation rate (anodic, gross) | B22: rO2_gen | C22: mol/h | D22: =I_app*etaF_OER/(z_e_O2*F_const)*3600 -> 5.305977e-05 | E22: Anodic OER, gross. Uses etaF_OER (anodic), not the cathodic etaF. H₂:O₂(anodic) = 2:1.
A23: H₂ generation rate (volumetric) | B23: V_H2_gen | C23: mL/min | D23: =rH2_gen/60*R_gas*T_K/P_atm*1000000 -> 0.0424272 | E23: Ideal gas at surface T,P. Collect gas over water to check against this.
A24: O₂ generation rate (volumetric) | B24: V_O2_gen | C24: mL/min | D24: =rO2_gen/60*R_gas*T_K/P_atm*1000000 -> 0.021998307 | E24: Anodic gross O₂.
A25: Total gas generation rate | B25: V_gas_total | C25: mL/min | D25: =V_H2_gen+V_O2_gen -> 0.064425507 | E25: Total electrolytic gas (H₂+O₂) — abiotic check: collect over water, no cells, to verify Gerrit/etaF. Less if etaF<1.
A26: Anodic O₂ faradaic efficiency | B26: etaF_OER | C26: - | D26: =IF(ISNUMBER(cal_etaF_OER),cal_etaF_OER,etaF_OER_calc) -> 0.99970505 | E26: Anodic O₂ faradaic efficiency: measured if available, otherwise CALCULATED (etaF_OER_calc) as 1 − the chlorine share − the metal-dissolution share − the anodic H₂-oxidation share. UdG contains chloride, so the chlorine current is modelled explicitly (D101). The faradaic-efficiency screen measures the sum of cathodic ORR and anodic HOR losses.
A27: Electrons per O₂ on the peroxide branch (cathode) | B27: z_e_ORR | C27: - | D27: =VLOOKUP(electrode_sel,tbl_electrode,MATCH("z_e_ORR",tbl_electrode_hdr,0),FALSE) -> 2 | E27: Electrode lookup: 2 e⁻ per O₂ on the peroxide branch (SS cathode, neutral pH) for every current electrode. The current drawn per O₂ is the weighted n_ORR_eff (D141), not this value.
A28: O₂ consumed at cathode (ORR) | B28: O2_cathode_ORR | C28: mol/h | D28: =I_app*(1-etaF)/(n_ORR_eff*F_const)*3600 -> 2.0630956e-06 | E28: Moles of O₂ reduced: the non-H₂ cathodic current (1−etaF) divided by n_ORR_eff·F. Equals the transport-limited O₂ flux when etaF is calculated; stays consistent if a measured etaF is in use. 0 at etaF = 1.
A29: Net O₂ to dissolved pool | B29: O2_net_gen | C29: mol/h | D29: =rO2_gen-O2_cathode_ORR+O2_H2O2_ret_g -> 5.1027984e-05 | E29: Anodic O₂ minus cathodic consumption at the design DO (D85), plus the O₂ returned by peroxide oxidation at the anode (D171) — the O₂ the dissolved pool receives in growth. The lag phase uses O2_net_lag (D132).
A30: z_e_ORR = 2 is the peroxide branch only; the current per O₂ is n_ORR_eff (D141, 2 and 4 e⁻ weighted by f_HOOH). etaF unmeasured — both live here per electrode.
A31: Sparger (from electrode) | B31: sparger_e | D31: =VLOOKUP(electrode_sel,tbl_electrode,MATCH("sparger",tbl_electrode_hdr,0),FALSE) -> Sintered | E31: Sparger type of the selected electrode assembly, looked up in the electrode table (tbl_electrode).
A32: Sinter porosity grade (from electrode) | B32: por_grade_e | D32: =IF(ISNUMBER(cal_sinter),cal_sinter,IF(ISNUMBER(VLOOKUP(electrode_sel,tbl_electrode,MATCH("sinter porosity",tbl_electrode_hdr,0),FALSE)),VLOOKUP(electrode_sel,tbl_electrode,MATCH("sinter porosity",tbl_electrode_hdr,0),FALSE),0)) -> 0 | E32: Porosity 0 = Gerrit's sourced sintered disc (SD8/0/P 8mm, fallback SD10/0/P 10mm; Scientific Glass Labs, 2026-05)
A33: ELECTRODE LOOKUP (selecting the electrode sets sparger, porosity, cathode)
A34: Electrode | B34: anode material | C34: anode dia (mm) | D34: sparger | E34: sinter porosity | F34: cathode | G34: cathode dia (mm) | H34: etaF | I34: z_e_ORR | J34: anode shape | K34: anode j cont (mA/cm²) | L34: anode j max (mA/cm²) | M34: cathode shape | N34: material note
A35: Pt/Ti rod | B35: Pt/Ti | C35: 6 | D35: Tube | E35: n/a | F35: SS rod | G35: 6 | H35: ? | I35: 2 | J35: rod | K35: 100 | L35: 500 | M35: rod | N35: Pt/Ti O₂-evolution; cells bind before the coating.
A36: MMO rod | B36: MMO | C36: 6 | D36: Tube | E36: n/a | F36: SS rod | G36: 6 | H36: ? | I36: 2 | J36: rod | K36: 50 | L36: 500 | M36: rod | N36: IrO₂-Ta₂O₅ O₂-selective; derates vs chloride.
A37: MMO tube | B37: MMO | C37: 6 | D37: Sintered | E37: 0 | F37: SS rod | G37: 6 | H37: ? | I37: 2 | J37: tube | K37: 10 | L37: 60 | M37: rod | N37: Tubular MMO CP rating ~100 A/m²; binds near the cell limit.
A38: Graphite rod | B38: Graphite | C38: 6 | D38: Tube | E38: n/a | F38: SS rod | G38: 6 | H38: ? | I38: 2 | J38: rod | K38: 35 | L38: 50 | M38: rod | N38: Consumable; ~35 mA/cm² erosion, unsuitable for sustained neutral O₂; testing only.
A40: CURRENT DENSITY, WETTED AREA & LIMITS
A41: Anode shape (from electrode) | B41: anode_shape | C41: - | D41: =VLOOKUP(electrode_sel,tbl_electrode,MATCH("anode shape",tbl_electrode_hdr,0),FALSE) -> tube | E41: Rod counts its end face; a tube does not.
A42: Anode diameter (from electrode) | B42: anode_dia | C42: mm | D42: =VLOOKUP(electrode_sel,tbl_electrode,MATCH("anode dia (mm)",tbl_electrode_hdr,0),FALSE) -> 6 | E42: Electrode table.
A43: Cathode shape (from electrode) | B43: cathode_shape | C43: - | D43: =VLOOKUP(electrode_sel,tbl_electrode,MATCH("cathode shape",tbl_electrode_hdr,0),FALSE) -> rod | E43: Rod/tube; sets the end-face term.
...

Sheet Chemistry
A1: CHEMISTRY — buffered pH & anodic bleaching (open-system carbonate+phosphate charge balance, van't Hoff to reactor T)
A2: Parameter | B2: Name | C2: Unit | D2: Value | E2: Source / assumption
A3: IMPORTS (from other tabs)
A4: (import) Reactor temperature | B4: TKc | C4: K | D4: =Biology!T_K -> 303.15 | E4: → Biology
A5: (import) Dissolved CO₂ (cycle average) | B5: CO2aqc | C5: mol/L | D5: ='Mass Transfer'!CO2aqc_ss -> 0.025556025 | E5: Schedule-dependent cycle-average dissolved CO₂ (mass-conserving limit cycle, bounded by air equilibrium and pure-CO₂ saturation).
A6: (import) Electrolysis current (Gerrit's Law) | B6: Iappc | C6: A | D6: =Electrochemistry!I_app -> 0.00569 | E6: → Electrochemistry (I_app)
A7: (import) Faraday constant | B7: Fcc | C7: C/mol | D7: =Electrochemistry!F_const -> 96485.332 | E7: → Electrochemistry (F_const)
A8: Reactor liquid volume (V_charge in litres) | B8: VLc | C8: L | D8: =V_charge/1000 -> 0.015 | E8: V_charge (D279, mL) / 1000 → L
A9: Molar gas constant | B9: R_gas | C9: J/mol/K | D9: ='Mass Transfer'!R_gas -> 8.3144626 | E9: → Mass Transfer (R_gas).
A11: EQUILIBRIUM CONSTANTS (van't Hoff to reactor T) | F11: K(T)=K₂₅·exp(−ΔH/R·(1/T−1/298.15)). ΔH = standard enthalpy of dissociation; well documented. Same van't Hoff treatment your sheet already uses for the Henry constants.
A12: constant | B12: K₂₅ | C12: ΔH kJ/mol | D12: K at reactor T | E12: source
A13: Carbonate Ka1 (pKa 6.35) | B13: 4.45e-07 | C13: 9.15 | D13: =B13*EXP(-C13*1000/R_gas*(1/TKc-1/T_ref)) -> 4.7293259e-07 | E13: Handbook: K₂₅ (CRC/IUPAC); ΔH dissociation (CRC)
A14: Carbonate Ka2 (pKa 10.33) | B14: 4.69e-11 | C14: 14.9 | D14: =B14*EXP(-C14*1000/R_gas*(1/TKc-1/T_ref)) -> 5.1787732e-11 | E14: Handbook: K₂₅ (CRC/IUPAC); ΔH dissociation (CRC)
A15: Phosphate Ka1 (pKa 2.15) | B15: 0.0071 | C15: -8 | D15: =B15*EXP(-C15*1000/R_gas*(1/TKc-1/T_ref)) -> 0.0067319686 | E15: Handbook: K₂₅ (CRC/IUPAC); ΔH dissociation (CRC)
A16: Phosphate Ka2 (pKa 7.20) | B16: 6.31e-08 | C16: 3.6 | D16: =B16*EXP(-C16*1000/R_gas*(1/TKc-1/T_ref)) -> 6.4629632e-08 | E16: Handbook: K₂₅ (CRC/IUPAC); ΔH dissociation (CRC)
A17: Phosphate Ka3 (pKa 12.38) | B17: 4.2e-13 | C17: 16 | D17: =B17*EXP(-C17*1000/R_gas*(1/TKc-1/T_ref)) -> 4.671774e-13 | E17: Handbook: K₂₅ (CRC/IUPAC); ΔH dissociation (CRC)
A18: Ammonium Ka (pKa 9.25) | B18: 5.6e-10 | C18: 52.2 | D18: =B18*EXP(-C18*1000/R_gas*(1/TKc-1/T_ref)) -> 7.9254089e-10 | E18: Handbook: K₂₅ (CRC/IUPAC); ΔH dissociation (CRC)
A19: Water Kw | B19: 1e-14 | C19: 55.8 | D19: =B19*EXP(-C19*1000/R_gas*(1/TKc-1/T_ref)) -> 1.4495593e-14 | E19: Handbook: K₂₅ (CRC/IUPAC); ΔH dissociation (CRC)
A20: Hypochlorous Ka (pKa 7.54) | B20: 2.8840315e-08 | C20: 13.8 | D20: =B20*EXP(-C20*1000/R_gas*(1/TKc-1/T_ref)) -> 3.1613717e-08 | E20: Handbook: K₂₅ (CRC/IUPAC); ΔH dissociation (CRC)
A21: HOCl pKa at reactor T | B21: pKa_HOCl | C21: - | D21: =-LOG10(Ka_HOCl) -> 7.5001244 | E21: = −log₁₀(Ka_HOCl at T)
A23: MEDIA IONIC COMPOSITION (per litre, as published; Excel derives the charge balance) | F23: Trace-metal salts omitted from SID (<0.2 mM charge, negligible vs ~50–60 mM); their chloride is carried in the chloride row.
A24: salt | B24: MW g/mol | C24: MC02 g/L | D24: UdG g/L | E24: source
A25: KH₂PO₄ | B25: 136.086 | C25: 0 | D25: 2.3 | E25: Pous 2022 (BiTE 101010) / Pous 2023 (JECE 111550), UdG recipe
A26: Na₂HPO₄ | B26: 141.96 | C26: 2.895 | D26: 2.9 | E26: Media/README.md (MC02); per Sydow 2017 SI Table S1
A27: NaH₂PO₄·2H₂O | B27: 156.01 | C27: 3.06 | D27: 0 | E27: Media/README.md (MC02); per Sydow 2017 SI Table S1
A28: NaHCO₃ | B28: 84.007 | C28: 0 | D28: 1.05 | E28: Pous 2022 (BiTE 101010) / Pous 2023 (JECE 111550), UdG recipe
A29: K₂SO₄ | B29: 174.26 | C29: 0.17 | D29: 0 | E29: Media/README.md (MC02); per Sydow 2017 SI Table S1
A30: CaSO₄·2H₂O | B30: 172.17 | C30: 0.097 | D30: 0 | E30: Media/README.md (MC02); per Sydow 2017 SI Table S1
A31: MgSO₄·7H₂O | B31: 246.48 | C31: 0.8 | D31: 0.5 | E31: Media/README.md (MC02); per Sydow 2017 SI Table S1
A32: (NH₄)₂SO₄ | B32: 132.14 | C32: 0.943 | D32: 0.47 | E32: Media/README.md (MC02); per Sydow 2017 SI Table S1
A33: CaCl₂ | B33: 110.98 | C33: 0 | D33: 0.01 | E33: Pous 2022 (BiTE 101010) / Pous 2023 (JECE 111550), UdG recipe = 0.01 g/L.
A35: MC02 — total phosphate | B35: PT_mc02 | C35: mol/L | D35: =mc_Na2HPO4/MW_Na2HPO4+mc_NaH2PO4_2H2O/MW_NaH2PO4_2H2O -> 0.040007196 | E35: Σ phosphate salts
A36: MC02 — strong-ion difference | B36: SID_mc02 | C36: mol/L | D36: =(2*mc_Na2HPO4/MW_Na2HPO4+mc_NaH2PO4_2H2O/MW_NaH2PO4_2H2O+2*mc_K2SO4/MW_K2SO4+2*mc_MgSO4_7H2O/MW_MgSO4_7H2O+2*mc_CaSO4_2H2O/MW_CaSO4_2H2O)-2*(mc_NH42SO4/MW_NH42SO4+mc_MgSO4_7H2O/MW_MgSO4_7H2O+mc_K2SO4/MW_K2SO4+mc_CaSO4_2H2O/MW_CaSO4_2H2O) -> 0.046127523 | E36: Σ strong cations − strong anions
A37: MC02 — total ammonium | B37: NT_mc02 | C37: mol/L | D37: =2*mc_NH42SO4/MW_NH42SO4 -> 0.014272741 | E37: Σ ammonium in the recipe: 2 × (NH₄)₂SO₄ per litre (MC02).
A38: MC02 — chloride | B38: Cl_mc02 | C38: mol/L | D38: =0 -> 0 | E38: no chloride salts
A39: UdG — total phosphate | B39: PT_udg | C39: mol/L | D39: =udg_KH2PO4/MW_KH2PO4+udg_Na2HPO4/MW_Na2HPO4 -> 0.037329367 | E39: Σ phosphate salts
A40: UdG — strong-ion difference | B40: SID_udg | C40: mol/L | D40: =(udg_NaHCO3/MW_NaHCO3+2*udg_Na2HPO4/MW_Na2HPO4+udg_KH2PO4/MW_KH2PO4+2*udg_MgSO4_7H2O/MW_MgSO4_7H2O+2*udg_CaCl2/MW_CaCl2)-(2*(udg_NH42SO4/MW_NH42SO4+udg_MgSO4_7H2O/MW_MgSO4_7H2O)+2*udg_CaCl2/MW_CaCl2) -> 0.063142948 | E40: Σ strong cations − strong anions
A41: UdG — total ammonium | B41: NT_udg | C41: mol/L | D41: =2*udg_NH42SO4/MW_NH42SO4 -> 0.0071136673 | E41: Σ ammonium in the recipe: 2 × (NH₄)₂SO₄ per litre (UdG).
A42: UdG — chloride | B42: Cl_udg | C42: mol/L | D42: =2*udg_CaCl2/MW_CaCl2 -> 0.00018021265 | E42: trace-metal Cl excluded (negligible)
A44: (sel) strong-ion difference | B44: pH_SID | C44: mol/L | D44: =IF(media_sel=INDEX(MediaList,1),SID_mc02,IF(media_sel=INDEX(MediaList,2),SID_udg,IF(media_sel=INDEX(MediaList,3),AMYBO03!SID_AMYBO03,NA())))+alk_add_M -> 0.11544691 | E44: by media_sel, plus any NaHCO₃ added on Summary D13 (alk_add_M, D318)
...

Sheet Biology
A1: BIOLOGY
A2: Parameter | B2: Name | C2: Unit | D2: Value | E2: Source / assumption
A3: IMPORTS (from other tabs)
A4: (import) H₂ generation rate | B4: rH2_gen | C4: mol/h | D4: =Electrochemistry!rH2_gen -> 0.00010233412 | E4: =HYPERLINK("#Electrochemistry!D21","→ Electrochemistry") -> → Electrochemistry
A5: (import) Net O₂ to dissolved pool | B5: O2_net_gen | C5: mol/h | D5: =Electrochemistry!O2_net_gen -> 5.1027984e-05 | E5: =HYPERLINK("#Electrochemistry!D29","→ Electrochemistry") -> → Electrochemistry
A6: (import) LIQUID VOLUME TO CHARGE | B6: V_charge | C6: mL | D6: =Geometry!V_charge -> 15 | E6: =HYPERLINK("#Geometry!D41","→ Geometry") -> → Geometry
A7: (import) HOB organism | B7: organism_sel | D7: =Summary!organism_sel -> Xanthobacter tagetidis | E7: =HYPERLINK("#Summary!D4","→ Summary") -> → Summary
A10: Gas requirement ratio - H₂ | B10: bio_H2 | C10: - | D10: =IF(ISNUMBER(cal_knall_H2),cal_knall_H2,knall_H2_default) -> 6 | E10: H₂:O₂:CO₂ UPTAKE ratio (not feed; phase-dependent, Lu & Yu 2019). Knallgas caps O₂:H₂≤0.5; growth gives O₂:H₂≈0.29–0.35, CO₂:H₂≈0.15–0.19. 6:2:1 = mid-range central. Feed optimum 7:2:1 (Ishizaki 2001). Can't measure pre-growth.
A11: Gas requirement ratio - O₂ | B11: bio_O2 | C11: - | D11: =IF(ISNUMBER(cal_knall_O2),cal_knall_O2,knall_O2_default) -> 2 | E11: O₂:H₂ uptake, range 0.29–0.35 (×6 → 1.75–2.1). 2 = central; 1.8 (lean) is growth-protective.
A12: Gas requirement ratio - CO₂ | B12: bio_CO2 | C12: - | D12: =IF(ISNUMBER(cal_knall_CO2),cal_knall_CO2,knall_CO2_default) -> 1 | E12: CO₂:H₂ uptake, range 0.15–0.19 (×6 → 0.9–1.15). 1 = central. Supply ≫ demand → non-limiting.
A13: H₂ consumed | B13: H2_cons | C13: mol/h | D13: =MAX(0,rH2_gen-H2_HOR_b) -> 0.00010233412 | E13: Evolved H₂ minus any crossed-over H₂ the Pt anode oxidises (D96; 0 until measured), assumed fully consumed — steady growth only; ~0 during lag (see §13).
A14: O₂ consumed | B14: O2_cons | C14: mol/h | D14: =H2_cons*bio_O2/bio_H2 -> 3.4111374e-05 | E14: Assumes 100% H₂ uptake (upper bound); true limit is gas-liquid H₂ transfer — see H2_turnover
A15: CO₂ consumed (carbon fixation) | B15: CO2_cons | C15: mol/h | D15: =H2_cons*bio_CO2/bio_H2 -> 1.7055687e-05 | E15: H₂ consumed x (CO₂/H₂ ratio).
A16: EXCESS O₂ to remove | B16: O2_excess | C16: mol/h | D16: =MAX(0,O2_net_gen-O2_cons) -> 1.691661e-05 | E16: =IFERROR(("Net electrolytic O₂ minus biological uptake, floored at zero. The floor matters: at the knallgas cap (O₂:H₂ = 0.5, i.e. bio_O2 = 3) uptake exactly consumes the electrolytic surplus and everything "&"downstream that divides by this would blow up. A LOWER bound on the surplus: full H₂ uptake maximises respiration, so any H₂ that bubbles off uncaught raises the surplus (half uptake → ×")&TEXT((O2_net_gen-O2_cons/2)/O2_excess,"0.0")&"). Sensitive: each 1 % on bio_O2 moves it "&TEXT(O2_cons/O2_excess,"0.0")&" % the other way (linear, so symmetric).","Net electrolytic O₂ minus biological uptake, floored at zero: uptake consumes the whole surplus at these ratios.") -> Net electrolytic O₂ minus biological uptake, floored at zero. The floor matters: at the knallgas cap (O₂:H₂ = 0.5, i.e. bio_O2 = 3) uptake exactly consumes the electrolytic surplus and everything downstream that divides by this would blow up. A LOWER bound on the surplus: full H₂ uptake maximises respiration, so any H₂ that bubbles off uncaught raises the surplus (half uptake → ×2.0). Sensitive: each 1 % on bio_O2 moves it 2.0 % the other way (linear, so symmetric).
A17: Temperature | B17: T_C | C17: °C | D17: =Summary!temp_C -> 30 | E17: C. necator optimum ~30 °C. Input.
A18: Temperature (absolute) | B18: T_K | C18: K | D18: =T_C+T_zero_C -> 303.15 | E18: °C + 273.15.
A19: Surface pressure | B19: P_atm | C19: Pa | D19: =IF(P_atm_set>0,P_atm_set,Pa_per_atm) -> 101325 | E19: Atmospheric at the liquid surface (assumed).
A20: Standard atmosphere (atm->Pa) | B20: Pa_per_atm | C20: Pa/atm | D20: 101325 | E20: Defined: 1 atm = 101 325 Pa exactly.
A21: Henry solubility O₂ (ref, 298.15 K) | B21: H_O2ref | C21: mol/m³/Pa | D21: 1.2e-05 | E21: Sander (2023) recommended H^cp O2; reproduces ~7.5 mg/L air-saturation at 30 degC
A22: Henry T-dependence O₂ | B22: H_O2T | C22: K | D22: 1500 | E22: Sander (2023): d ln(Hcp)/d(1/T).
A23: Reference temperature | B23: T_ref | C23: K | D23: 298.15 | E23: Standard reference for Henry constants.
A24: Henry solubility O₂ at T | B24: H_O2_T | C24: mol/m³/Pa | D24: =H_O2ref*EXP(H_O2T*(1/T_K-1/T_ref))*f_salt_O2 -> 1.0354236e-05 | E24: van 't Hoff correction to reactor T, then salted out for the medium's ionic strength (f_salt_O2, D123). Moves the dissolved-O₂ ceiling (D27) and every Henry O₂ term.
A25: O₂ growth-inhibition ceiling (gas) | B25: O2_ceil_atm | C25: atm | D25: 0.3 | E25: Whole-cell growth inhibited above ~0.30 atm O₂ (Amer & Kim 2023); the [NiFe] hydrogenase itself is O₂-tolerant.
A26: O₂ ceiling (partial pressure) | B26: O2_ceil_Pa | C26: Pa | D26: =O2_ceil_atm*Pa_per_atm -> 30397.5 | E26: Ceiling in Pa.
A27: Dissolved-O₂ ceiling | B27: O2_ceil_C | C27: mol/m³ | D27: =H_O2_T*O2_ceil_Pa -> 0.3147429 | E27: Henry's law at the gas ceiling.
A28: Dissolved-O₂ ceiling | B28: O2_ceil_uM | C28: µM | D28: =O2_ceil_C*1000 -> 314.7429 | E28: mol/m³ = mM; ×1000 = µM. Aim: minimise dissolved O₂; floor set by O₂-removal capacity (§11).
A29: Henry solubility CO₂ (ref, 298.15 K) | B29: H_CO2ref | C29: mol/m³/Pa | D29: 0.00033 | E29: Sander (2023) compilation; CO₂ ~28× more soluble than O₂ (vs the 1.2e-5 O₂ Hcp).
A30: Henry T-dependence CO₂ | B30: H_CO2T | C30: K | D30: 2400 | E30: Sander (2023): d ln(Hcp)/d(1/T) for CO₂.
A31: Henry solubility CO₂ at T | B31: H_CO2_T | C31: mol/m³/Pa | D31: =H_CO2ref*EXP(H_CO2T*(1/T_K-1/T_ref)) -> 0.00028897092 | E31: van 't Hoff to reactor T.
A32: (import) CO₂ partial pressure at sparge (dry-gas basis) | B32: p_CO2_sparge | C32: Pa | D32: ='Mass Transfer'!P_dry -> 97088.35 | E32: Import from Mass Transfer!D418 (P_dry): a pure-CO₂ pulse in a water-saturated headspace carries p_CO₂ = P_atm − p_sat_w, the basis of Mass Transfer D145.
A33: Dissolved CO₂ (during sparge) | B33: CO2_diss | C33: mol/m³ | D33: =H_CO2_T*p_CO2_sparge -> 28.055709 | E33: Equilibrium dissolved CO₂ under a pure-CO₂ headspace on the dry-gas basis (= Mass Transfer C_sat_CO2, D145; mol/m³ = mM). Legacy upper bound: a sub-second pulse never reaches it.
A34: RuBisCO Km for CO₂ | B34: Km_CO2 | C34: µM | D34: 50 | E34: RuBisCO Km(CO₂) ~ order 50 µM. Coarse — confirm.
A35: Carbon margin (dissolved CO₂ : Km) | B35: CO2_carbon_margin | C35: × | D35: =CO2_diss*1000/Km_CO2 -> 561.11419 | E35: Dissolved CO₂ at full dry-basis saturation : RuBisCO Km. Legacy upper bound, superseded by the cycle-trough margin D98 (Summary D76).
A36: Carbonic-acid Ka1 (apparent) | B36: Ka1_carb | C36: mol/L | D36: 4.45e-07 | E36: CO₂(aq)+H₂O ⇌ H⁺+HCO₃⁻, pKa1 6.35 (25 °C).
A37: pH — UNBUFFERED worst case | B37: pH_CO2_unbuf | C37: - | D37: =-LOG10(SQRT(Ka1_carb*(CO2_diss/1000))) -> 3.9518094 | E37: Unbuffered worst case (pure water + CO₂) — lower bound only; the Sydow phosphate medium holds pH near setpoint.
A38: Henry solubility H₂ (ref, 298.15 K) | B38: H_H2ref | C38: mol/m³/Pa | D38: 7.8e-06 | E38: Sander (2023). H₂ ~1.5× less soluble than O₂ (vs the 1.2e-5 O₂ Hcp).
A39: Henry T-dependence H₂ | B39: H_H2T | C39: K | D39: 500 | E39: Sander (2023): d ln(Hcp)/d(1/T) for H₂ (weak T-dependence).
A40: Henry solubility H₂ at T | B40: H_H2_T | C40: mol/m³/Pa | D40: =H_H2ref*EXP(H_H2T*(1/T_K-1/T_ref)) -> 7.5872107e-06 | E40: van 't Hoff to reactor T.
A41: Dissolved-H₂ saturation (1 atm) | B41: C_H2_sat | C41: mol/m³ | D41: =H_H2_T*P_atm -> 0.76877412 | E41: Max dissolved H₂ at 1 atm — the cells' H₂ ceiling.
A42: Time to saturate dissolved H₂ (LAG) | B42: t_H2_sat | C42: min | D42: =C_H2_sat*(V_charge/1000000)/rH2_gen*60 -> 6.7611535 | E42: Lag: dissolved H₂ saturates this fast unconsumed, then bubbles off (lost + explosive headspace). Mirrors the O₂ lag timescale.
...

Sheet Mass Transfer
A1: MASS TRANSFER
A2: Parameter | B2: Name | C2: Unit | D2: Value | E2: Source / assumption
A4: IMPORTS (from other tabs)
A5: (import) Stir-bar length (from reactor type) | B5: stir_len | C5: mm | D5: =Geometry!stir_bar_L -> 12 | E5: =HYPERLINK("#Geometry!D52","→ Geometry") -> → Geometry | F5: Magnetic stir bar. Pioreactor max 20 mm; confirm the supplied bar's length.
A6: (import) Dissolved-O₂ ceiling | B6: O2_ceil_C | C6: mol/m³ | D6: =Biology!O2_ceil_C -> 0.3147429 | E6: =HYPERLINK("#Biology!D27","→ Biology") -> → Biology
A7: (import) O₂ ceiling (partial pressure) | B7: O2_ceil_Pa | C7: Pa | D7: =Biology!O2_ceil_Pa -> 30397.5 | E7: =HYPERLINK("#Biology!D26","→ Biology") -> → Biology
A8: (import) Temperature (absolute) | B8: T_K | C8: K | D8: =Biology!T_K -> 303.15 | E8: =HYPERLINK("#Biology!D18","→ Biology") -> → Biology
A9: (import) Surface pressure | B9: P_atm | C9: Pa | D9: =Biology!P_atm -> 101325 | E9: =HYPERLINK("#Biology!D19","→ Biology") -> → Biology
A10: (import) CO₂ consumed (carbon fixation) | B10: CO2_cons | C10: mol/h | D10: =Biology!CO2_cons -> 1.7055687e-05 | E10: =HYPERLINK("#Biology!D15","→ Biology") -> → Biology
A11: (import) EXCESS O₂ to remove | B11: O2_excess | C11: mol/h | D11: =Biology!O2_excess -> 1.691661e-05 | E11: =HYPERLINK("#Biology!D16","→ Biology") -> → Biology
A12: (import) Henry solubility O₂ at T | B12: H_O2_T | C12: mol/m³/Pa | D12: =Biology!H_O2_T -> 1.0354236e-05 | E12: =HYPERLINK("#Biology!D24","→ Biology") -> → Biology
A13: (import) Net O₂ to dissolved pool | B13: O2_net_gen | C13: mol/h | D13: =Electrochemistry!O2_net_gen -> 5.1027984e-05 | E13: =HYPERLINK("#Electrochemistry!D29","→ Electrochemistry") -> → Electrochemistry
A14: (import) Gas-liquid interfacial area | B14: interface_A | C14: mm² | D14: =Geometry!interface_A -> 429.54773 | E14: =HYPERLINK("#Geometry!D44","→ Geometry") -> → Geometry
A15: (import) Vial internal diameter | B15: vial_ID | C15: mm | D15: =Geometry!vial_ID -> 25.28 | E15: =HYPERLINK("#Geometry!D20","→ Geometry") -> → Geometry
A16: (import) LIQUID VOLUME TO CHARGE | B16: V_charge | C16: mL | D16: =Geometry!V_charge -> 15 | E16: =HYPERLINK("#Geometry!D41","→ Geometry") -> → Geometry
A17: (import) Internal cross-sectional area | B17: A_x | C17: mm² | D17: =Geometry!A_x -> 501.931 | E17: =HYPERLINK("#Geometry!D21","→ Geometry") -> → Geometry
A18: (import) Sparge tube ID | B18: spg_ID | C18: mm | D18: =Geometry!spg_ID -> 1.5875 | E18: =HYPERLINK("#Geometry!D31","→ Geometry") -> → Geometry
A19: (import) Headspace gas volume | B19: headspace_V | C19: mL | D19: =Geometry!headspace_V -> 2.6124285 | E19: =HYPERLINK("#Geometry!D49","→ Geometry") -> → Geometry
A20: (import) Sinter porosity grade (from electrode) | B20: por_grade | C20: 0-5 | D20: =Electrochemistry!por_grade_e -> 0 | E20: =HYPERLINK("#Electrochemistry!D32","→ Electrochemistry") -> → Electrochemistry
A21: (import) Sparger type (from electrode) | B21: sparger | C21: - | D21: =Electrochemistry!sparger_e -> Sintered | E21: =HYPERLINK("#Electrochemistry!D31","→ Electrochemistry") -> → Electrochemistry
A22: (import) Optimum DO (organism) | B22: DO_opt | D22: =Biology!DO_opt -> #N/A | E22: =HYPERLINK("#Biology!D46","→ Biology") -> → Biology
A23: (import) Impairment DO (organism) | B23: DO_impair | D23: =Biology!DO_impair -> #N/A | E23: =HYPERLINK("#Biology!D47","→ Biology") -> → Biology
A24: (import) Toxic/inhibition DO (organism) | B24: DO_toxic | D24: =Biology!DO_toxic -> #N/A | E24: =HYPERLINK("#Biology!D48","→ Biology") -> → Biology
A25: (import) Minimum DO (organism) | B25: DO_min | D25: =Biology!DO_min -> #N/A | E25: =HYPERLINK("#Biology!D45","→ Biology") -> → Biology
A27: valid sparger 1 | B27: spg_name_1 | C27: - | D27: Tube | E27: Bare 1/8" OD x 1/16" ID Flexelene 135C tube orifice.
A28: valid sparger 2 | B28: spg_name_2 | C28: - | D28: Sintered | E28: 10 mm sintered-glass disc annulus on a tubular anode.
A29: Surface tension (water, T) | B29: sigma | C29: N/m | D29: =sigma_0+sigma_k*(T_K-T_zero_C) -> 0.07118 | E29: IAPWS R1-76(2014), evaluated at the reactor temperature (T_C). Feeds the bubble-detachment diameter.
A30: Liquid density (water, T) | B30: rho_L | C30: kg/m³ | D30: =rho_0+rho_k*(T_K-T_zero_C) -> 995.662 | E30: IAPWS-95, evaluated at the reactor temperature.
A31: Gravitational acceleration | B31: g_const | C31: m/s² | D31: 9.80665 | E31: Standard gravity (defined).
A32: O₂ diffusivity in water (T) | B32: D_O2 | C32: m²/s | D32: =10^(HB_a+HB_b/T_K-(HB_c/T_K)^2)/10000 -> 2.2495444e-09 | E32: Han & Bartels (1996) evaluated at the reactor temperature. At 25 °C this is 2.00e-9 m²/s.
A33: Pore size - grade 0 | B33: por0_um | C33: µm | D33: 205 | E33: DURAN P0 160-250 µm, midpoint. ISO 4793 (paywalled) underlies; DURAN table is free.
A34: Pore size - grade 1 | B34: por1_um | C34: µm | D34: 130 | E34: DURAN P1 100-160 µm, midpoint.
A35: Pore size - grade 2 | B35: por2_um | C35: µm | D35: 70 | E35: DURAN P2 40-100 µm, midpoint.
A36: Pore size - grade 3 | B36: por3_um | C36: µm | D36: 28 | E36: DURAN P3 16-40 µm, midpoint.
A37: Pore size - grade 4 | B37: por4_um | C37: µm | D37: 13 | E37: DURAN P4 10-16 µm, midpoint.
A38: Pore size - grade 5 | B38: por5_um | C38: µm | D38: 1.3 | E38: DURAN P5 1.0-1.6 µm, midpoint.
A39: Selected sinter pore diameter | B39: por_pore | C39: m | D39: =CHOOSE(por_grade+1,por0_um,por1_um,por2_um,por3_um,por4_um,por5_um)/1000000 -> 0.000205 | E39: Picked by por_grade.
A40: Tube orifice diameter | B40: tube_d_m | C40: m | D40: =spg_ID/1000 -> 0.0015875 | E40: Tube ID in metres.
A41: Effective orifice/pore diameter | B41: d_orifice | C41: m | D41: =IF(sparger=spg_name_1,tube_d_m,IF(sparger=spg_name_2,por_pore,NA())) -> 0.000205 | E41: Tube ID or sinter pore; invalid sparger returns an error.
A42: Bubble detachment diameter | B42: d_bubble | C42: m | D42: =(6*d_orifice*sigma/(rho_L*g_const))^(1/3) -> 0.0020775118 | E42: Static low-flow force balance (buoyancy vs surface tension); valid in the quasi-static regime — see bubble_regime (§10).
...

Sheet CO2 flows
A1: CO₂ DOSING FLOWRATES
A2: Reactor | B2: date | C2: cylinder size | D2: observed volume* | E2: volume | F2: time | G2: flowrate | H2: average flowrate | I2: minimum sparge | J2: nominal flowrate | L2: KEY | M2: max flow without carryover | N2: excluded from pulse fit
C3: mL | D3: mL | E3: mL | F3: s | G3: mL/s | H3: mL/s | I3: s | J3: mL/s | L3: Flowrate set by inspection, as maximum to not give bubbles rising into vial neck | M3: mL/s | N3: 1 = yes
A4: ed04 | B4: 46190 | C4: 50 | D4: 0 | I4: 0.25 | J4: 3.33 | L4: First or last data point removed as suspect outlier
A5: ed04 | B5: 46190 | C5: 50 | D5: 50 | E5: =D5-D4 -> 50 | F5: 15 | G5: =E5/F5 -> 3.3333333 | H5: =AVERAGE(G5) -> 3.3333333
A6: ed04 | B6: 46190 | C6: 50 | D6: 0 | K6: Point | L6: Note
A7: ed04 | B7: 46190 | C7: 50 | D7: 12 | E7: =D7-D6 -> 12 | F7: 4 | G7: =E7/F7 -> 3 | H7: =AVERAGE(G7:G9) -> 3.3333333 | K7: * | L7: CO2 collected in measuring cylinder over CO2-saturated water
A8: ed04 | B8: 46190 | C8: 50 | D8: 26 | E8: =D8-D7 -> 14 | F8: 4 | G8: =E8/F8 -> 3.5 | K8: 46190 | L8: Collected using inlet CO2 tube rather than outlet as MEP vialcap leaking
A9: ed04 | B9: 46190 | C9: 50 | D9: 40 | E9: =D9-D8 -> 14 | F9: 4 | G9: =E9/F9 -> 3.5 | K9: 46190 | L9: Collected over saturated NaHCO3 solution
A10: ed04 | B10: 46190 | C10: 50 | D10: 0 | L10: Column M: highest steady flow at which no liquid is carried into the vial neck or vent for this reactor (measured; blank = not measured, and Mass Transfer carry_flag then reads "not measured"). If the lowest entry for the reactor is below the pulse flow, carry_flag reads RISK.
A11: ed04 | B11: 46190 | C11: 50 | D11: 6 | E11: =D11-D10 -> 6 | F11: 2 | G11: =E11/F11 -> 3 | H11: =AVERAGE(G11:G16) -> 3.75 | L11: Column N: 1 = point excluded from the pulse-volume fit V = V₀ + Q·t on Mass Transfer (rows 401–408); 1 is set on the two red outliers (G36, G46). Blank = used.
A12: ed04 | B12: 46190 | C12: 50 | D12: 15 | E12: =D12-D11 -> 9 | F12: 2 | G12: =E12/F12 -> 4.5
A13: ed04 | B13: 46190 | C13: 50 | D13: 21 | E13: =D13-D12 -> 6 | F13: 2 | G13: =E13/F13 -> 3
A14: ed04 | B14: 46190 | C14: 50 | D14: 29 | E14: =D14-D13 -> 8 | F14: 2 | G14: =E14/F14 -> 4
A15: ed04 | B15: 46190 | C15: 50 | D15: 35 | E15: =D15-D14 -> 6 | F15: 2 | G15: =E15/F15 -> 3
A16: ed04 | B16: 46190 | C16: 50 | D16: 45 | E16: =D16-D15 -> 10 | F16: 2 | G16: =E16/F16 -> 5
A17: ed04 | B17: 46190 | C17: 50 | D17: 0
A18: ed04 | B18: 46190 | C18: 50 | D18: 4 | E18: =D18-D17 -> 4 | F18: 1 | G18: =E18/F18 -> 4 | H18: =AVERAGE(G18:G23) -> 3.8333333
A19: ed04 | B19: 46190 | C19: 50 | D19: 8 | E19: =D19-D18 -> 4 | F19: 1 | G19: =E19/F19 -> 4
A20: ed04 | B20: 46190 | C20: 50 | D20: 11 | E20: =D20-D19 -> 3 | F20: 1 | G20: =E20/F20 -> 3
A21: ed04 | B21: 46190 | C21: 50 | D21: 15 | E21: =D21-D20 -> 4 | F21: 1 | G21: =E21/F21 -> 4
A22: ed04 | B22: 46190 | C22: 50 | D22: 19 | E22: =D22-D21 -> 4 | F22: 1 | G22: =E22/F22 -> 4
A23: ed04 | B23: 46190 | C23: 50 | D23: 23 | E23: =D23-D22 -> 4 | F23: 1 | G23: =E23/F23 -> 4
A24: ed04 | B24: 46190 | C24: 50 | D24: 31
A25: ed04 | B25: 46190 | C25: 50 | D25: 33 | E25: =D25-D24 -> 2 | F25: 0.5 | G25: =E25/F25 -> 4 | H25: =AVERAGE(G25:G29) -> 4
A26: ed04 | B26: 46190 | C26: 50 | D26: 35 | E26: =D26-D25 -> 2 | F26: 0.5 | G26: =E26/F26 -> 4
A27: ed04 | B27: 46190 | C27: 50 | D27: 37 | E27: =D27-D26 -> 2 | F27: 0.5 | G27: =E27/F27 -> 4
A28: ed04 | B28: 46190 | C28: 50 | D28: 39 | E28: =D28-D27 -> 2 | F28: 0.5 | G28: =E28/F28 -> 4
A29: ed04 | B29: 46190 | C29: 50 | D29: 41 | E29: =D29-D28 -> 2 | F29: 0.5 | G29: =E29/F29 -> 4
A30: ed04 | B30: 46190 | C30: 50 | D30: 42 | E30: =D30-D29 -> 1 | F30: 0.25 | G30: =E30/F30 -> 4 | H30: =AVERAGE(G30:G34) -> 4
A31: ed04 | B31: 46190 | C31: 50 | D31: 43 | E31: =D31-D30 -> 1 | F31: 0.25 | G31: =E31/F31 -> 4
A32: ed04 | B32: 46190 | C32: 50 | D32: 44 | E32: =D32-D31 -> 1 | F32: 0.25 | G32: =E32/F32 -> 4
A33: ed04 | B33: 46190 | C33: 50 | D33: 45 | E33: =D33-D32 -> 1 | F33: 0.25 | G33: =E33/F33 -> 4
A34: ed04 | B34: 46190 | C34: 50 | D34: 46 | E34: =D34-D33 -> 1 | F34: 0.25 | G34: =E34/F34 -> 4
A35: ed04 | B35: 46190 | C35: 10 | D35: 0 | E35: =D35-D34 -> -46
A36: ed04 | B36: 46190 | C36: 10 | D36: 0.4 | E36: =D36-D35 -> 0.4 | F36: 0.2 | G36: =E36/F36 -> 2 | N36: 1
A37: ed04 | B37: 46190 | C37: 10 | D37: 1.2 | E37: =D37-D36 -> 0.8 | F37: 0.2 | G37: =E37/F37 -> 4 | H37: =AVERAGE(G37:G39) -> 4.3333333
A38: ed04 | B38: 46190 | C38: 10 | D38: 2.2 | E38: =D38-D37 -> 1 | F38: 0.2 | G38: =E38/F38 -> 5
A39: ed04 | B39: 46190 | C39: 10 | D39: 3 | E39: =D39-D38 -> 0.8 | F39: 0.2 | G39: =E39/F39 -> 4
A40: ed04 | B40: 46190 | C40: 10 | D40: 0
...

Sheet Calibrations
A1: CALIBRATIONS
A2: Fill the white cells only: Researcher, Date, the key (Reactor or Organism) and the raw measurements. Grey cells are computed automatically. Set Include to y for rows the model should use.
A3: The value in use for each calibration follows the rule stated under its heading. If no rows are included yet, the model falls back to its built-in default.
A5: =HYPERLINK("https://github.com/amy-bo/electroPioreactor/blob/AEP02/Media/protocols/gerrit-current.md","ELECTROLYSIS CURRENT") -> ELECTROLYSIS CURRENT
A6: Value in use: one least-squares fit of current against intensity over every included point for the active reactor (pooled, so a run with more points weighs more).
A7: Researcher | B7: Date | C7: Reactor | D7: Intensity | E7: Current | F7: Type (auto) | G7: Include? | H7: Notes
F8: =IFERROR(INDEX(ReactorTypeList,MATCH(C8,ReactorList,0)),"")
F9: =IFERROR(INDEX(ReactorTypeList,MATCH(C9,ReactorList,0)),"")
F10: =IFERROR(INDEX(ReactorTypeList,MATCH(C10,ReactorList,0)),"")
F11: =IFERROR(INDEX(ReactorTypeList,MATCH(C11,ReactorList,0)),"")
F12: =IFERROR(INDEX(ReactorTypeList,MATCH(C12,ReactorList,0)),"")
F13: =IFERROR(INDEX(ReactorTypeList,MATCH(C13,ReactorList,0)),"")
F14: =IFERROR(INDEX(ReactorTypeList,MATCH(C14,ReactorList,0)),"")
F15: =IFERROR(INDEX(ReactorTypeList,MATCH(C15,ReactorList,0)),"")
A16: Value in use - slope | C16: mA/% | D16: =IFERROR((COUNTIFS(C8:C15,Reactor_sel,G8:G15,"y")*SUMPRODUCT((C8:C15=Reactor_sel)*(G8:G15="y")*D8:D15*E8:E15)-SUMIFS(D8:D15,C8:C15,Reactor_sel,G8:G15,"y")*SUMIFS(E8:E15,C8:C15,Reactor_sel,G8:G15,"y"))/(COUNTIFS(C8:C15,Reactor_sel,G8:G15,"y")*SUMPRODUCT((C8:C15=Reactor_sel)*(G8:G15="y")*D8:D15*D8:D15)-SUMIFS(D8:D15,C8:C15,Reactor_sel,G8:G15,"y")*SUMIFS(D8:D15,C8:C15,Reactor_sel,G8:G15,"y")),"no included runs — model uses its default") -> no included runs — model uses its default
A17: Value in use - intercept | C17: mA | D17: =IFERROR((SUMIFS(E8:E15,C8:C15,Reactor_sel,G8:G15,"y")-((COUNTIFS(C8:C15,Reactor_sel,G8:G15,"y")*SUMPRODUCT((C8:C15=Reactor_sel)*(G8:G15="y")*D8:D15*E8:E15)-SUMIFS(D8:D15,C8:C15,Reactor_sel,G8:G15,"y")*SUMIFS(E8:E15,C8:C15,Reactor_sel,G8:G15,"y"))/(COUNTIFS(C8:C15,Reactor_sel,G8:G15,"y")*SUMPRODUCT((C8:C15=Reactor_sel)*(G8:G15="y")*D8:D15*D8:D15)-SUMIFS(D8:D15,C8:C15,Reactor_sel,G8:G15,"y")*SUMIFS(D8:D15,C8:C15,Reactor_sel,G8:G15,"y")))*SUMIFS(D8:D15,C8:C15,Reactor_sel,G8:G15,"y"))/COUNTIFS(C8:C15,Reactor_sel,G8:G15,"y"),"no included runs — model uses its default") -> no included runs — model uses its default
A20: =HYPERLINK("https://github.com/amy-bo/electroPioreactor/blob/AEP02/Media/protocols/faradaic-efficiency.md","FARADAIC EFFICIENCY (cathodic etaF, anodic etaF_OER)") -> FARADAIC EFFICIENCY (cathodic etaF, anodic etaF_OER)
A21: Value in use: average of the included runs for the active reactor, taken separately for the H2 (cathode) and O2 (anode) electrodes. The gas volume is corrected for saturated water vapour at the temperature you record, per protocols/faradaic-efficiency.md.
A22: Researcher | B22: Date | C22: Reactor | D22: Charge Q | E22: Gas volume | F22: Temp | G22: Pressure | H22: Electrode | I22: etaF (computed) | J22: Type (auto) | K22: Include? | L22: Notes
I23: =IFERROR(((G23-pw_A*EXP(pw_B*F23/(F23+pw_C)))*(E23/1000000)/(R_gas*(F23+T_zero_C)))/(D23/(IF(H23="H2",z_e_H2,IF(H23="O2",z_e_O2,NA()))*F_const)),"") | J23: =IFERROR(INDEX(ReactorTypeList,MATCH(C23,ReactorList,0)),"")
I24: =IFERROR(((G24-pw_A*EXP(pw_B*F24/(F24+pw_C)))*(E24/1000000)/(R_gas*(F24+T_zero_C)))/(D24/(IF(H24="H2",z_e_H2,IF(H24="O2",z_e_O2,NA()))*F_const)),"") | J24: =IFERROR(INDEX(ReactorTypeList,MATCH(C24,ReactorList,0)),"")
