Workbook
Name electrode_sel: Summary!$D$3
Name led_intensity: Summary!$D$6
Name media_sel: Summary!$D$5
Name media_volume: Summary!$D$9
Name organism_sel: Summary!$D$4
Name P_atm_set: Summary!$D$10
Name Reactor_sel: Summary!$D$2
Name stir_rpm_set: Summary!$D$7
Name temp_C: Summary!$D$8
Name A_x: Geometry!$D$21
Name D_int: Geometry!$D$22
Name D_int_1: Geometry!$D$12
Name D_int_2: Geometry!$D$13
Name depth_warn: Geometry!$D$55
Name disp_tot: Geometry!$D$40
Name eff_disp: Geometry!$D$39
Name eff_ID: Geometry!$D$34
Name eff_OD: Geometry!$D$33
Name eff_sub_L: Geometry!$D$38
Name elec_clear: Geometry!$D$28
Name elec_disp: Geometry!$D$36
Name elec_ins: Geometry!$D$29
Name elec_sub_L: Geometry!$D$35
Name geom_check: Geometry!$D$90
Name h_actual: Geometry!$D$42
Name h_datum: Geometry!$D$25
Name headspace_V: Geometry!$D$49
Name interface_A: Geometry!$D$44
Name media_vol_warn: Geometry!$D$54
Name media_volume: Geometry!$D$6
Name reactor_sel: Geometry!$D$5
Name rod_d: Geometry!$D$26
Name rod_n: Geometry!$D$27
Name rx_ver: Geometry!$D$51
Name sparge_depth: Geometry!$D$43
Name spg_disp: Geometry!$D$37
Name spg_ID: Geometry!$D$31
Name spg_len: Geometry!$D$50
Name spg_OD: Geometry!$D$30
Name spg_tip_h: Geometry!$D$32
Name stir_bar_L: Geometry!$D$52
Name V_charge: Geometry!$D$41
Name V_inserts: Geometry!$D$48
Name V_max: Geometry!$D$23
Name V_vial_total: Geometry!$D$24
Name ver_name_1: Geometry!$D$8
Name ver_name_2: Geometry!$D$9
Name vial_ID: Geometry!$D$20
Name vial_OD: Geometry!$D$18
Name vial_OD_1: Geometry!$D$10
Name vial_OD_2: Geometry!$D$11
Name vial_wall: Geometry!$D$19
Name Vmax_1: Geometry!$D$14
Name Vmax_2: Geometry!$D$15
Name Vtot_1: Geometry!$D$16
Name Vtot_2: Geometry!$D$17
Name xtube_n: Geometry!$D$46
Name xtube_OD: Geometry!$D$45
Name xtube_pro: Geometry!$D$47
Name electrode_sel: Electrochemistry!$D$8

Sheet Summary
A1: Parameter | B1: Name | C1: Unit | D1: Value | E1: Source | F1: Comment
A2: Reactor | B2: Reactor_sel | D2: ed04 | E2: select | F2: Active build. Choose from the values below. Dropdown.
A3: Electrode | B3: electrode_sel | D3: MMO tube | E3: select | F3: CO₂ delivery route. Choose from the values below. Dropdown.
A4: HOB organism | B4: organism_sel | D4: Cupriavidus necator | E4: select | F4: The HOB strain; sets the DO band the schedule targets.
A5: Media | B5: media_sel | D5: Sydow 2017 minimal | E5: select | F5: Growth medium.
A6: LED intensity setpoint | B6: led_intensity | C6: % | D6: 3 | E6: input | F6: Pioreactor LED channel % driving electrolysis current (Gerrit's Law, valid 3-25%).
A7: Stirrer rate | B7: stir_rpm_set | C7: rpm | D7: 1000 | E7: input | F7: Stir rate; sets tip speed and surface O2 transfer.
A8: Temperature setpoint | B8: temp_C | C8: °C | D8: 30 | E8: input | F8: Temperature setpoint; sets Henry solubilities and rates.
A9: Media volume | B9: media_volume | C9: mL | E9: input/blank | F9: Liquid charged; leave blank to use the reactor's recommended max working volume.
A10: Ambient pressure | B10: P_atm_set | C10: Pa | E10: input/blank | F10: blank = default 101325 Pa
A12: Results | B12: Name | C12: Unit | D12: Value | E12: Source | F12: Comment
A13: CO₂ pulse duration | C13: s | D13: =IFERROR('Mass Transfer'!$D$90,"calibrate this reactor first (see CO2 flows)") | E13: =HYPERLINK("#'Mass Transfer'!D90","→ Mass") | F13: How long to open the CO2 solenoid each dose.
A14: CO₂ pulse duration (rounded) | C14: s | D14: =IF(D13>0.5,ROUND(D13,0),ROUND(D13,1-(1+INT(LOG10(ABS(D13))))))
A15: CO₂ sparge interval | C15: min | D15: =IFERROR('Mass Transfer'!$D$91,"calibrate this reactor first (see CO2 flows)") | E15: =HYPERLINK("#'Mass Transfer'!D91","→ Mass") | F15: Time between doses (conservative, O2-safe). The 'interval can be relaxed?' check below says if you can dose less often.
A16: CO₂ sparge interval rounded) | C16: min | D16: =IF(D15>0.5,ROUND(D15,0),ROUND(D15,1-(1+INT(LOG10(ABS(D15))))))
A18: Checks | D18: Value | E18: Source | F18: Comment
A19: Vial geometry consistent? | D19: =Geometry!$D$90 | E19: =HYPERLINK("#Geometry!D90","→ Geometry") | F19: Red until the vial headspace is measured (vial-geometry.md). While red, the pulse above is provisional (~4x uncertain).
A20: Reactor calibrated? | D20: ='Mass Transfer'!$D$120 | E20: =HYPERLINK("#'Mass Transfer'!D120","→ Mass") | F20: Red = no CO2-flow calibration for this reactor; results read 'calibrate first' (flow-calibration.md).
A21: O₂ at/under organism optimum? | D21: ='Mass Transfer'!$D$109 | E21: =HYPERLINK("#'Mass Transfer'!D109","→ Mass") | F21: Green = dissolved O2 sits at/under the organism optimum; red = surface stripping insufficient, O2 may breach impairment.
A22: O₂ above organism minimum? | D22: ='Mass Transfer'!$D$110 | E22: =HYPERLINK("#'Mass Transfer'!D110","→ Mass") | F22: Minimum DO is a data gap for most organisms (dissolved-oxygen.md).
A23: Interval can be relaxed (carbon-limited)? | D23: ='Mass Transfer'!$D$113 | E23: =HYPERLINK("#'Mass Transfer'!D113","→ Mass") | F23: If surface stripping handles O2 you may dose far less often (the carbon-limited interval, in Supporting figures). The interval above is the safe fallback until kL_surf is measured.
A24: H₂ headspace safe? | D24: =Biology!$D$44 | E24: =HYPERLINK("#Biology!D44","→ Biology") | F24: EXPLOSIVE = H2 evolves faster than it dissolves; ensure headspace venting and no ignition source.
A25: Bubble model valid? | D25: ='Mass Transfer'!$D$64 | E25: =HYPERLINK("#'Mass Transfer'!D64","→ Mass") | F25: 'Sinter OOR' = sinter pore size out of the validated bubble range; sparge mass-transfer is approximate (expected for the porosity-0 disc).
A26: CO₂ supply meets demand? | D26: =IFERROR(IF('Mass Transfer'!$D$126>=1,"OK","UNDER (CO2 < demand)"),"calibrate this reactor first") | E26: =HYPERLINK("#'Mass Transfer'!D126","→ Mass") | F26: Ratio of CO2 supplied to carbon demand; should be >= 1.
A27: Pulse ≥ solenoid floor? | D27: =IFERROR('Mass Transfer'!$D$130,"calibrate this reactor first (see CO2 flows)") | E27: =HYPERLINK("#'Mass Transfer'!D130","→ Mass") | F27: The optimal pulse must exceed the shortest reliable sparge.
A28: Dosing window OK? | D28: =IFERROR('Mass Transfer'!$D$95,"calibrate this reactor first (see CO2 flows)") | E28: =HYPERLINK("#'Mass Transfer'!D95","→ Mass") | F28: Enough gap between doses to read OD without sparging.
A29: Carryover risk? | D29: ='Mass Transfer'!$D$59 | E29: =HYPERLINK("#'Mass Transfer'!D59","→ Mass") | F29: Gas velocity below the entrainment limit (no liquid carried out).
A30: Tip-speed shear OK? | D30: ='Mass Transfer'!$D$111 | E30: =HYPERLINK("#'Mass Transfer'!D111","→ Mass") | F30: Stirrer tip speed under the conservative 1.5 m/s shear limit.
A31: Media volume fits vial? | D31: =Geometry!$D$54 | E31: =HYPERLINK("#Geometry!D54","→ Geometry") | F31: Media volume not exceeding the max working volume.
A32: Liquid level OK? | D32: =Geometry!$D$55 | E32: =HYPERLINK("#Geometry!D55","→ Geometry") | F32: Liquid not above the usable vial depth.
A33: LED current-law in range? | D33: =Electrochemistry!$D$20 | E33: =HYPERLINK("#Electrochemistry!D20","→ Electrochemistry") | F33: LED intensity within Gerrit's-Law validated band 3-25% (gerrit-current.md).
A35: SUPPORTING FIGURES
A36: Steady-state DO (surface) | C36: mg/L | D36: ='Mass Transfer'!$D$108 | E36: =HYPERLINK("#'Mass Transfer'!D108","→ Mass") | F36: Predicted dissolved O2 the surface stripping settles at; compare to the organism band.
A37: Sparge interval if O₂ handled | C37: min | D37: ='Mass Transfer'!$D$112 | E37: =HYPERLINK("#'Mass Transfer'!D112","→ Mass") | F37: The longer (carbon-limited) interval usable if the 'relaxed' check is green.
A38: Stir-bar tip speed | C38: m/s | D38: ='Mass Transfer'!$D$68 | E38: =HYPERLINK("#'Mass Transfer'!D68","→ Mass") | F38: Checked against 1.5 m/s above.
A39: Carbon margin | C39: × | D39: =Biology!$D$35 | E39: =HYPERLINK("#Biology!D35","→ Biology") | F39: Dissolved CO2 vs RuBisCO Km at in-sparge peak; large = ample carbon.
A41: Key
A42: Verified / handbook / defined / standard
A43: Literature-supported (~90%)
A44: Design assumption (~70%)
...

Sheet Geometry
A1: GEOMETRY
A2: Parameter | B2: Name | C2: Unit | D2: Value | E2: Source / assumption
A4: IMPORTS (from other tabs)
A5: (import) Reactor selection | B5: reactor_sel | C5: - | D5: =Summary!$D$2 | E5: =HYPERLINK("#Summary!D3","→ Summary")
A6: (import) Media volume (set) | B6: media_volume | C6: mL | D6: =Summary!$D$9 | E6: =HYPERLINK("#Summary!D9","→ Summary")
A8: valid version 1 | B8: ver_name_1 | C8: - | D8: AEP0.1.1 | E8: Superseded by the reactor-type lookup below; not read by any formula
A9: valid version 2 | B9: ver_name_2 | C9: - | D9: AEP0.2 | E9: Superseded by the reactor-type lookup below; not read by any formula
A10: Vial outer diameter - AEP0.1.1 | B10: vial_OD_1 | C10: mm | D10: 27.48 | E10: Superseded by the reactor-type lookup below; not read by any formula
A11: Vial outer diameter - AEP0.2 | B11: vial_OD_2 | C11: mm | D11: 27.48 | E11: Superseded by the reactor-type lookup below; not read by any formula
A12: Internal usable depth - AEP0.1.1 | B12: D_int_1 | C12: mm | D12: 55 | E12: Superseded by the reactor-type lookup below; not read by any formula
A13: Internal usable depth - AEP0.2 | B13: D_int_2 | C13: mm | D13: 95 | E13: Superseded by the reactor-type lookup below; not read by any formula
A14: Recommended max working volume - AEP0.1.1 | B14: Vmax_1 | C14: mL | D14: 16 | E14: Superseded by the reactor-type lookup below; not read by any formula
A15: Recommended max working volume - AEP0.2 | B15: Vmax_2 | C15: mL | D15: 30 | E15: Superseded by the reactor-type lookup below; not read by any formula
A16: Total internal vial volume - AEP0.1.1 | B16: Vtot_1 | C16: mL | D16: 20 | E16: Superseded by the reactor-type lookup below; not read by any formula
A17: Total internal vial volume - AEP0.2 | B17: Vtot_2 | C17: mL | D17: 42 | E17: Superseded by the reactor-type lookup below; not read by any formula
A18: Vial outer diameter | B18: vial_OD | C18: mm | D18: =VLOOKUP(rx_ver,$A$84:$I$87,7,FALSE) | E18: Selected by rx_ver; invalid version returns an error.
A19: Vial wall thickness | B19: vial_wall | C19: mm | D19: 1.1 | E19: Borosilicate vial; Pioreactor publish neither wall nor internal diameter, so wall estimated ~1.1 mm (typical for this glass-vial class).
A20: Vial internal diameter | B20: vial_ID | C20: mm | D20: =vial_OD-2*vial_wall | E20: OD minus two wall thicknesses.
A21: Internal cross-sectional area | B21: A_x | C21: mm² | D21: =PI()/4*vial_ID^2 | E21: Uniform-cylinder body approximation (neck excluded - see headspace).
A22: Internal usable depth | B22: D_int | C22: mm | D22: =VLOOKUP(rx_ver,$A$84:$I$87,4,FALSE) | E22: Selected by rx_ver.
A23: Recommended max working volume (datum) | B23: V_max | C23: mL | D23: =VLOOKUP(rx_ver,$A$84:$I$87,5,FALSE) | E23: Selected by rx_ver.
A24: Total internal vial volume | B24: V_vial_total | C24: mL | D24: =VLOOKUP(rx_ver,$A$84:$I$87,6,FALSE) | E24: Selected by rx_ver.
A25: Bare liquid level (datum height) | B25: h_datum | C25: mm | D25: =V_max*1000/A_x | E25: Height the bare max volume reaches with no inserts.
A26: Electrode rod diameter | B26: rod_d | C26: mm | D26: 6 | E26: 6 mm rod electrodes.
A27: Number of electrodes | B27: rod_n | C27: - | D27: 2 | E27: Anode + cathode.
A28: Electrode tip clearance above base | B28: elec_clear | C28: mm | D28: 22 | E28: Held constant across builds (OD clear zone). 22 mm ↔ 33 mm insertion in AEP0.1.1. Input.
A29: Electrode insertion depth (derived) | B29: elec_ins | C29: mm | D29: =D_int-elec_clear | E29: Cap underside -> tip. Increases for the taller AEP0.2 to keep clearance constant.
A30: Sparge tube OD | B30: spg_OD | C30: mm | D30: 3.175 | E30: 1/8" OD Flexelene 135C.
A31: Sparge tube ID | B31: spg_ID | C31: mm | D31: 1.5875 | E31: 1/16" ID.
A32: Sparge release height (= anode tip) | B32: spg_tip_h | C32: mm | D32: =elec_clear | E32: CO₂ released near anode tip.
A33: Efflux tube OD | B33: eff_OD | C33: mm | D33: 3.175 | E33: 1/8" OD Flexelene 135C.
A34: Efflux tube ID | B34: eff_ID | C34: mm | D34: 1.5875 | E34: 1/16" ID.
A35: Electrode submerged length (@datum) | B35: elec_sub_L | C35: mm | D35: =MAX(0,h_datum-elec_clear) | E35: For displacement bookkeeping.
A36: Electrode displaced volume | B36: elec_disp | C36: mL | D36: =rod_n*(PI()/4*rod_d^2)*elec_sub_L/1000 | E36: Submerged rod volume.
A37: Sparge tube displaced volume | B37: spg_disp | C37: mL | D37: =(PI()/4*spg_OD^2)*MAX(0,h_datum-spg_tip_h)/1000 | E37: Submerged sparge-tube volume.
A38: Efflux tube submerged length | B38: eff_sub_L | C38: mm | D38: =(eff_OD+eff_ID)/2 | E38: 45 deg cut; level held at top of the ID opening, so wall is wetted from tip up to (OD+ID)/2.
A39: Efflux tube displaced volume | B39: eff_disp | C39: mL | D39: =(PI()/4*(eff_OD^2-eff_ID^2))*eff_sub_L/1000 | E39: Annular wall only (bore is open to withdrawal). 45 deg approximation.
A40: Total displaced volume | B40: disp_tot | C40: mL | D40: =elec_disp+spg_disp+eff_disp | E40: Sum of submerged inserts.
A41: LIQUID VOLUME TO CHARGE | B41: V_charge | C41: mL | D41: =IF(media_volume>0,media_volume,ROUND(V_max-disp_tot,0)) | E41: Integer mL to charge so the level matches the bare datum despite inserts.
A42: Resulting liquid level | B42: h_actual | C42: mm | D42: =(V_charge+disp_tot)*1000/A_x | E42: Level achieved by the integer charge (displacement taken at datum; sub-mm error).
...

Sheet Electrochemistry
A1: ELECTROCHEMISTRY
A2: Parameter | B2: Name | C2: Unit | D2: Value | E2: Source / assumption
A4: IMPORTS (from other tabs)
A5: (import) Temperature (absolute) | B5: T_K | C5: K | D5: =Biology!$D$18 | E5: =HYPERLINK("#Biology!D18","→ Biology")
A6: (import) Surface pressure | B6: P_atm | C6: Pa | D6: =Biology!$D$19 | E6: =HYPERLINK("#Biology!D19","→ Biology")
A7: (import) Ideal gas constant | B7: R_gas | C7: J/mol/K | D7: ='Mass Transfer'!$D$101 | E7: =HYPERLINK("#'Mass Transfer'!D101","→ Mass Transfer")
A8: (import) Electrode selection | B8: electrode_sel | D8: =Summary!$D$3 | E8: =HYPERLINK("#Summary!D4","→ Summary")
A10: LED intensity setpoint (Pioreactor LED_D) | B10: intensity | C10: % | D10: =Summary!$D$6 | E10: Electrode drive via LED_D channel. Input.
A11: Gerrit's Law - slope | B11: gerrit_slope | C11: mA/% | D11: 1.03 | E11: Gerrit's Law fit (slope) - from LED-current calibration; see protocol gerrit-current.md
A12: Gerrit's Law - intercept | B12: gerrit_int | C12: mA | D12: 2.6 | E12: Gerrit's Law fit (intercept); calibration-derived constant
A13: Gerrit's Law - min valid intensity | B13: gerrit_min | C13: % | D13: 3 | E13: Fit validated from 3%.
A14: Gerrit's Law - max valid intensity | B14: gerrit_max | C14: % | D14: 25 | E14: Fit validated to 25%; above this constant-current may fail as cell V nears the 5 V rail.
A15: Faraday constant | B15: F_const | C15: C/mol | D15: 96485.332 | E15: NIST CODATA (exact, SI 2019).
A16: Electrons per H₂ | B16: z_e_H2 | C16: - | D16: 2 | E16: 2H⁺ + 2e⁻ -> H₂.
A17: Electrons per O₂ | B17: z_e_O2 | C17: - | D17: 4 | E17: 2H₂O -> O₂ + 4H⁺ + 4e⁻.
A18: Faradaic efficiency – H₂ at cathode (HER share) | B18: etaF | C18: - | D18: 1 | E18: Cathodic H₂ faradaic efficiency. Neutral-pH HER peaks ~97% and competes with O₂ reduction, so true FE is likely <1 and unmeasured (Clary 2020, PNAS 117:32947). 1.0 = optimistic; measure by gas collection.
A19: Electrolysis current (Gerrit's Law) | B19: I_app | C19: A | D19: =(gerrit_slope*intensity+gerrit_int)/1000 | E19: I(mA) = slope x intensity + intercept; /1000 -> A.
A20: Gerrit's Law validity flag | B20: I_valid | C20: - | D20: =IF(AND(intensity>=gerrit_min,intensity<=gerrit_max),"OK","OUT") | E20: Linear fit only validated over the stated range.
A21: H₂ generation rate | B21: rH2_gen | C21: mol/h | D21: =I_app*etaF/(z_e_H2*F_const)*3600 | E21: Faraday: I x etaF /(z F).
A22: O₂ generation rate (anodic, gross) | B22: rO2_gen | C22: mol/h | D22: =I_app*etaF_OER/(z_e_O2*F_const)*3600 | E22: Anodic OER, gross. Uses etaF_OER (anodic), not the cathodic etaF. H₂:O₂(anodic) = 2:1.
A23: H₂ generation rate (volumetric) | B23: V_H2_gen | C23: mL/min | D23: =rH2_gen/60*R_gas*T_K/P_atm*1000000 | E23: Ideal gas at surface T,P. Collect gas over water to check against this.
A24: O₂ generation rate (volumetric) | B24: V_O2_gen | C24: mL/min | D24: =rO2_gen/60*R_gas*T_K/P_atm*1000000 | E24: Anodic gross O₂.
A25: Total gas generation rate | B25: V_gas_total | C25: mL/min | D25: =V_H2_gen+V_O2_gen | E25: Total electrolytic gas (H₂+O₂) — abiotic check: collect over water, no cells, to verify Gerrit/etaF. Less if etaF<1.
A26: Anodic O₂ faradaic efficiency | B26: etaF_OER | C26: - | D26: 1 | E26: Assumes chloride-free medium (no competing Cl2 evolution at the anode)
A27: Electrons per O₂ reduced (cathode) | B27: z_e_ORR | C27: - | D27: =VLOOKUP(electrode_sel,$A$35:$I$37,9,FALSE) | E27: Electrode lookup fixes ORR at 2 e- (peroxide pathway, SS cathode, neutral pH) for every current electrode; a 4 e- (to-water) electrode would need its own table row.
A28: O₂ consumed at cathode (ORR) | B28: O2_cathode_ORR | C28: mol/h | D28: =I_app*(1-etaF)/(z_e_ORR*F_const)*3600 | E28: Cathodic current not making H₂ (1−etaF) reduces dissolved O₂. 0 at etaF=1.
A29: Net O₂ to dissolved pool | B29: O2_net_gen | C29: mol/h | D29: =rO2_gen-O2_cathode_ORR | E29: Anodic O₂ minus cathodic consumption — the O₂ the dissolved pool receives.
A30: z_e_ORR=2 assumed (peroxide, non-Pt SS cathode, neutral pH); etaF unmeasured - both live here per electrode.
A31: Sparger (from electrode) | B31: sparger_e | D31: =VLOOKUP(electrode_sel,$A$35:$I$37,4,FALSE)
A32: Sinter porosity grade (from electrode) | B32: por_grade_e | D32: =IF(ISNUMBER(VLOOKUP(electrode_sel,$A$35:$I$37,5,FALSE)),VLOOKUP(electrode_sel,$A$35:$I$37,5,FALSE),0) | E32: Porosity 0 = Gerrit's sourced sintered disc (SD8/0/P 8mm, fallback SD10/0/P 10mm; Scientific Glass Labs, 2026-05)
A33: ELECTRODE LOOKUP (selecting the electrode sets sparger, porosity, cathode)
A34: Electrode | B34: anode material | C34: anode dia (mm) | D34: sparger | E34: sinter porosity | F34: cathode | G34: cathode dia (mm) | H34: etaF | I34: z_e_ORR
A35: Pt/Ti rod | B35: Pt/Ti | C35: 6 | D35: Tube | E35: n/a | F35: SS rod | G35: 6 | H35: ? | I35: 2
A36: MMO rod | B36: MMO | C36: 6 | D36: Tube | E36: n/a | F36: SS rod | G36: 6 | H36: ? | I36: 2
A37: MMO tube | B37: MMO | C37: 6 | D37: Sintered | E37: 0 | F37: SS rod | G37: 6 | H37: ? | I37: 2

Sheet Biology
A1: BIOLOGY
A2: Parameter | B2: Name | C2: Unit | D2: Value | E2: Source / assumption
A3: IMPORTS (from other tabs)
A4: (import) H₂ generation rate | B4: rH2_gen | C4: mol/h | D4: =Electrochemistry!$D$21 | E4: =HYPERLINK("#Electrochemistry!D21","→ Electrochemistry")
A5: (import) Net O₂ to dissolved pool | B5: O2_net_gen | C5: mol/h | D5: =Electrochemistry!$D$29 | E5: =HYPERLINK("#Electrochemistry!D29","→ Electrochemistry")
A6: (import) LIQUID VOLUME TO CHARGE | B6: V_charge | C6: mL | D6: =Geometry!$D$41 | E6: =HYPERLINK("#Geometry!D41","→ Geometry")
A7: (import) HOB organism | B7: organism_sel | D7: =Summary!$D$4 | E7: =HYPERLINK("#Summary!D5","→ Summary")
A8: (import) HOB organism | B8: organism_sel | D8: =Summary!$D$4 | E8: =HYPERLINK("#Summary!D5","→ Summary")
A10: Gas requirement ratio - H₂ | B10: bio_H2 | C10: - | D10: 6 | E10: H₂:O₂:CO₂ UPTAKE ratio (not feed; phase-dependent, Lu & Yu 2019). Knallgas caps O₂:H₂≤0.5; growth gives O₂:H₂≈0.29–0.35, CO₂:H₂≈0.15–0.19. 6:2:1 = mid-range central. Feed optimum 7:2:1 (Ishizaki 2001). Can't measure pre-growth.
A11: Gas requirement ratio - O₂ | B11: bio_O2 | C11: - | D11: 2 | E11: O₂:H₂ uptake, range 0.29–0.35 (×6 → 1.75–2.1). 2 = central; 1.8 (lean) is growth-protective.
A12: Gas requirement ratio - CO₂ | B12: bio_CO2 | C12: - | D12: 1 | E12: CO₂:H₂ uptake, range 0.15–0.19 (×6 → 0.9–1.15). 1 = central. Supply ≫ demand → non-limiting.
A13: H₂ consumed | B13: H2_cons | C13: mol/h | D13: =rH2_gen | E13: Assumes 100% of evolved H₂ consumed — steady growth only; ~0 during lag (see §13).
A14: O₂ consumed | B14: O2_cons | C14: mol/h | D14: =H2_cons*bio_O2/bio_H2 | E14: Assumes 100% H₂ uptake (upper bound); true limit is gas-liquid H₂ transfer — see H2_turnover
A15: CO₂ consumed (carbon fixation) | B15: CO2_cons | C15: mol/h | D15: =H2_cons*bio_CO2/bio_H2 | E15: H₂ consumed x (CO₂/H₂ ratio).
A16: EXCESS O₂ to remove | B16: O2_excess | C16: mol/h | D16: =O2_net_gen-O2_cons | E16: Upper bound: rests on full-uptake O2_cons above
A17: Temperature | B17: T_C | C17: °C | D17: =Summary!$D$8 | E17: C. necator optimum ~30 °C. Input.
A18: Temperature (absolute) | B18: T_K | C18: K | D18: =T_C+273.15 | E18: °C + 273.15.
A19: Surface pressure | B19: P_atm | C19: Pa | D19: =IF(Summary!$D$10>0,Summary!$D$10,101325) | E19: Atmospheric at the liquid surface (assumed).
A20: Standard atmosphere (atm->Pa) | B20: Pa_per_atm | C20: Pa/atm | D20: 101325 | E20: Defined: 1 atm = 101 325 Pa exactly.
A21: Henry solubility O₂ (ref, 298.15 K) | B21: H_O2ref | C21: mol/m³/Pa | D21: 1.2e-05 | E21: Sander (2023) recommended H^cp O2; reproduces ~7.5 mg/L air-saturation at 30 degC
A22: Henry T-dependence O₂ | B22: H_O2T | C22: K | D22: 1500 | E22: Sander (2023): d ln(Hcp)/d(1/T).
A23: Reference temperature | B23: T_ref | C23: K | D23: 298.15 | E23: Standard reference for Henry constants.
A24: Henry solubility O₂ at T | B24: H_O2_T | C24: mol/m³/Pa | D24: =H_O2ref*EXP(H_O2T*(1/T_K-1/T_ref)) | E24: van 't Hoff correction to reactor T.
A25: O₂ growth-inhibition ceiling (gas) | B25: O2_ceil_atm | C25: atm | D25: 0.3 | E25: Whole-cell growth inhibited above ~0.30 atm O₂ (Amer & Kim 2023); the [NiFe] hydrogenase itself is O₂-tolerant.
A26: O₂ ceiling (partial pressure) | B26: O2_ceil_Pa | C26: Pa | D26: =O2_ceil_atm*Pa_per_atm | E26: Ceiling in Pa.
A27: Dissolved-O₂ ceiling | B27: O2_ceil_C | C27: mol/m³ | D27: =H_O2_T*O2_ceil_Pa | E27: Henry's law at the gas ceiling.
A28: Dissolved-O₂ ceiling | B28: O2_ceil_uM | C28: µM | D28: =O2_ceil_C*1000 | E28: mol/m³ = mM; ×1000 = µM. Aim: minimise dissolved O₂; floor set by O₂-removal capacity (§11).
A29: Henry solubility CO₂ (ref, 298.15 K) | B29: H_CO2ref | C29: mol/m³/Pa | D29: 0.00033 | E29: Sander (2023) compilation; CO₂ ~25× more soluble than O₂.
A30: Henry T-dependence CO₂ | B30: H_CO2T | C30: K | D30: 2400 | E30: Sander (2023): d ln(Hcp)/d(1/T) for CO₂.
A31: Henry solubility CO₂ at T | B31: H_CO2_T | C31: mol/m³/Pa | D31: =H_CO2ref*EXP(H_CO2T*(1/T_K-1/T_ref)) | E31: van 't Hoff to reactor T.
A32: CO₂ partial pressure at sparge | B32: p_CO2_sparge | C32: Pa | D32: =P_atm | E32: Pure-CO₂ sparge: p_CO₂ ≈ surface pressure during a pulse. Assumption.
A33: Dissolved CO₂ (during sparge) | B33: CO2_diss | C33: mol/m³ | D33: =H_CO2_T*p_CO2_sparge | E33: Equilibrium dissolved CO₂ while sparging (mol/m³ = mM).
A34: RuBisCO Km for CO₂ | B34: Km_CO2 | C34: µM | D34: 50 | E34: RuBisCO Km(CO₂) ~ order 50 µM. Coarse — confirm.
A35: Carbon margin (dissolved CO₂ : Km) | B35: CO2_carbon_margin | C35: × | D35: =CO2_diss*1000/Km_CO2 | E35: Dissolved CO₂ : RuBisCO Km. ≫1 = saturating (duty-averaged lower).
A36: Carbonic-acid Ka1 (apparent) | B36: Ka1_carb | C36: mol/L | D36: 4.45e-07 | E36: CO₂(aq)+H₂O ⇌ H⁺+HCO₃⁻, pKa1 6.35 (25 °C).
A37: pH — UNBUFFERED worst case | B37: pH_CO2_unbuf | C37: - | D37: =-LOG10(SQRT(Ka1_carb*(CO2_diss/1000))) | E37: Unbuffered worst case (pure water + CO₂) — lower bound only; the Sydow phosphate medium holds pH near setpoint.
A38: Henry solubility H₂ (ref, 298.15 K) | B38: H_H2ref | C38: mol/m³/Pa | D38: 7.8e-06 | E38: Sander (2023). H₂ ~1.7× less soluble than O₂.
A39: Henry T-dependence H₂ | B39: H_H2T | C39: K | D39: 500 | E39: Sander (2023): d ln(Hcp)/d(1/T) for H₂ (weak T-dependence).
A40: Henry solubility H₂ at T | B40: H_H2_T | C40: mol/m³/Pa | D40: =H_H2ref*EXP(H_H2T*(1/T_K-1/T_ref)) | E40: van 't Hoff to reactor T.
A41: Dissolved-H₂ saturation (1 atm) | B41: C_H2_sat | C41: mol/m³ | D41: =H_H2_T*P_atm | E41: Max dissolved H₂ at 1 atm — the cells' H₂ ceiling.
...

Sheet Mass Transfer
A1: MASS TRANSFER
A2: Parameter | B2: Name | C2: Unit | D2: Value | E2: Source / assumption
A4: IMPORTS (from other tabs)
A5: (import) Stir-bar length (from reactor type) | B5: stir_len | C5: mm | D5: =Geometry!$D$52 | E5: =HYPERLINK("#Geometry!D52","→ Geometry") | F5: Magnetic stir bar. Pioreactor max 20 mm; confirm the supplied bar's length. Input.
A6: (import) Dissolved-O₂ ceiling | B6: O2_ceil_C | C6: mol/m³ | D6: =Biology!$D$27 | E6: =HYPERLINK("#Biology!D27","→ Biology")
A7: (import) O₂ ceiling (partial pressure) | B7: O2_ceil_Pa | C7: Pa | D7: =Biology!$D$26 | E7: =HYPERLINK("#Biology!D26","→ Biology")
A8: (import) Temperature (absolute) | B8: T_K | C8: K | D8: =Biology!$D$18 | E8: =HYPERLINK("#Biology!D18","→ Biology")
A9: (import) Surface pressure | B9: P_atm | C9: Pa | D9: =Biology!$D$19 | E9: =HYPERLINK("#Biology!D19","→ Biology")
A10: (import) CO₂ consumed (carbon fixation) | B10: CO2_cons | C10: mol/h | D10: =Biology!$D$15 | E10: =HYPERLINK("#Biology!D15","→ Biology")
A11: (import) EXCESS O₂ to remove | B11: O2_excess | C11: mol/h | D11: =Biology!$D$16 | E11: =HYPERLINK("#Biology!D16","→ Biology")
A12: (import) Henry solubility O₂ at T | B12: H_O2_T | C12: mol/m³/Pa | D12: =Biology!$D$24 | E12: =HYPERLINK("#Biology!D24","→ Biology")
A13: (import) Net O₂ to dissolved pool | B13: O2_net_gen | C13: mol/h | D13: =Electrochemistry!$D$29 | E13: =HYPERLINK("#Electrochemistry!D29","→ Electrochemistry")
A14: (import) Gas-liquid interfacial area | B14: interface_A | C14: mm² | D14: =Geometry!$D$44 | E14: =HYPERLINK("#Geometry!D44","→ Geometry")
A15: (import) Vial internal diameter | B15: vial_ID | C15: mm | D15: =Geometry!$D$20 | E15: =HYPERLINK("#Geometry!D20","→ Geometry")
A16: (import) LIQUID VOLUME TO CHARGE | B16: V_charge | C16: mL | D16: =Geometry!$D$41 | E16: =HYPERLINK("#Geometry!D41","→ Geometry")
A17: (import) Internal cross-sectional area | B17: A_x | C17: mm² | D17: =Geometry!$D$21 | E17: =HYPERLINK("#Geometry!D21","→ Geometry")
A18: (import) Sparge tube ID | B18: spg_ID | C18: mm | D18: =Geometry!$D$31 | E18: =HYPERLINK("#Geometry!D31","→ Geometry")
A19: (import) Headspace gas volume | B19: headspace_V | C19: mL | D19: =Geometry!$D$49 | E19: =HYPERLINK("#Geometry!D49","→ Geometry")
A20: (import) Sinter porosity grade (from electrode) | B20: por_grade | C20: 0-5 | D20: =Electrochemistry!$D$32 | E20: =HYPERLINK("#Electrochemistry!D32","→ Electrochemistry")
A21: (import) Sparger type (from electrode) | B21: sparger | C21: - | D21: =Electrochemistry!$D$31 | E21: =HYPERLINK("#Electrochemistry!D31","→ Electrochemistry")
A22: (import) Optimum DO (organism) | B22: DO_opt | D22: =Biology!$D$46 | E22: =HYPERLINK("#Biology!D46","→ Biology")
A23: (import) Impairment DO (organism) | B23: DO_impair | D23: =Biology!$D$47 | E23: =HYPERLINK("#Biology!D47","→ Biology")
A24: (import) Toxic/inhibition DO (organism) | B24: DO_toxic | D24: =Biology!$D$48 | E24: =HYPERLINK("#Biology!D48","→ Biology")
A25: (import) Minimum DO (organism) | B25: DO_min | D25: =Biology!$D$45 | E25: =HYPERLINK("#Biology!D45","→ Biology")
A27: valid sparger 1 | B27: spg_name_1 | C27: - | D27: Tube | E27: Bare 1/8" OD x 1/16" ID Flexelene 135C tube orifice.
A28: valid sparger 2 | B28: spg_name_2 | C28: - | D28: Sintered | E28: 10 mm sintered-glass disc annulus on a tubular anode.
A29: Surface tension (water, T) | B29: sigma | C29: N/m | D29: 0.0712 | E29: IAPWS R1-76(2014) formulation, evaluated at 30 °C.
A30: Liquid density (water, T) | B30: rho_L | C30: kg/m³ | D30: 995.65 | E30: IAPWS-95, evaluated at 30 °C.
A31: Gravitational acceleration | B31: g_const | C31: m/s² | D31: 9.80665 | E31: Standard gravity (defined).
A32: O₂ diffusivity in water (T) | B32: D_O2 | C32: m²/s | D32: 2.249e-09 | E32: O₂ diffusivity in water at 30 °C. Han & Bartels (1996) fit log₁₀(D[cm²/s]) = −4.410 + 773.8/T − (506.4/T)² → 2.25e-9 m²/s at 303.15 K.
A33: Pore size - grade 0 | B33: por0_um | C33: µm | D33: 205 | E33: DURAN P0 160-250 µm, midpoint. ISO 4793 (paywalled) underlies; DURAN table is free.
A34: Pore size - grade 1 | B34: por1_um | C34: µm | D34: 130 | E34: DURAN P1 100-160 µm, midpoint.
A35: Pore size - grade 2 | B35: por2_um | C35: µm | D35: 70 | E35: DURAN P2 40-100 µm, midpoint.
A36: Pore size - grade 3 | B36: por3_um | C36: µm | D36: 28 | E36: DURAN P3 16-40 µm, midpoint.
A37: Pore size - grade 4 | B37: por4_um | C37: µm | D37: 13 | E37: DURAN P4 10-16 µm, midpoint.
A38: Pore size - grade 5 | B38: por5_um | C38: µm | D38: 1.3 | E38: DURAN P5 1.0-1.6 µm, midpoint.
A39: Selected sinter pore diameter | B39: por_pore | C39: m | D39: =CHOOSE(por_grade+1,por0_um,por1_um,por2_um,por3_um,por4_um,por5_um)/1000000 | E39: Picked by por_grade.
A40: Tube orifice diameter | B40: tube_d_m | C40: m | D40: =spg_ID/1000 | E40: Tube ID in metres.
A41: Effective orifice/pore diameter | B41: d_orifice | C41: m | D41: =IF(sparger=spg_name_1,tube_d_m,IF(sparger=spg_name_2,por_pore,NA())) | E41: Tube ID or sinter pore; invalid sparger returns an error.
A42: Bubble detachment diameter | B42: d_bubble | C42: m | D42: =(6*d_orifice*sigma/(rho_L*g_const))^(1/3) | E42: Static low-flow force balance (buoyancy vs surface tension); valid in the quasi-static regime — see bubble_regime (§10).
...

Sheet CO2 flows
A1: CO₂ DOSING FLOWRATES
A2: Reactor | B2: date | C2: cylinder size | D2: observed volume* | E2: volume | F2: time | G2: flowrate | H2: average flowrate | I2: minimum sparge | J2: nominal flowrate | L2: KEY
C3: ml | D3: ml | E3: ml | F3: s | G3: ml/s | H3: ml/s | I3: s | J3: ml/s | L3: Flowrate set by inspection, as maximum to not give bubbles rising into vial neck
A4: ed04 | B4: 46190 | C4: 50 | D4: 0 | I4: 0.25 | J4: 3.33 | L4: First or last data point removed as suspect outlier
A5: ed04 | B5: 46190 | C5: 50 | D5: 50 | E5: =D5-D4 | F5: 15 | G5: =E5/F5 | H5: =AVERAGE(G5)
A6: ed04 | B6: 46190 | C6: 50 | D6: 0 | K6: Point | L6: Note
A7: ed04 | B7: 46190 | C7: 50 | D7: 12 | E7: =D7-D6 | F7: 4 | G7: =E7/F7 | H7: =AVERAGE(G7:G9) | K7: * | L7: CO2 collected in measuring cyclinder over CO2-saturated water
A8: ed04 | B8: 46190 | C8: 50 | D8: 26 | E8: =D8-D7 | F8: 4 | G8: =E8/F8 | K8: 46190 | L8: Collected using inlet CO2 tube rather than outlet as MEP vialcap leaking
A9: ed04 | B9: 46190 | C9: 50 | D9: 40 | E9: =D9-D8 | F9: 4 | G9: =E9/F9 | K9: 46190 | L9: Collected over saturated NaHCO3 soln, as Martin innovated without thinking
A10: ed04 | B10: 46190 | C10: 50 | D10: 0
A11: ed04 | B11: 46190 | C11: 50 | D11: 6 | E11: =D11-D10 | F11: 2 | G11: =E11/F11 | H11: =AVERAGE(G11:G16)
A12: ed04 | B12: 46190 | C12: 50 | D12: 15 | E12: =D12-D11 | F12: 2 | G12: =E12/F12
A13: ed04 | B13: 46190 | C13: 50 | D13: 21 | E13: =D13-D12 | F13: 2 | G13: =E13/F13
A14: ed04 | B14: 46190 | C14: 50 | D14: 29 | E14: =D14-D13 | F14: 2 | G14: =E14/F14
A15: ed04 | B15: 46190 | C15: 50 | D15: 35 | E15: =D15-D14 | F15: 2 | G15: =E15/F15
A16: ed04 | B16: 46190 | C16: 50 | D16: 45 | E16: =D16-D15 | F16: 2 | G16: =E16/F16
A17: ed04 | B17: 46190 | C17: 50 | D17: 0
A18: ed04 | B18: 46190 | C18: 50 | D18: 4 | E18: =D18-D17 | F18: 1 | G18: =E18/F18 | H18: =AVERAGE(G18:G23)
A19: ed04 | B19: 46190 | C19: 50 | D19: 8 | E19: =D19-D18 | F19: 1 | G19: =E19/F19
A20: ed04 | B20: 46190 | C20: 50 | D20: 11 | E20: =D20-D19 | F20: 1 | G20: =E20/F20
A21: ed04 | B21: 46190 | C21: 50 | D21: 15 | E21: =D21-D20 | F21: 1 | G21: =E21/F21
A22: ed04 | B22: 46190 | C22: 50 | D22: 19 | E22: =D22-D21 | F22: 1 | G22: =E22/F22
A23: ed04 | B23: 46190 | C23: 50 | D23: 23 | E23: =D23-D22 | F23: 1 | G23: =E23/F23
A24: ed04 | B24: 46190 | C24: 50 | D24: 31
A25: ed04 | B25: 46190 | C25: 50 | D25: 33 | E25: =D25-D24 | F25: 0.5 | G25: =E25/F25 | H25: =AVERAGE(G25:G29)
A26: ed04 | B26: 46190 | C26: 50 | D26: 35 | E26: =D26-D25 | F26: 0.5 | G26: =E26/F26
A27: ed04 | B27: 46190 | C27: 50 | D27: 37 | E27: =D27-D26 | F27: 0.5 | G27: =E27/F27
A28: ed04 | B28: 46190 | C28: 50 | D28: 39 | E28: =D28-D27 | F28: 0.5 | G28: =E28/F28
A29: ed04 | B29: 46190 | C29: 50 | D29: 41 | E29: =D29-D28 | F29: 0.5 | G29: =E29/F29
A30: ed04 | B30: 46190 | C30: 50 | D30: 42 | E30: =D30-D29 | F30: 0.25 | G30: =E30/F30 | H30: =AVERAGE(G30:G34)
A31: ed04 | B31: 46190 | C31: 50 | D31: 43 | E31: =D31-D30 | F31: 0.25 | G31: =E31/F31
A32: ed04 | B32: 46190 | C32: 50 | D32: 44 | E32: =D32-D31 | F32: 0.25 | G32: =E32/F32
A33: ed04 | B33: 46190 | C33: 50 | D33: 45 | E33: =D33-D32 | F33: 0.25 | G33: =E33/F33
A34: ed04 | B34: 46190 | C34: 50 | D34: 46 | E34: =D34-D33 | F34: 0.25 | G34: =E34/F34
A35: ed04 | B35: 46190 | C35: 10 | D35: 0 | E35: =D35-D34
A36: ed04 | B36: 46190 | C36: 10 | D36: 0.4 | E36: =D36-D35 | F36: 0.2 | G36: =E36/F36
A37: ed04 | B37: 46190 | C37: 10 | D37: 1.2 | E37: =D37-D36 | F37: 0.2 | G37: =E37/F37 | H37: =AVERAGE(G37:G39)
A38: ed04 | B38: 46190 | C38: 10 | D38: 2.2 | E38: =D38-D37 | F38: 0.2 | G38: =E38/F38
A39: ed04 | B39: 46190 | C39: 10 | D39: 3 | E39: =D39-D38 | F39: 0.2 | G39: =E39/F39
A40: ed04 | B40: 46190 | C40: 10 | D40: 0
...
