Workbook
Name A_anode: Chemistry!$D$130
Name A_anode_wet: Electrochemistry!$D$46
Name A_cath_wet: Electrochemistry!$D$47
Name A_DH: Chemistry!$D$186
Name a_int: 'Mass Transfer'!$D$49
Name a_surf: 'Mass Transfer'!$D$71
Name A_x: Geometry!$D$21
Name A_x: 'Mass Transfer'!$D$17
Name anode_dia: Electrochemistry!$D$42
Name anode_j_cont: Electrochemistry!$D$50
Name anode_j_max: Electrochemistry!$D$51
Name anode_material: Electrochemistry!$D$63
Name anode_shape: Electrochemistry!$D$41
Name b_anode: Electrochemistry!$D$107
Name b_cath: Electrochemistry!$D$109
Name bio_CO2: Biology!$D$12
Name bio_H2: Biology!$D$10
Name bio_O2: Biology!$D$11
Name bleach_flag: Chemistry!$D$109
Name bleach_rate: Chemistry!$D$107
Name bleach_t1ppm: Chemistry!$D$108
Name bubble_regime: 'Mass Transfer'!$D$64
Name buffer_flag: Chemistry!$D$219
Name C_air_CO2: 'Mass Transfer'!$D$146
Name C_cycle_peak: 'Mass Transfer'!$D$199
Name C_cycle_start: 'Mass Transfer'!$D$198
Name C_eff: Chemistry!$D$145
Name C_eff_Cl2: Chemistry!$D$226
Name C_eff_hi: Chemistry!$D$157
Name C_eff_lo: Chemistry!$D$156
Name C_H2_sat: Biology!$D$41
Name C_sat_CO2: 'Mass Transfer'!$D$145
Name Ca_CO2: 'Mass Transfer'!$D$157
Name cal_Dint: Calibrations!$D$75
Name cal_DO_impair: Calibrations!$D$105
Name cal_DO_min: Calibrations!$D$103
Name cal_DO_opt: Calibrations!$D$104
Name cal_DO_toxic: Calibrations!$D$106
Name cal_etaF: Calibrations!$D$31
Name cal_etaF_OER: Calibrations!$D$32
Name cal_flow: Calibrations!$D$60
Name cal_gerrit_int: Calibrations!$D$17
Name cal_gerrit_slope: Calibrations!$D$16
Name cal_j_ceiling: Calibrations!$D$137
Name cal_j_opt: Calibrations!$D$136
Name cal_kLa: Calibrations!$D$46
Name cal_knall_CO2: Calibrations!$D$122
Name cal_knall_H2: Calibrations!$D$120
Name cal_knall_O2: Calibrations!$D$121
Name cal_sinter: Calibrations!$D$89
Name cal_Vtot: Calibrations!$D$74
Name cal_warning: 'Mass Transfer'!$D$120
Name carbon_margin_min: 'Mass Transfer'!$D$85
Name carry_flag: 'Mass Transfer'!$D$59
Name cath_j_cont: Electrochemistry!$D$52
Name cath_j_max: Electrochemistry!$D$53
Name cathode_dia: Electrochemistry!$D$44
Name cathode_shape: Electrochemistry!$D$43
Name Cb_CO2: 'Mass Transfer'!$D$158
Name Cl_kill: Chemistry!$D$147

Sheet Summary
A1: Parameter | B1: Name | C1: Unit | D1: Value | E1: Source | F1: Comment
A2: Reactor | B2: Reactor_sel | D2: ed04 | E2: select | F2: Active build. Choose from the values below. Dropdown.
A3: Electrode | B3: electrode_sel | D3: Pt/Ti rod | E3: select | F3: CO₂ delivery route. Choose from the values below. Dropdown.
A4: HOB organism | B4: organism_sel | D4: UdG (mixed) | E4: select | F4: The HOB strain; sets the DO band the schedule targets.
A5: Media | B5: media_sel | D5: MC02 | E5: select | F5: Growth medium.
A6: Electrolysis power | B6: led_intensity | C6: % | D6: 3 | E6: input | F6: LED channel D %, the AEP-Plugin 'electrolysis_power' setting (runtime-clamped 0–10 %); drives the electrolysis current via Gerrit's Law.
A7: Stirrer rate | B7: stir_rpm_set | C7: rpm | D7: 1000 | E7: input | F7: Stir rate; sets tip speed and surface O2 transfer.
A8: Temperature setpoint | B8: temp_C | C8: °C | D8: 25 | E8: input | F8: Temperature setpoint; sets Henry solubilities and rates.
A9: Media volume | B9: media_volume | C9: mL | E9: input/blank | F9: Liquid charged; leave blank to use the reactor's recommended max working volume.
A10: Ambient pressure | B10: P_atm_set | C10: Pa | E10: input/blank | F10: blank = default 101325 Pa
A12: Results | B12: Name | C12: Unit | D12: Value | E12: Source | F12: Comment | G12: Override
A13: CO₂ sparge duration | C13: s | D13: =IFERROR('Mass Transfer'!$D$90,"calibrate this reactor first (see CO2 flows)") -> 0.78451305 | E13: =HYPERLINK("#'Mass Transfer'!D90","→ Mass") -> → Mass | F13: How long to open the CO2 solenoid each dose.
A14: CO₂ sparge duration (rounded) | C14: s | D14: =IF(AND(ISNUMBER($G$13),$G$13>0),$G$13,IF(NOT(ISNUMBER(D13)),D13,IF(D13>0.5,ROUND(D13,0),ROUND(D13,1-(1+INT(LOG10(ABS(D13)))))))) -> 1
A15: CO₂ sparge interval | C15: min | D15: =IFERROR('Mass Transfer'!$D$91,"calibrate this reactor first (see CO2 flows)") -> 13.911968 | E15: =HYPERLINK("#'Mass Transfer'!D91","→ Mass") -> → Mass | F15: Time between doses. Now credits surface O2 stripping (kL_surf proxy); when surface handles the O2 this is carbon-limited. Refine via the kL_surf measurement.
A16: CO₂ sparge interval (rounded) | C16: min | D16: =IF(AND(ISNUMBER($G$15),$G$15>0),$G$15,IF(NOT(ISNUMBER(D15)),D15,IF(D15>0.5,ROUND(D15,0),ROUND(D15,1-(1+INT(LOG10(ABS(D15)))))))) -> 14
A18: Checks | D18: Value | E18: Source | F18: Comment
A19: Vial geometry consistent? | D19: =Geometry!$D$90 -> VIAL GEOMETRY INCONSISTENT - measure true fill volume & bore depth | E19: =HYPERLINK("#Geometry!D90","→ Geometry") -> → Geometry | F19: Red until the vial headspace is measured (vial-geometry.md). While red, the pulse above is provisional (~4x uncertain).
A20: Reactor calibrated? | D20: ='Mass Transfer'!$D$120 -> calibrated: ed04 | E20: =HYPERLINK("#'Mass Transfer'!D120","→ Mass") -> → Mass | F20: Red = no CO2-flow calibration for this reactor; results read 'calibrate first' (flow-calibration.md).
A21: O₂ at/under organism optimum? | D21: ='Mass Transfer'!$D$109 -> organism optimum unknown | E21: =HYPERLINK("#'Mass Transfer'!D109","→ Mass") -> → Mass | F21: Green = dissolved O2 sits at/under the organism optimum; red = surface stripping insufficient, O2 may breach impairment.
A22: O₂ above organism minimum? | D22: ='Mass Transfer'!$D$110 -> minimum DO unknown - measure | E22: =HYPERLINK("#'Mass Transfer'!D110","→ Mass") -> → Mass | F22: Minimum DO is a data gap for most organisms (dissolved-oxygen.md).
A23: Interval can be relaxed (carbon-limited)? | D23: ='Mass Transfer'!$D$113 -> organism DO unknown | E23: =HYPERLINK("#'Mass Transfer'!D113","→ Mass") -> → Mass | F23: If surface stripping handles O2 you may dose far less often (the carbon-limited interval, in Supporting figures). The interval above is the safe fallback until kL_surf is measured.
A24: H₂ headspace safe? | D24: =Biology!$D$44 -> EXPLOSIVE | E24: =HYPERLINK("#Biology!D44","→ Biology") -> → Biology | F24: EXPLOSIVE = H2 evolves faster than it dissolves; ensure headspace venting and no ignition source.
A25: Bubble model valid? | D25: ='Mass Transfer'!$D$64 -> Static | E25: =HYPERLINK("#'Mass Transfer'!D64","→ Mass") -> → Mass | F25: 'Sinter OOR' = sinter pore size out of the validated bubble range; sparge mass-transfer is approximate (expected for the porosity-0 disc).
A26: CO₂ supply meets demand? | D26: =IFERROR("×"&TEXT('Mass Transfer'!$D$126,"0.0")&IF('Mass Transfer'!$D$126>=1," OK"," SHORTFALL (CO2 < demand)"),"calibrate this reactor first") -> ×26.6 OK | E26: =HYPERLINK("#'Mass Transfer'!D126","→ Mass") -> → Mass | F26: Ratio of CO2 supplied to carbon demand; should be >= 1.
A27: Pulse ≥ solenoid floor? | D27: =IFERROR('Mass Transfer'!$D$130,"calibrate this reactor first (see CO2 flows)") -> OK | E27: =HYPERLINK("#'Mass Transfer'!D130","→ Mass") -> → Mass | F27: The optimal pulse must exceed the shortest reliable sparge.
A28: Dosing window OK? | D28: =IFERROR('Mass Transfer'!$D$95,"calibrate this reactor first (see CO2 flows)") -> OK | E28: =HYPERLINK("#'Mass Transfer'!D95","→ Mass") -> → Mass | F28: Enough gap between doses to read OD without sparging.
A29: Carryover risk? | D29: ='Mass Transfer'!$D$59 -> OK | E29: =HYPERLINK("#'Mass Transfer'!D59","→ Mass") -> → Mass | F29: Gas velocity below the entrainment limit (no liquid carried out).
A30: Tip-speed shear OK? | D30: ='Mass Transfer'!$D$111 -> OK | E30: =HYPERLINK("#'Mass Transfer'!D111","→ Mass") -> → Mass | F30: Stirrer tip speed under the conservative 1.5 m/s shear limit.
A31: Media volume fits vial? | D31: =Geometry!$D$54 -> OK | E31: =HYPERLINK("#Geometry!D54","→ Geometry") -> → Geometry | F31: Media volume not exceeding the max working volume.
A32: Liquid level OK? | D32: =Geometry!$D$55 -> OK | E32: =HYPERLINK("#Geometry!D55","→ Geometry") -> → Geometry | F32: Liquid not above the usable vial depth.
A33: LED current-law in range? | D33: =Electrochemistry!$D$20 -> OK | E33: =HYPERLINK("#Electrochemistry!D20","→ Electrochemistry") -> → Electrochemistry | F33: LED intensity within Gerrit's-Law validated band 3-25% (gerrit-current.md).
A34: Organism DO data present? | D34: =IF(AND(ISNUMBER(Biology!$D$45),ISNUMBER(Biology!$D$46),ISNUMBER(Biology!$D$47),ISNUMBER(Biology!$D$48)),"inputs present","DATA GAP - organism DO thresholds unmeasured; results unreliable") -> DATA GAP - organism DO thresholds unmeasured; results unreliable | E34: =HYPERLINK("#Biology!D45","→ Biology") -> → Biology | F34: Red = the selected organism has no measured DO thresholds, so every DO/sparge verdict above is running on missing data.
A35: Endpoint pH (worst-case, full sparge) | D35: =Chemistry!$D$220 -> #DIV/0! | E35: =HYPERLINK("#Chemistry!D103","→ Chemistry") -> → Chemistry | F35: Operating pH at the CO₂ trough, on the activity scale a probe reads. Green 6.5–7.5; red outside 6–8.
A36: Effective biocidal chlorine | C36: mg/L | D36: =Chemistry!$D$226 -> #DIV/0! | E36: =HYPERLINK("#Chemistry!D226","→ Chemistry") -> → Chemistry | F36: Effective biocidal chlorine from the medium’s chloride, on the as-Cl₂ basis the literature thresholds use. Green <0.1, red >1 mg/L. Zero for chloride-free media.
A37: SUPPORTING FIGURES
A38: Steady-state DO (surface) | C38: mg/L | D38: ='Mass Transfer'!$D$108 -> 2.6390317 | E38: =HYPERLINK("#'Mass Transfer'!D108","→ Mass") -> → Mass | F38: Predicted dissolved O2 the surface stripping settles at; compare to the organism band.
A39: Sparge interval if O₂ handled | C39: min | D39: ='Mass Transfer'!$D$112 -> 185.24021 | E39: =HYPERLINK("#'Mass Transfer'!D112","→ Mass") -> → Mass | F39: The longer (carbon-limited) interval usable if the 'relaxed' check is green.
A40: Stir-bar tip speed | C40: m/s | D40: ='Mass Transfer'!$D$68 -> 0.62831853 | E40: =HYPERLINK("#'Mass Transfer'!D68","→ Mass") -> → Mass | F40: Checked against 1.5 m/s above.
A41: Carbon margin | C41: × | D41: =Biology!$D$35 -> 668.745 | E41: =HYPERLINK("#Biology!D35","→ Biology") -> → Biology | F41: Dissolved CO2 vs RuBisCO Km at in-sparge peak; large = ample carbon.
A42: ELECTROLYSIS & CURRENT DENSITY
...

Sheet Geometry
A1: GEOMETRY
A2: Parameter | B2: Name | C2: Unit | D2: Value | E2: Source / assumption
A4: IMPORTS (from other tabs)
A5: (import) Reactor selection | B5: reactor_sel | C5: - | D5: =Summary!$D$2 -> ed04 | E5: =HYPERLINK("#Summary!D2","→ Summary") -> → Summary
A6: (import) Media volume (set) | B6: media_volume | C6: mL | D6: =Summary!$D$9 -> 0 | E6: =HYPERLINK("#Summary!D9","→ Summary") -> → Summary
A8: valid version 1 | B8: ver_name_1 | C8: - | D8: AEP0.1.1 | E8: Superseded by the reactor-type lookup below; not read by any formula
A9: valid version 2 | B9: ver_name_2 | C9: - | D9: AEP0.2 | E9: Superseded by the reactor-type lookup below; not read by any formula
A10: Vial outer diameter - AEP0.1.1 | B10: vial_OD_1 | C10: mm | D10: 27.48 | E10: Superseded by the reactor-type lookup below; not read by any formula
A11: Vial outer diameter - AEP0.2 | B11: vial_OD_2 | C11: mm | D11: 27.48 | E11: Superseded by the reactor-type lookup below; not read by any formula
A12: Internal usable depth - AEP0.1.1 | B12: D_int_1 | C12: mm | D12: 55 | E12: Superseded by the reactor-type lookup below; not read by any formula
A13: Internal usable depth - AEP0.2 | B13: D_int_2 | C13: mm | D13: 95 | E13: Superseded by the reactor-type lookup below; not read by any formula
A14: Recommended max working volume - AEP0.1.1 | B14: Vmax_1 | C14: mL | D14: 16 | E14: Superseded by the reactor-type lookup below; not read by any formula
A15: Recommended max working volume - AEP0.2 | B15: Vmax_2 | C15: mL | D15: 30 | E15: Superseded by the reactor-type lookup below; not read by any formula
A16: Total internal vial volume - AEP0.1.1 | B16: Vtot_1 | C16: mL | D16: 20 | E16: Superseded by the reactor-type lookup below; not read by any formula
A17: Total internal vial volume - AEP0.2 | B17: Vtot_2 | C17: mL | D17: 42 | E17: Superseded by the reactor-type lookup below; not read by any formula
A18: Vial outer diameter | B18: vial_OD | C18: mm | D18: =VLOOKUP(rx_ver,$A$84:$I$87,7,FALSE) -> 27.48 | E18: Selected by rx_ver; invalid version returns an error.
A19: Vial wall thickness | B19: vial_wall | C19: mm | D19: 1.1 | E19: Borosilicate vial; Pioreactor publish neither wall nor internal diameter, so wall estimated ~1.1 mm (typical for this glass-vial class).
A20: Vial internal diameter | B20: vial_ID | C20: mm | D20: =vial_OD-2*vial_wall -> 25.28 | E20: OD minus two wall thicknesses.
A21: Internal cross-sectional area | B21: A_x | C21: mm² | D21: =PI()/4*vial_ID^2 -> 501.931 | E21: Uniform-cylinder body approximation (neck excluded - see headspace).
A22: Internal usable depth | B22: D_int | C22: mm | D22: =IF(ISNUMBER(cal_Dint),cal_Dint,VLOOKUP(rx_ver,$A$84:$I$87,4,FALSE)) -> 55 | E22: Selected by rx_ver.
A23: Recommended max working volume (datum) | B23: V_max | C23: mL | D23: =VLOOKUP(rx_ver,$A$84:$I$87,5,FALSE) -> 16 | E23: Selected by rx_ver.
A24: Total internal vial volume | B24: V_vial_total | C24: mL | D24: =IF(ISNUMBER(cal_Vtot),cal_Vtot,VLOOKUP(rx_ver,$A$84:$I$87,6,FALSE)) -> 20 | E24: Selected by rx_ver.
A25: Bare liquid level (datum height) | B25: h_datum | C25: mm | D25: =V_max*1000/A_x -> 31.876891 | E25: Height the bare max volume reaches with no inserts.
A26: Electrode rod diameter | B26: rod_d | C26: mm | D26: 6 | E26: 6 mm rod electrodes.
A27: Number of electrodes | B27: rod_n | C27: - | D27: 2 | E27: Anode + cathode.
A28: Electrode tip clearance above base | B28: elec_clear | C28: mm | D28: 22 | E28: Held constant across builds (OD clear zone). 22 mm ↔ 33 mm insertion in AEP0.1.1. Input.
A29: Electrode insertion depth (derived) | B29: elec_ins | C29: mm | D29: =D_int-elec_clear -> 33 | E29: Cap underside -> tip. Increases for the taller AEP0.2 to keep clearance constant.
A30: Sparge tube OD | B30: spg_OD | C30: mm | D30: 3.175 | E30: 1/8" OD Flexelene 135C.
A31: Sparge tube ID | B31: spg_ID | C31: mm | D31: 1.5875 | E31: 1/16" ID.
A32: Sparge release height (= anode tip) | B32: spg_tip_h | C32: mm | D32: =elec_clear -> 22 | E32: CO₂ released near anode tip.
A33: Efflux tube OD | B33: eff_OD | C33: mm | D33: 3.175 | E33: 1/8" OD Flexelene 135C.
A34: Efflux tube ID | B34: eff_ID | C34: mm | D34: 1.5875 | E34: 1/16" ID.
A35: Electrode submerged length (@datum) | B35: elec_sub_L | C35: mm | D35: =MAX(0,h_datum-elec_clear) -> 9.8768913 | E35: For displacement bookkeeping.
A36: Electrode displaced volume | B36: elec_disp | C36: mL | D36: =rod_n*(PI()/4*rod_d^2)*elec_sub_L/1000 -> 0.55852505 | E36: Submerged rod volume.
A37: Sparge tube displaced volume | B37: spg_disp | C37: mL | D37: =(PI()/4*spg_OD^2)*MAX(0,h_datum-spg_tip_h)/1000 -> 0.078198355 | E37: Submerged sparge-tube volume.
A38: Efflux tube submerged length | B38: eff_sub_L | C38: mm | D38: =(eff_OD+eff_ID)/2 -> 2.38125 | E38: 45 deg cut; level held at top of the ID opening, so wall is wetted from tip up to (OD+ID)/2.
A39: Efflux tube displaced volume | B39: eff_disp | C39: mL | D39: =(PI()/4*(eff_OD^2-eff_ID^2))*eff_sub_L/1000 -> 0.014139811 | E39: Annular wall only (bore is open to withdrawal). 45 deg approximation.
A40: Total displaced volume | B40: disp_tot | C40: mL | D40: =elec_disp+spg_disp+eff_disp -> 0.65086321 | E40: Sum of submerged inserts.
A41: LIQUID VOLUME TO CHARGE | B41: V_charge | C41: mL | D41: =IF(media_volume>0,media_volume,ROUND(V_max-disp_tot,0)) -> 15 | E41: Integer mL to charge so the level matches the bare datum despite inserts.
A42: Resulting liquid level | B42: h_actual | C42: mm | D42: =(V_charge+disp_tot)*1000/A_x -> 31.181304 | E42: Level achieved by the integer charge (displacement taken at datum; sub-mm error).
...

Sheet Electrochemistry
A1: ELECTROCHEMISTRY
A2: Parameter | B2: Name | C2: Unit | D2: Value | E2: Source / assumption
A4: IMPORTS (from other tabs)
A5: (import) Temperature (absolute) | B5: T_K | C5: K | D5: =Biology!$D$18 -> 298.15 | E5: =HYPERLINK("#Biology!D18","→ Biology") -> → Biology
A6: (import) Surface pressure | B6: P_atm | C6: Pa | D6: =Biology!$D$19 -> 101325 | E6: =HYPERLINK("#Biology!D19","→ Biology") -> → Biology
A7: (import) Ideal gas constant | B7: R_gas | C7: J/mol/K | D7: ='Mass Transfer'!$D$101 -> 8.3144626 | E7: =HYPERLINK("#'Mass Transfer'!D101","→ Mass Transfer") -> → Mass Transfer
A8: (import) Electrode selection | B8: electrode_sel | D8: =Summary!$D$3 -> Pt/Ti rod | E8: =HYPERLINK("#Summary!D3","→ Summary") -> → Summary
A10: LED intensity setpoint (Pioreactor LED_D) | B10: intensity | C10: % | D10: =Summary!$D$6 -> 3 | E10: Electrode drive via LED_D channel. Input.
A11: Gerrit's Law - slope | B11: gerrit_slope | C11: mA/% | D11: =IF(ISNUMBER(cal_gerrit_slope),cal_gerrit_slope,1.03) -> 1.03 | E11: Gerrit's Law fit (slope) - from LED-current calibration; see protocol gerrit-current.md
A12: Gerrit's Law - intercept | B12: gerrit_int | C12: mA | D12: =IF(ISNUMBER(cal_gerrit_int),cal_gerrit_int,2.6) -> 2.6 | E12: Gerrit's Law fit (intercept); calibration-derived constant
A13: Gerrit's Law - min valid intensity | B13: gerrit_min | C13: % | D13: 3 | E13: Fit validated from 3%.
A14: Gerrit's Law - max valid intensity | B14: gerrit_max | C14: % | D14: 25 | E14: Fit validated to 25%; above this constant-current may fail as cell V nears the 5 V rail.
A15: Faraday constant | B15: F_const | C15: C/mol | D15: 96485.332 | E15: NIST CODATA (exact, SI 2019).
A16: Electrons per H₂ | B16: z_e_H2 | C16: - | D16: 2 | E16: 2H⁺ + 2e⁻ -> H₂.
A17: Electrons per O₂ | B17: z_e_O2 | C17: - | D17: 4 | E17: 2H₂O -> O₂ + 4H⁺ + 4e⁻.
A18: Faradaic efficiency – H₂ at cathode (HER share) | B18: etaF | C18: - | D18: =IF(ISNUMBER(cal_etaF),cal_etaF,etaF_calc) -> 0.9774753 | E18: Cathodic H₂ faradaic efficiency: a measured value from the Calibrations tab if there is one, otherwise CALCULATED (D89) from the cathodic O₂ reduction competing for the current — it is no longer assumed to be 1. Neutral-pH HER on stainless peaks near 97% before that competition is counted, so the calculated value remains an upper bound.
A19: Electrolysis current (Gerrit's Law) | B19: I_app | C19: A | D19: =(gerrit_slope*intensity+gerrit_int)/1000 -> 0.00569 | E19: I(mA) = slope x intensity + intercept; /1000 -> A.
A20: Gerrit's Law validity flag | B20: I_valid | C20: - | D20: =IF(AND(intensity>=gerrit_min,intensity<=gerrit_max),"OK","OUT") -> OK | E20: Linear fit only validated over the stated range.
A21: H₂ generation rate | B21: rH2_gen | C21: mol/h | D21: =I_app*etaF/(z_e_H2*F_const)*3600 -> 0.00010375983 | E21: Faraday: I x etaF /(z F).
A22: O₂ generation rate (anodic, gross) | B22: rO2_gen | C22: mol/h | D22: =I_app*etaF_OER/(z_e_O2*F_const)*3600 -> 5.3075425e-05 | E22: Anodic OER, gross. Uses etaF_OER (anodic), not the cathodic etaF. H₂:O₂(anodic) = 2:1.
A23: H₂ generation rate (volumetric) | B23: V_H2_gen | C23: mL/min | D23: =rH2_gen/60*R_gas*T_K/P_atm*1000000 -> 0.04230877 | E23: Ideal gas at surface T,P. Collect gas over water to check against this.
A24: O₂ generation rate (volumetric) | B24: V_O2_gen | C24: mL/min | D24: =rO2_gen/60*R_gas*T_K/P_atm*1000000 -> 0.021641862 | E24: Anodic gross O₂.
A25: Total gas generation rate | B25: V_gas_total | C25: mL/min | D25: =V_H2_gen+V_O2_gen -> 0.063950632 | E25: Total electrolytic gas (H₂+O₂) — abiotic check: collect over water, no cells, to verify Gerrit/etaF. Less if etaF<1.
A26: Anodic O₂ faradaic efficiency | B26: etaF_OER | C26: - | D26: =IF(ISNUMBER(cal_etaF_OER),cal_etaF_OER,etaF_OER_calc) -> 1 | E26: Anodic O₂ faradaic efficiency: measured if available, otherwise CALCULATED (etaF_OER_calc) as 1 − the chlorine share − the metal-dissolution share. The old note asserted a chloride-free medium; UdG contains chloride and the sheet now models the chlorine current explicitly.
A27: Electrons per O₂ reduced (cathode) | B27: z_e_ORR | C27: - | D27: =VLOOKUP(electrode_sel,$A$35:$I$38,9,FALSE) -> 2 | E27: Electrode lookup fixes ORR at 2 e- (peroxide pathway, SS cathode, neutral pH) for every current electrode; a 4 e- (to-water) electrode would need its own table row.
A28: O₂ consumed at cathode (ORR) | B28: O2_cathode_ORR | C28: mol/h | D28: =I_app*(1-etaF)/(z_e_ORR*F_const)*3600 -> 2.3910162e-06 | E28: Cathodic current not making H₂ (1−etaF) reduces dissolved O₂. 0 at etaF=1.
A29: Net O₂ to dissolved pool | B29: O2_net_gen | C29: mol/h | D29: =rO2_gen-O2_cathode_ORR -> 5.0684409e-05 | E29: Anodic O₂ minus cathodic consumption — the O₂ the dissolved pool receives.
A30: z_e_ORR=2 assumed (peroxide, non-Pt SS cathode, neutral pH); etaF unmeasured - both live here per electrode.
A31: Sparger (from electrode) | B31: sparger_e | D31: =VLOOKUP(electrode_sel,$A$35:$I$38,4,FALSE) -> Tube
A32: Sinter porosity grade (from electrode) | B32: por_grade_e | D32: =IF(ISNUMBER(cal_sinter),cal_sinter,IF(ISNUMBER(VLOOKUP(electrode_sel,$A$35:$I$38,5,FALSE)),VLOOKUP(electrode_sel,$A$35:$I$38,5,FALSE),0)) -> 0 | E32: Porosity 0 = Gerrit's sourced sintered disc (SD8/0/P 8mm, fallback SD10/0/P 10mm; Scientific Glass Labs, 2026-05)
A33: ELECTRODE LOOKUP (selecting the electrode sets sparger, porosity, cathode)
A34: Electrode | B34: anode material | C34: anode dia (mm) | D34: sparger | E34: sinter porosity | F34: cathode | G34: cathode dia (mm) | H34: etaF | I34: z_e_ORR | J34: anode shape | K34: anode j cont (mA/cm²) | L34: anode j max (mA/cm²) | M34: cathode shape | N34: material note
A35: Pt/Ti rod | B35: Pt/Ti | C35: 6 | D35: Tube | E35: n/a | F35: SS rod | G35: 6 | H35: ? | I35: 2 | J35: rod | K35: 100 | L35: 500 | M35: rod | N35: Pt/Ti O₂-evolution; cells bind before the coating.
A36: MMO rod | B36: MMO | C36: 6 | D36: Tube | E36: n/a | F36: SS rod | G36: 6 | H36: ? | I36: 2 | J36: rod | K36: 50 | L36: 500 | M36: rod | N36: IrO₂-Ta₂O₅ O₂-selective; derates vs chloride.
A37: MMO tube | B37: MMO | C37: 6 | D37: Sintered | E37: 0 | F37: SS rod | G37: 6 | H37: ? | I37: 2 | J37: tube | K37: 10 | L37: 60 | M37: rod | N37: Tubular MMO CP rating ~100 A/m²; binds near the cell limit.
A38: Graphite rod | B38: Graphite | C38: 6 | D38: Tube | E38: n/a | F38: SS rod | G38: 6 | H38: ? | I38: 2 | J38: rod | K38: 35 | L38: 50 | M38: rod | N38: Consumable; ~35 mA/cm² erosion, unsuitable for sustained neutral O₂; testing only.
A40: CURRENT DENSITY, WETTED AREA & LIMITS
A41: Anode shape (from electrode) | B41: anode_shape | C41: - | D41: =VLOOKUP(electrode_sel,$A$35:$N$38,10,FALSE) -> rod | E41: Rod counts its end face; a tube does not.
A42: Anode diameter (from electrode) | B42: anode_dia | C42: mm | D42: =VLOOKUP(electrode_sel,$A$35:$N$38,3,FALSE) -> 6 | E42: Electrode table.
A43: Cathode shape (from electrode) | B43: cathode_shape | C43: - | D43: =VLOOKUP(electrode_sel,$A$35:$N$38,13,FALSE) -> rod | E43: Rod/tube; sets the end-face term.
...

Sheet Chemistry
A1: CHEMISTRY — buffered pH & anodic bleaching (open-system carbonate+phosphate charge balance, van't Hoff to reactor T)
A2: Parameter | B2: Name | C2: Unit | D2: Value | E2: Source / assumption
A3: IMPORTS (from other tabs)
A4: (import) Reactor temperature | B4: TKc | C4: K | D4: =Biology!$D$18 -> 298.15 | E4: → Biology
A5: (import) Dissolved CO₂ (worst case, full sparge) | B5: CO2aqc | C5: mol/L | D5: ='Mass Transfer'!$D$162 -> 0.0097159948 | E5: Schedule-dependent steady-state dissolved CO₂ (sawtooth limit cycle, bounded air-eq..saturation) - was the fixed full-sparge worst case
A6: (import) Electrolysis current (Gerrit's Law) | B6: Iappc | C6: A | D6: =Electrochemistry!$D$19 -> 0.00569 | E6: → Electrochemistry (I_app)
A7: (import) Faraday constant | B7: Fcc | C7: C/mol | D7: =Electrochemistry!$D$15 -> 96485.332 | E7: → Electrochemistry (F_const)
A8: (import) Reactor liquid volume | B8: VLc | C8: L | D8: =Biology!$D$6/1000 -> 0.015 | E8: → Biology (V_charge / 1000)
A9: Molar gas constant | B9: R_gas | C9: J/mol/K | D9: ='Mass Transfer'!$D$101 -> 8.3144626 | E9: → Mass Transfer (R_gas). Was a second, separately typed 8.314 that disagreed with the workbook's own constant in the fifth digit.
A11: EQUILIBRIUM CONSTANTS (van't Hoff to reactor T) | F11: K(T)=K₂₅·exp(−ΔH/R·(1/T−1/298.15)). ΔH = standard enthalpy of dissociation; well documented. Same van't Hoff treatment your sheet already uses for the Henry constants.
A12: constant | B12: K₂₅ | C12: ΔH kJ/mol | D12: K at reactor T | E12: source
A13: Carbonate Ka1 (pKa 6.35) | B13: 4.45e-07 | C13: 9.15 | D13: =B13*EXP(-C13*1000/R_gas*(1/TKc-1/298.15)) -> 4.45e-07 | E13: Handbook: K₂₅ (CRC/IUPAC); ΔH dissociation (CRC)
A14: Carbonate Ka2 (pKa 10.33) | B14: 4.69e-11 | C14: 14.9 | D14: =B14*EXP(-C14*1000/R_gas*(1/TKc-1/298.15)) -> 4.69e-11 | E14: Handbook: K₂₅ (CRC/IUPAC); ΔH dissociation (CRC)
A15: Phosphate Ka1 (pKa 2.15) | B15: 0.0071 | C15: -8 | D15: =B15*EXP(-C15*1000/R_gas*(1/TKc-1/298.15)) -> 0.0071 | E15: Handbook: K₂₅ (CRC/IUPAC); ΔH dissociation (CRC)
A16: Phosphate Ka2 (pKa 7.20) | B16: 6.31e-08 | C16: 3.6 | D16: =B16*EXP(-C16*1000/R_gas*(1/TKc-1/298.15)) -> 6.31e-08 | E16: Handbook: K₂₅ (CRC/IUPAC); ΔH dissociation (CRC)
A17: Phosphate Ka3 (pKa 12.38) | B17: 4.2e-13 | C17: 16 | D17: =B17*EXP(-C17*1000/R_gas*(1/TKc-1/298.15)) -> 4.2e-13 | E17: Handbook: K₂₅ (CRC/IUPAC); ΔH dissociation (CRC)
A18: Ammonium Ka (pKa 9.25) | B18: 5.6e-10 | C18: 52.2 | D18: =B18*EXP(-C18*1000/R_gas*(1/TKc-1/298.15)) -> 5.6e-10 | E18: Handbook: K₂₅ (CRC/IUPAC); ΔH dissociation (CRC)
A19: Water Kw | B19: 1e-14 | C19: 55.8 | D19: =B19*EXP(-C19*1000/R_gas*(1/TKc-1/298.15)) -> 1e-14 | E19: Handbook: K₂₅ (CRC/IUPAC); ΔH dissociation (CRC)
A20: Hypochlorous Ka (pKa 7.54) | B20: 2.8840315e-08 | C20: 13.8 | D20: =B20*EXP(-C20*1000/R_gas*(1/TKc-1/298.15)) -> 2.8840315e-08 | E20: Handbook: K₂₅ (CRC/IUPAC); ΔH dissociation (CRC)
A21: HOCl pKa at reactor T | B21: pKa_HOCl | C21: - | D21: =-LOG10(Ka_HOCl) -> 7.54 | E21: = −log₁₀(Ka_HOCl at T)
A23: MEDIA IONIC COMPOSITION (per litre, as published; Excel derives the charge balance) | F23: Trace-metal salts omitted from SID (<0.2 mM charge, negligible vs ~50–60 mM); their chloride is carried in the chloride row.
A24: salt | B24: MW g/mol | C24: MC02 g/L | D24: UdG g/L | E24: source
A25: KH₂PO₄ | B25: 136.086 | C25: 0 | D25: 2.3 | E25: Pous 2022 (BiTE 101010) / Pous 2023 (JECE 111550), UdG recipe
A26: Na₂HPO₄ | B26: 141.96 | C26: 2.895 | D26: 2.9 | E26: Media/README.md (MC02); per Sydow 2017 SI Table S1
A27: NaH₂PO₄·2H₂O | B27: 156.01 | C27: 3.06 | D27: 0 | E27: Media/README.md (MC02); per Sydow 2017 SI Table S1
A28: NaHCO₃ | B28: 84.007 | C28: 0 | D28: 1.05 | E28: Pous 2022 (BiTE 101010) / Pous 2023 (JECE 111550), UdG recipe
A29: K₂SO₄ | B29: 174.26 | C29: 0.17 | D29: 0 | E29: Media/README.md (MC02); per Sydow 2017 SI Table S1
A30: CaSO₄·2H₂O | B30: 172.17 | C30: 0.097 | D30: 0 | E30: Media/README.md (MC02); per Sydow 2017 SI Table S1
A31: MgSO₄·7H₂O | B31: 246.48 | C31: 0.8 | D31: 0.5 | E31: Media/README.md (MC02); per Sydow 2017 SI Table S1
A32: (NH₄)₂SO₄ | B32: 132.14 | C32: 0.943 | D32: 0.47 | E32: Media/README.md (MC02); per Sydow 2017 SI Table S1
A33: CaCl₂ | B33: 110.98 | C33: 0 | D33: 0.01 | E33: Pous 2022 (BiTE 101010) / Pous 2023 (JECE 111550), UdG recipe = 0.01 g/L.
A35: MC02 — total phosphate | B35: PT_mc02 | C35: mol/L | D35: =mc_Na2HPO4/MW_Na2HPO4+mc_NaH2PO4_2H2O/MW_NaH2PO4_2H2O -> 0.040007196 | E35: Σ phosphate salts
A36: MC02 — strong-ion difference | B36: SID_mc02 | C36: mol/L | D36: =(2*mc_Na2HPO4/MW_Na2HPO4+mc_NaH2PO4_2H2O/MW_NaH2PO4_2H2O+2*mc_K2SO4/MW_K2SO4+2*mc_MgSO4_7H2O/MW_MgSO4_7H2O+2*mc_CaSO4_2H2O/MW_CaSO4_2H2O)-2*(mc_NH42SO4/MW_NH42SO4+mc_MgSO4_7H2O/MW_MgSO4_7H2O+mc_K2SO4/MW_K2SO4+mc_CaSO4_2H2O/MW_CaSO4_2H2O) -> 0.046127523 | E36: Σ strong cations − strong anions
A37: MC02 — total ammonium | B37: NT_mc02 | C37: mol/L | D37: =2*mc_NH42SO4/MW_NH42SO4 -> 0.014272741
A38: MC02 — chloride | B38: Cl_mc02 | C38: mol/L | D38: =0 -> 0 | E38: no chloride salts
A39: UdG — total phosphate | B39: PT_udg | C39: mol/L | D39: =udg_KH2PO4/MW_KH2PO4+udg_Na2HPO4/MW_Na2HPO4 -> 0.037329367 | E39: Σ phosphate salts
A40: UdG — strong-ion difference | B40: SID_udg | C40: mol/L | D40: =(udg_NaHCO3/MW_NaHCO3+2*udg_Na2HPO4/MW_Na2HPO4+udg_KH2PO4/MW_KH2PO4+2*udg_MgSO4_7H2O/MW_MgSO4_7H2O+2*udg_CaCl2/MW_CaCl2)-(2*(udg_NH42SO4/MW_NH42SO4+udg_MgSO4_7H2O/MW_MgSO4_7H2O)+2*udg_CaCl2/MW_CaCl2) -> 0.063142948 | E40: Σ strong cations − strong anions
A41: UdG — total ammonium | B41: NT_udg | C41: mol/L | D41: =2*udg_NH42SO4/MW_NH42SO4 -> 0.0071136673
A42: UdG — chloride | B42: Cl_udg | C42: mol/L | D42: =2*udg_CaCl2/MW_CaCl2 -> 0.00018021265 | E42: trace-metal Cl excluded (negligible)
A44: (sel) strong-ion difference | B44: pH_SID | C44: mol/L | D44: =IF(Summary!$D$5="MC02",SID_mc02,IF(Summary!$D$5="UdG phosphate",SID_udg,NA())) -> 0.046127523 | E44: by media_sel
...

Sheet Biology
A1: BIOLOGY
A2: Parameter | B2: Name | C2: Unit | D2: Value | E2: Source / assumption
A3: IMPORTS (from other tabs)
A4: (import) H₂ generation rate | B4: rH2_gen | C4: mol/h | D4: =Electrochemistry!$D$21 -> 0.00010375983 | E4: =HYPERLINK("#Electrochemistry!D21","→ Electrochemistry") -> → Electrochemistry
A5: (import) Net O₂ to dissolved pool | B5: O2_net_gen | C5: mol/h | D5: =Electrochemistry!$D$29 -> 5.0684409e-05 | E5: =HYPERLINK("#Electrochemistry!D29","→ Electrochemistry") -> → Electrochemistry
A6: (import) LIQUID VOLUME TO CHARGE | B6: V_charge | C6: mL | D6: =Geometry!$D$41 -> 15 | E6: =HYPERLINK("#Geometry!D41","→ Geometry") -> → Geometry
A7: (import) HOB organism | B7: organism_sel | D7: =Summary!$D$4 -> UdG (mixed) | E7: =HYPERLINK("#Summary!D4","→ Summary") -> → Summary
A8: (import) HOB organism | B8: organism_sel | D8: =Summary!$D$4 -> UdG (mixed) | E8: =HYPERLINK("#Summary!D4","→ Summary") -> → Summary
A10: Gas requirement ratio - H₂ | B10: bio_H2 | C10: - | D10: =IF(ISNUMBER(cal_knall_H2),cal_knall_H2,6) -> 6 | E10: H₂:O₂:CO₂ UPTAKE ratio (not feed; phase-dependent, Lu & Yu 2019). Knallgas caps O₂:H₂≤0.5; growth gives O₂:H₂≈0.29–0.35, CO₂:H₂≈0.15–0.19. 6:2:1 = mid-range central. Feed optimum 7:2:1 (Ishizaki 2001). Can't measure pre-growth.
A11: Gas requirement ratio - O₂ | B11: bio_O2 | C11: - | D11: =IF(ISNUMBER(cal_knall_O2),cal_knall_O2,2) -> 2 | E11: O₂:H₂ uptake, range 0.29–0.35 (×6 → 1.75–2.1). 2 = central; 1.8 (lean) is growth-protective.
A12: Gas requirement ratio - CO₂ | B12: bio_CO2 | C12: - | D12: =IF(ISNUMBER(cal_knall_CO2),cal_knall_CO2,1) -> 1 | E12: CO₂:H₂ uptake, range 0.15–0.19 (×6 → 0.9–1.15). 1 = central. Supply ≫ demand → non-limiting.
A13: H₂ consumed | B13: H2_cons | C13: mol/h | D13: =rH2_gen -> 0.00010375983 | E13: Assumes 100% of evolved H₂ consumed — steady growth only; ~0 during lag (see §13).
A14: O₂ consumed | B14: O2_cons | C14: mol/h | D14: =H2_cons*bio_O2/bio_H2 -> 3.4586611e-05 | E14: Assumes 100% H₂ uptake (upper bound); true limit is gas-liquid H₂ transfer — see H2_turnover
A15: CO₂ consumed (carbon fixation) | B15: CO2_cons | C15: mol/h | D15: =H2_cons*bio_CO2/bio_H2 -> 1.7293306e-05 | E15: H₂ consumed x (CO₂/H₂ ratio).
A16: EXCESS O₂ to remove | B16: O2_excess | C16: mol/h | D16: =MAX(0,O2_net_gen-O2_cons) -> 1.6097798e-05 | E16: Net electrolytic O₂ minus biological uptake, floored at zero. The floor matters: at the knallgas cap (O₂:H₂ = 0.5, i.e. bio_O2 = 3) uptake exactly consumes the electrolytic surplus and everything downstream that divides by this would blow up. Upper bound in any case, because it rests on the full-H₂-uptake assumption above.
A17: Temperature | B17: T_C | C17: °C | D17: =Summary!$D$8 -> 25 | E17: C. necator optimum ~30 °C. Input.
A18: Temperature (absolute) | B18: T_K | C18: K | D18: =T_C+273.15 -> 298.15 | E18: °C + 273.15.
A19: Surface pressure | B19: P_atm | C19: Pa | D19: =IF(Summary!$D$10>0,Summary!$D$10,101325) -> 101325 | E19: Atmospheric at the liquid surface (assumed).
A20: Standard atmosphere (atm->Pa) | B20: Pa_per_atm | C20: Pa/atm | D20: 101325 | E20: Defined: 1 atm = 101 325 Pa exactly.
A21: Henry solubility O₂ (ref, 298.15 K) | B21: H_O2ref | C21: mol/m³/Pa | D21: 1.2e-05 | E21: Sander (2023) recommended H^cp O2; reproduces ~7.5 mg/L air-saturation at 30 degC
A22: Henry T-dependence O₂ | B22: H_O2T | C22: K | D22: 1500 | E22: Sander (2023): d ln(Hcp)/d(1/T).
A23: Reference temperature | B23: T_ref | C23: K | D23: 298.15 | E23: Standard reference for Henry constants.
A24: Henry solubility O₂ at T | B24: H_O2_T | C24: mol/m³/Pa | D24: =H_O2ref*EXP(H_O2T*(1/T_K-1/T_ref)) -> 1.2e-05 | E24: van 't Hoff correction to reactor T.
A25: O₂ growth-inhibition ceiling (gas) | B25: O2_ceil_atm | C25: atm | D25: 0.3 | E25: Whole-cell growth inhibited above ~0.30 atm O₂ (Amer & Kim 2023); the [NiFe] hydrogenase itself is O₂-tolerant.
A26: O₂ ceiling (partial pressure) | B26: O2_ceil_Pa | C26: Pa | D26: =O2_ceil_atm*Pa_per_atm -> 30397.5 | E26: Ceiling in Pa.
A27: Dissolved-O₂ ceiling | B27: O2_ceil_C | C27: mol/m³ | D27: =H_O2_T*O2_ceil_Pa -> 0.36477 | E27: Henry's law at the gas ceiling.
A28: Dissolved-O₂ ceiling | B28: O2_ceil_uM | C28: µM | D28: =O2_ceil_C*1000 -> 364.77 | E28: mol/m³ = mM; ×1000 = µM. Aim: minimise dissolved O₂; floor set by O₂-removal capacity (§11).
A29: Henry solubility CO₂ (ref, 298.15 K) | B29: H_CO2ref | C29: mol/m³/Pa | D29: 0.00033 | E29: Sander (2023) compilation; CO₂ ~28× more soluble than O₂ (vs the 1.2e-5 O₂ Hcp).
A30: Henry T-dependence CO₂ | B30: H_CO2T | C30: K | D30: 2400 | E30: Sander (2023): d ln(Hcp)/d(1/T) for CO₂.
A31: Henry solubility CO₂ at T | B31: H_CO2_T | C31: mol/m³/Pa | D31: =H_CO2ref*EXP(H_CO2T*(1/T_K-1/T_ref)) -> 0.00033 | E31: van 't Hoff to reactor T.
A32: CO₂ partial pressure at sparge | B32: p_CO2_sparge | C32: Pa | D32: =P_atm -> 101325 | E32: Pure-CO₂ sparge: p_CO₂ ≈ surface pressure during a pulse. Assumption.
A33: Dissolved CO₂ (during sparge) | B33: CO2_diss | C33: mol/m³ | D33: =H_CO2_T*p_CO2_sparge -> 33.43725 | E33: Equilibrium dissolved CO₂ while sparging (mol/m³ = mM).
A34: RuBisCO Km for CO₂ | B34: Km_CO2 | C34: µM | D34: 50 | E34: RuBisCO Km(CO₂) ~ order 50 µM. Coarse — confirm.
A35: Carbon margin (dissolved CO₂ : Km) | B35: CO2_carbon_margin | C35: × | D35: =CO2_diss*1000/Km_CO2 -> 668.745 | E35: Dissolved CO₂ : RuBisCO Km. ≫1 = saturating (duty-averaged lower).
A36: Carbonic-acid Ka1 (apparent) | B36: Ka1_carb | C36: mol/L | D36: 4.45e-07 | E36: CO₂(aq)+H₂O ⇌ H⁺+HCO₃⁻, pKa1 6.35 (25 °C).
A37: pH — UNBUFFERED worst case | B37: pH_CO2_unbuf | C37: - | D37: =-LOG10(SQRT(Ka1_carb*(CO2_diss/1000))) -> 3.9137047 | E37: Unbuffered worst case (pure water + CO₂) — lower bound only; the Sydow phosphate medium holds pH near setpoint.
A38: Henry solubility H₂ (ref, 298.15 K) | B38: H_H2ref | C38: mol/m³/Pa | D38: 7.8e-06 | E38: Sander (2023). H₂ ~1.5× less soluble than O₂ (vs the 1.2e-5 O₂ Hcp).
A39: Henry T-dependence H₂ | B39: H_H2T | C39: K | D39: 500 | E39: Sander (2023): d ln(Hcp)/d(1/T) for H₂ (weak T-dependence).
A40: Henry solubility H₂ at T | B40: H_H2_T | C40: mol/m³/Pa | D40: =H_H2ref*EXP(H_H2T*(1/T_K-1/T_ref)) -> 7.8e-06 | E40: van 't Hoff to reactor T.
A41: Dissolved-H₂ saturation (1 atm) | B41: C_H2_sat | C41: mol/m³ | D41: =H_H2_T*P_atm -> 0.790335 | E41: Max dissolved H₂ at 1 atm — the cells' H₂ ceiling.
...

Sheet Mass Transfer
A1: MASS TRANSFER
A2: Parameter | B2: Name | C2: Unit | D2: Value | E2: Source / assumption
A4: IMPORTS (from other tabs)
A5: (import) Stir-bar length (from reactor type) | B5: stir_len | C5: mm | D5: =Geometry!$D$52 -> 12 | E5: =HYPERLINK("#Geometry!D52","→ Geometry") -> → Geometry | F5: Magnetic stir bar. Pioreactor max 20 mm; confirm the supplied bar's length. Input.
A6: (import) Dissolved-O₂ ceiling | B6: O2_ceil_C | C6: mol/m³ | D6: =Biology!$D$27 -> 0.36477 | E6: =HYPERLINK("#Biology!D27","→ Biology") -> → Biology
A7: (import) O₂ ceiling (partial pressure) | B7: O2_ceil_Pa | C7: Pa | D7: =Biology!$D$26 -> 30397.5 | E7: =HYPERLINK("#Biology!D26","→ Biology") -> → Biology
A8: (import) Temperature (absolute) | B8: T_K | C8: K | D8: =Biology!$D$18 -> 298.15 | E8: =HYPERLINK("#Biology!D18","→ Biology") -> → Biology
A9: (import) Surface pressure | B9: P_atm | C9: Pa | D9: =Biology!$D$19 -> 101325 | E9: =HYPERLINK("#Biology!D19","→ Biology") -> → Biology
A10: (import) CO₂ consumed (carbon fixation) | B10: CO2_cons | C10: mol/h | D10: =Biology!$D$15 -> 1.7293306e-05 | E10: =HYPERLINK("#Biology!D15","→ Biology") -> → Biology
A11: (import) EXCESS O₂ to remove | B11: O2_excess | C11: mol/h | D11: =Biology!$D$16 -> 1.6097798e-05 | E11: =HYPERLINK("#Biology!D16","→ Biology") -> → Biology
A12: (import) Henry solubility O₂ at T | B12: H_O2_T | C12: mol/m³/Pa | D12: =Biology!$D$24 -> 1.2e-05 | E12: =HYPERLINK("#Biology!D24","→ Biology") -> → Biology
A13: (import) Net O₂ to dissolved pool | B13: O2_net_gen | C13: mol/h | D13: =Electrochemistry!$D$29 -> 5.0684409e-05 | E13: =HYPERLINK("#Electrochemistry!D29","→ Electrochemistry") -> → Electrochemistry
A14: (import) Gas-liquid interfacial area | B14: interface_A | C14: mm² | D14: =Geometry!$D$44 -> 429.54773 | E14: =HYPERLINK("#Geometry!D44","→ Geometry") -> → Geometry
A15: (import) Vial internal diameter | B15: vial_ID | C15: mm | D15: =Geometry!$D$20 -> 25.28 | E15: =HYPERLINK("#Geometry!D20","→ Geometry") -> → Geometry
A16: (import) LIQUID VOLUME TO CHARGE | B16: V_charge | C16: mL | D16: =Geometry!$D$41 -> 15 | E16: =HYPERLINK("#Geometry!D41","→ Geometry") -> → Geometry
A17: (import) Internal cross-sectional area | B17: A_x | C17: mm² | D17: =Geometry!$D$21 -> 501.931 | E17: =HYPERLINK("#Geometry!D21","→ Geometry") -> → Geometry
A18: (import) Sparge tube ID | B18: spg_ID | C18: mm | D18: =Geometry!$D$31 -> 1.5875 | E18: =HYPERLINK("#Geometry!D31","→ Geometry") -> → Geometry
A19: (import) Headspace gas volume | B19: headspace_V | C19: mL | D19: =Geometry!$D$49 -> 2.6124285 | E19: =HYPERLINK("#Geometry!D49","→ Geometry") -> → Geometry
A20: (import) Sinter porosity grade (from electrode) | B20: por_grade | C20: 0-5 | D20: =Electrochemistry!$D$32 -> 0 | E20: =HYPERLINK("#Electrochemistry!D32","→ Electrochemistry") -> → Electrochemistry
A21: (import) Sparger type (from electrode) | B21: sparger | C21: - | D21: =Electrochemistry!$D$31 -> Tube | E21: =HYPERLINK("#Electrochemistry!D31","→ Electrochemistry") -> → Electrochemistry
A22: (import) Optimum DO (organism) | B22: DO_opt | D22: =Biology!$D$46 -> #N/A | E22: =HYPERLINK("#Biology!D46","→ Biology") -> → Biology
A23: (import) Impairment DO (organism) | B23: DO_impair | D23: =Biology!$D$47 -> #N/A | E23: =HYPERLINK("#Biology!D47","→ Biology") -> → Biology
A24: (import) Toxic/inhibition DO (organism) | B24: DO_toxic | D24: =Biology!$D$48 -> #N/A | E24: =HYPERLINK("#Biology!D48","→ Biology") -> → Biology
A25: (import) Minimum DO (organism) | B25: DO_min | D25: =Biology!$D$45 -> #N/A | E25: =HYPERLINK("#Biology!D45","→ Biology") -> → Biology
A27: valid sparger 1 | B27: spg_name_1 | C27: - | D27: Tube | E27: Bare 1/8" OD x 1/16" ID Flexelene 135C tube orifice.
A28: valid sparger 2 | B28: spg_name_2 | C28: - | D28: Sintered | E28: 10 mm sintered-glass disc annulus on a tubular anode.
A29: Surface tension (water, T) | B29: sigma | C29: N/m | D29: =sigma_0+sigma_k*(T_K-273.15) -> 0.071965 | E29: IAPWS R1-76(2014), evaluated at the reactor temperature (T_C) rather than frozen at 30 °C. Feeds the bubble-detachment diameter.
A30: Liquid density (water, T) | B30: rho_L | C30: kg/m³ | D30: =rho_0+rho_k*(T_K-273.15) -> 996.94 | E30: IAPWS-95, evaluated at the reactor temperature.
A31: Gravitational acceleration | B31: g_const | C31: m/s² | D31: 9.80665 | E31: Standard gravity (defined).
A32: O₂ diffusivity in water (T) | B32: D_O2 | C32: m²/s | D32: =10^(HB_a+HB_b/T_K-(HB_c/T_K)^2)/10000 -> 1.9976723e-09 | E32: Han & Bartels (1996) evaluated at the reactor temperature. At 25 °C this is 2.00e-9 m²/s; the sheet previously carried the 30 °C value 2.249e-9 as a constant, which overstated the surface transfer coefficient by 6%.
A33: Pore size - grade 0 | B33: por0_um | C33: µm | D33: 205 | E33: DURAN P0 160-250 µm, midpoint. ISO 4793 (paywalled) underlies; DURAN table is free.
A34: Pore size - grade 1 | B34: por1_um | C34: µm | D34: 130 | E34: DURAN P1 100-160 µm, midpoint.
A35: Pore size - grade 2 | B35: por2_um | C35: µm | D35: 70 | E35: DURAN P2 40-100 µm, midpoint.
A36: Pore size - grade 3 | B36: por3_um | C36: µm | D36: 28 | E36: DURAN P3 16-40 µm, midpoint.
A37: Pore size - grade 4 | B37: por4_um | C37: µm | D37: 13 | E37: DURAN P4 10-16 µm, midpoint.
A38: Pore size - grade 5 | B38: por5_um | C38: µm | D38: 1.3 | E38: DURAN P5 1.0-1.6 µm, midpoint.
A39: Selected sinter pore diameter | B39: por_pore | C39: m | D39: =CHOOSE(por_grade+1,por0_um,por1_um,por2_um,por3_um,por4_um,por5_um)/1000000 -> 0.000205 | E39: Picked by por_grade.
A40: Tube orifice diameter | B40: tube_d_m | C40: m | D40: =spg_ID/1000 -> 0.0015875 | E40: Tube ID in metres.
A41: Effective orifice/pore diameter | B41: d_orifice | C41: m | D41: =IF(sparger=spg_name_1,tube_d_m,IF(sparger=spg_name_2,por_pore,NA())) -> 0.0015875 | E41: Tube ID or sinter pore; invalid sparger returns an error.
A42: Bubble detachment diameter | B42: d_bubble | C42: m | D42: =(6*d_orifice*sigma/(rho_L*g_const))^(1/3) -> 0.0041234956 | E42: Static low-flow force balance (buoyancy vs surface tension); valid in the quasi-static regime — see bubble_regime (§10).
...

Sheet CO2 flows
A1: CO₂ DOSING FLOWRATES
A2: Reactor | B2: date | C2: cylinder size | D2: observed volume* | E2: volume | F2: time | G2: flowrate | H2: average flowrate | I2: minimum sparge | J2: nominal flowrate | L2: KEY
C3: ml | D3: ml | E3: ml | F3: s | G3: ml/s | H3: ml/s | I3: s | J3: ml/s | L3: Flowrate set by inspection, as maximum to not give bubbles rising into vial neck
A4: ed04 | B4: 46190 | C4: 50 | D4: 0 | I4: 0.25 | J4: 3.33 | L4: First or last data point removed as suspect outlier
A5: ed04 | B5: 46190 | C5: 50 | D5: 50 | E5: =D5-D4 -> 50 | F5: 15 | G5: =E5/F5 -> 3.3333333 | H5: =AVERAGE(G5) -> 3.3333333
A6: ed04 | B6: 46190 | C6: 50 | D6: 0 | K6: Point | L6: Note
A7: ed04 | B7: 46190 | C7: 50 | D7: 12 | E7: =D7-D6 -> 12 | F7: 4 | G7: =E7/F7 -> 3 | H7: =AVERAGE(G7:G9) -> 3.3333333 | K7: * | L7: CO2 collected in measuring cyclinder over CO2-saturated water
A8: ed04 | B8: 46190 | C8: 50 | D8: 26 | E8: =D8-D7 -> 14 | F8: 4 | G8: =E8/F8 -> 3.5 | K8: 46190 | L8: Collected using inlet CO2 tube rather than outlet as MEP vialcap leaking
A9: ed04 | B9: 46190 | C9: 50 | D9: 40 | E9: =D9-D8 -> 14 | F9: 4 | G9: =E9/F9 -> 3.5 | K9: 46190 | L9: Collected over saturated NaHCO3 soln, as Martin innovated without thinking
A10: ed04 | B10: 46190 | C10: 50 | D10: 0
A11: ed04 | B11: 46190 | C11: 50 | D11: 6 | E11: =D11-D10 -> 6 | F11: 2 | G11: =E11/F11 -> 3 | H11: =AVERAGE(G11:G16) -> 3.75
A12: ed04 | B12: 46190 | C12: 50 | D12: 15 | E12: =D12-D11 -> 9 | F12: 2 | G12: =E12/F12 -> 4.5
A13: ed04 | B13: 46190 | C13: 50 | D13: 21 | E13: =D13-D12 -> 6 | F13: 2 | G13: =E13/F13 -> 3
A14: ed04 | B14: 46190 | C14: 50 | D14: 29 | E14: =D14-D13 -> 8 | F14: 2 | G14: =E14/F14 -> 4
A15: ed04 | B15: 46190 | C15: 50 | D15: 35 | E15: =D15-D14 -> 6 | F15: 2 | G15: =E15/F15 -> 3
A16: ed04 | B16: 46190 | C16: 50 | D16: 45 | E16: =D16-D15 -> 10 | F16: 2 | G16: =E16/F16 -> 5
A17: ed04 | B17: 46190 | C17: 50 | D17: 0
A18: ed04 | B18: 46190 | C18: 50 | D18: 4 | E18: =D18-D17 -> 4 | F18: 1 | G18: =E18/F18 -> 4 | H18: =AVERAGE(G18:G23) -> 3.8333333
A19: ed04 | B19: 46190 | C19: 50 | D19: 8 | E19: =D19-D18 -> 4 | F19: 1 | G19: =E19/F19 -> 4
A20: ed04 | B20: 46190 | C20: 50 | D20: 11 | E20: =D20-D19 -> 3 | F20: 1 | G20: =E20/F20 -> 3
A21: ed04 | B21: 46190 | C21: 50 | D21: 15 | E21: =D21-D20 -> 4 | F21: 1 | G21: =E21/F21 -> 4
A22: ed04 | B22: 46190 | C22: 50 | D22: 19 | E22: =D22-D21 -> 4 | F22: 1 | G22: =E22/F22 -> 4
A23: ed04 | B23: 46190 | C23: 50 | D23: 23 | E23: =D23-D22 -> 4 | F23: 1 | G23: =E23/F23 -> 4
A24: ed04 | B24: 46190 | C24: 50 | D24: 31
A25: ed04 | B25: 46190 | C25: 50 | D25: 33 | E25: =D25-D24 -> 2 | F25: 0.5 | G25: =E25/F25 -> 4 | H25: =AVERAGE(G25:G29) -> 4
A26: ed04 | B26: 46190 | C26: 50 | D26: 35 | E26: =D26-D25 -> 2 | F26: 0.5 | G26: =E26/F26 -> 4
A27: ed04 | B27: 46190 | C27: 50 | D27: 37 | E27: =D27-D26 -> 2 | F27: 0.5 | G27: =E27/F27 -> 4
A28: ed04 | B28: 46190 | C28: 50 | D28: 39 | E28: =D28-D27 -> 2 | F28: 0.5 | G28: =E28/F28 -> 4
A29: ed04 | B29: 46190 | C29: 50 | D29: 41 | E29: =D29-D28 -> 2 | F29: 0.5 | G29: =E29/F29 -> 4
A30: ed04 | B30: 46190 | C30: 50 | D30: 42 | E30: =D30-D29 -> 1 | F30: 0.25 | G30: =E30/F30 -> 4 | H30: =AVERAGE(G30:G34) -> 4
A31: ed04 | B31: 46190 | C31: 50 | D31: 43 | E31: =D31-D30 -> 1 | F31: 0.25 | G31: =E31/F31 -> 4
A32: ed04 | B32: 46190 | C32: 50 | D32: 44 | E32: =D32-D31 -> 1 | F32: 0.25 | G32: =E32/F32 -> 4
A33: ed04 | B33: 46190 | C33: 50 | D33: 45 | E33: =D33-D32 -> 1 | F33: 0.25 | G33: =E33/F33 -> 4
A34: ed04 | B34: 46190 | C34: 50 | D34: 46 | E34: =D34-D33 -> 1 | F34: 0.25 | G34: =E34/F34 -> 4
A35: ed04 | B35: 46190 | C35: 10 | D35: 0 | E35: =D35-D34 -> -46
A36: ed04 | B36: 46190 | C36: 10 | D36: 0.4 | E36: =D36-D35 -> 0.4 | F36: 0.2 | G36: =E36/F36 -> 2
A37: ed04 | B37: 46190 | C37: 10 | D37: 1.2 | E37: =D37-D36 -> 0.8 | F37: 0.2 | G37: =E37/F37 -> 4 | H37: =AVERAGE(G37:G39) -> 4.3333333
A38: ed04 | B38: 46190 | C38: 10 | D38: 2.2 | E38: =D38-D37 -> 1 | F38: 0.2 | G38: =E38/F38 -> 5
A39: ed04 | B39: 46190 | C39: 10 | D39: 3 | E39: =D39-D38 -> 0.8 | F39: 0.2 | G39: =E39/F39 -> 4
A40: ed04 | B40: 46190 | C40: 10 | D40: 0
...

Sheet Calibrations
A1: CALIBRATIONS
A2: Fill the white cells only: Researcher, Date, the key (Reactor or Organism) and the raw measurements. Grey cells are computed automatically. Set Include to y for rows the model should use.
A3: The value in use for each calibration follows the rule stated under its heading. If no rows are included yet, the model falls back to its built-in default.
A5: =HYPERLINK("https://github.com/amy-bo/electroPioreactor/blob/CO2-modular/Media/protocols/gerrit-current.md","ELECTROLYSIS CURRENT") -> ELECTROLYSIS CURRENT
A6: Value in use: least-squares fit of current vs intensity, averaged across all included runs for the active reactor.
A7: Researcher | B7: Date | C7: Reactor | D7: Intensity | E7: Current | F7: Type (auto) | G7: Include? | H7: Notes
F8: =IFERROR(VLOOKUP(C8,Geometry!$A$59:$B$80,2,FALSE),"")
F9: =IFERROR(VLOOKUP(C9,Geometry!$A$59:$B$80,2,FALSE),"")
F10: =IFERROR(VLOOKUP(C10,Geometry!$A$59:$B$80,2,FALSE),"")
F11: =IFERROR(VLOOKUP(C11,Geometry!$A$59:$B$80,2,FALSE),"")
F12: =IFERROR(VLOOKUP(C12,Geometry!$A$59:$B$80,2,FALSE),"")
F13: =IFERROR(VLOOKUP(C13,Geometry!$A$59:$B$80,2,FALSE),"")
F14: =IFERROR(VLOOKUP(C14,Geometry!$A$59:$B$80,2,FALSE),"")
F15: =IFERROR(VLOOKUP(C15,Geometry!$A$59:$B$80,2,FALSE),"")
A16: Value in use - slope | C16: mA/% | D16: =IFERROR((COUNTIFS(C8:C15,Summary!$D$2,G8:G15,"y")*SUMPRODUCT((C8:C15=Summary!$D$2)*(G8:G15="y")*D8:D15*E8:E15)-SUMIFS(D8:D15,C8:C15,Summary!$D$2,G8:G15,"y")*SUMIFS(E8:E15,C8:C15,Summary!$D$2,G8:G15,"y"))/(COUNTIFS(C8:C15,Summary!$D$2,G8:G15,"y")*SUMPRODUCT((C8:C15=Summary!$D$2)*(G8:G15="y")*D8:D15*D8:D15)-SUMIFS(D8:D15,C8:C15,Summary!$D$2,G8:G15,"y")*SUMIFS(D8:D15,C8:C15,Summary!$D$2,G8:G15,"y")),"no included runs — model uses its default") -> no included runs — model uses its default
A17: Value in use - intercept | C17: mA | D17: =IFERROR((SUMIFS(E8:E15,C8:C15,Summary!$D$2,G8:G15,"y")-((COUNTIFS(C8:C15,Summary!$D$2,G8:G15,"y")*SUMPRODUCT((C8:C15=Summary!$D$2)*(G8:G15="y")*D8:D15*E8:E15)-SUMIFS(D8:D15,C8:C15,Summary!$D$2,G8:G15,"y")*SUMIFS(E8:E15,C8:C15,Summary!$D$2,G8:G15,"y"))/(COUNTIFS(C8:C15,Summary!$D$2,G8:G15,"y")*SUMPRODUCT((C8:C15=Summary!$D$2)*(G8:G15="y")*D8:D15*D8:D15)-SUMIFS(D8:D15,C8:C15,Summary!$D$2,G8:G15,"y")*SUMIFS(D8:D15,C8:C15,Summary!$D$2,G8:G15,"y")))*SUMIFS(D8:D15,C8:C15,Summary!$D$2,G8:G15,"y"))/COUNTIFS(C8:C15,Summary!$D$2,G8:G15,"y"),"no included runs — model uses its default") -> no included runs — model uses its default
A20: =HYPERLINK("https://github.com/amy-bo/electroPioreactor/blob/CO2-modular/Media/protocols/faradaic-efficiency.md","FARADAIC EFFICIENCY (cathodic etaF, anodic etaF_OER)") -> FARADAIC EFFICIENCY (cathodic etaF, anodic etaF_OER)
A21: Value in use: average of the included runs for the active reactor, taken separately for the H2 (cathode) and O2 (anode) electrodes. The gas volume is corrected for saturated water vapour at the temperature you record, per protocols/faradaic-efficiency.md.
A22: Researcher | B22: Date | C22: Reactor | D22: Charge Q | E22: Gas volume | F22: Temp | G22: Pressure | H22: Electrode | I22: etaF (computed) | J22: Type (auto) | K22: Include? | L22: Notes
I23: =IFERROR(((G23-'Mass Transfer'!$D$206)*(E23/1000000)/('Mass Transfer'!$D$101*(F23+273.15)))/(D23/(IF(H23="H2",2,4)*Electrochemistry!$D$15)),"") | J23: =IFERROR(VLOOKUP(C23,Geometry!$A$59:$B$80,2,FALSE),"")
I24: =IFERROR(((G24-'Mass Transfer'!$D$206)*(E24/1000000)/('Mass Transfer'!$D$101*(F24+273.15)))/(D24/(IF(H24="H2",2,4)*Electrochemistry!$D$15)),"") | J24: =IFERROR(VLOOKUP(C24,Geometry!$A$59:$B$80,2,FALSE),"")
I25: =IFERROR(((G25-'Mass Transfer'!$D$206)*(E25/1000000)/('Mass Transfer'!$D$101*(F25+273.15)))/(D25/(IF(H25="H2",2,4)*Electrochemistry!$D$15)),"") | J25: =IFERROR(VLOOKUP(C25,Geometry!$A$59:$B$80,2,FALSE),"")
I26: =IFERROR(((G26-'Mass Transfer'!$D$206)*(E26/1000000)/('Mass Transfer'!$D$101*(F26+273.15)))/(D26/(IF(H26="H2",2,4)*Electrochemistry!$D$15)),"") | J26: =IFERROR(VLOOKUP(C26,Geometry!$A$59:$B$80,2,FALSE),"")
I27: =IFERROR(((G27-'Mass Transfer'!$D$206)*(E27/1000000)/('Mass Transfer'!$D$101*(F27+273.15)))/(D27/(IF(H27="H2",2,4)*Electrochemistry!$D$15)),"") | J27: =IFERROR(VLOOKUP(C27,Geometry!$A$59:$B$80,2,FALSE),"")
I28: =IFERROR(((G28-'Mass Transfer'!$D$206)*(E28/1000000)/('Mass Transfer'!$D$101*(F28+273.15)))/(D28/(IF(H28="H2",2,4)*Electrochemistry!$D$15)),"") | J28: =IFERROR(VLOOKUP(C28,Geometry!$A$59:$B$80,2,FALSE),"")
I29: =IFERROR(((G29-'Mass Transfer'!$D$206)*(E29/1000000)/('Mass Transfer'!$D$101*(F29+273.15)))/(D29/(IF(H29="H2",2,4)*Electrochemistry!$D$15)),"") | J29: =IFERROR(VLOOKUP(C29,Geometry!$A$59:$B$80,2,FALSE),"")
I30: =IFERROR(((G30-'Mass Transfer'!$D$206)*(E30/1000000)/('Mass Transfer'!$D$101*(F30+273.15)))/(D30/(IF(H30="H2",2,4)*Electrochemistry!$D$15)),"") | J30: =IFERROR(VLOOKUP(C30,Geometry!$A$59:$B$80,2,FALSE),"")
A31: Value in use - cathode (H2) | C31: - | D31: =IFERROR(AVERAGEIFS(I23:I30,C23:C30,Summary!$D$2,K23:K30,"y",H23:H30,"H2"),"no included runs — model uses its default") -> no included runs — model uses its default
A32: Value in use - anode (O2) | C32: - | D32: =IFERROR(AVERAGEIFS(I23:I30,C23:C30,Summary!$D$2,K23:K30,"y",H23:H30,"O2"),"no included runs — model uses its default") -> no included runs — model uses its default
A35: =HYPERLINK("https://github.com/amy-bo/electroPioreactor/blob/CO2-modular/Media/protocols/surface-kla.md","SURFACE kLa (oxygen surface transfer)") -> SURFACE kLa (oxygen surface transfer)
A36: Value in use: average of the included kLa runs for the active reactor.
A37: Researcher | B37: Date | C37: Reactor | D37: kLa | E37: Type (auto) | F37: Include? | G37: Notes
E38: =IFERROR(VLOOKUP(C38,Geometry!$A$59:$B$80,2,FALSE),"")
E39: =IFERROR(VLOOKUP(C39,Geometry!$A$59:$B$80,2,FALSE),"")
E40: =IFERROR(VLOOKUP(C40,Geometry!$A$59:$B$80,2,FALSE),"")
E41: =IFERROR(VLOOKUP(C41,Geometry!$A$59:$B$80,2,FALSE),"")
E42: =IFERROR(VLOOKUP(C42,Geometry!$A$59:$B$80,2,FALSE),"")
E43: =IFERROR(VLOOKUP(C43,Geometry!$A$59:$B$80,2,FALSE),"")
E44: =IFERROR(VLOOKUP(C44,Geometry!$A$59:$B$80,2,FALSE),"")
E45: =IFERROR(VLOOKUP(C45,Geometry!$A$59:$B$80,2,FALSE),"")
...
